ERROR 2024-12-16 21:38:18,677 utils 20204 1980 
API Error Details:
View: TaskViewSet
URL: /api/v1/tasks/tasks/calendar/
Method: GET
User: AnonymousUser
Error Type: InvalidToken
Error Message: {'detail': ErrorDetail(string='此令牌对任何类型的令牌无效', code='token_not_valid'), 'code': ErrorDetail(string='token_not_valid', code='token_not_valid'), 'messages': [{'token_class': ErrorDetail(string='AccessToken', code='token_not_valid'), 'token_type': ErrorDetail(string='access', code='token_not_valid'), 'message': ErrorDetail(string='令牌无效或已过期', code='token_not_valid')}]}
Stack Trace:
Traceback (most recent call last):
  File "E:\Github\todo2\todoServer\venv\Lib\site-packages\rest_framework\views.py", line 497, in dispatch
    self.initial(request, *args, **kwargs)
    ~~~~~~~~~~~~^^^^^^^^^^^^^^^^^^^^^^^^^^
  File "E:\Github\todo2\todoServer\venv\Lib\site-packages\rest_framework\views.py", line 414, in initial
    self.perform_authentication(request)
    ~~~~~~~~~~~~~~~~~~~~~~~~~~~^^^^^^^^^
  File "E:\Github\todo2\todoServer\venv\Lib\site-packages\rest_framework\views.py", line 324, in perform_authentication
    request.user
  File "E:\Github\todo2\todoServer\venv\Lib\site-packages\rest_framework\request.py", line 227, in user
    self._authenticate()
    ~~~~~~~~~~~~~~~~~~^^
  File "E:\Github\todo2\todoServer\venv\Lib\site-packages\rest_framework\request.py", line 380, in _authenticate
    user_auth_tuple = authenticator.authenticate(self)
  File "E:\Github\todo2\todoServer\venv\Lib\site-packages\rest_framework_simplejwt\authentication.py", line 49, in authenticate
    validated_token = self.get_validated_token(raw_token)
  File "E:\Github\todo2\todoServer\venv\Lib\site-packages\rest_framework_simplejwt\authentication.py", line 113, in get_validated_token
    raise InvalidToken(
    ...<4 lines>...
    )
rest_framework_simplejwt.exceptions.InvalidToken: {'detail': ErrorDetail(string='此令牌对任何类型的令牌无效', code='token_not_valid'), 'code': ErrorDetail(string='token_not_valid', code='token_not_valid'), 'messages': [{'token_class': ErrorDetail(string='AccessToken', code='token_not_valid'), 'token_type': ErrorDetail(string='access', code='token_not_valid'), 'message': ErrorDetail(string='令牌无效或已过期', code='token_not_valid')}]}

    
ERROR 2024-12-16 21:54:27,793 utils 9952 7504 
API Error Details:
View: TaskViewSet
URL: /api/v1/tasks/tasks/month_stats/
Method: GET
User: fx0883
Error Type: Http404
Error Message: 
Stack Trace:
Traceback (most recent call last):
  File "E:\Github\todo2\todoServer\venv\Lib\site-packages\django\db\models\fields\__init__.py", line 2112, in get_prep_value
    return int(value)
ValueError: invalid literal for int() with base 10: 'month_stats'

The above exception was the direct cause of the following exception:

Traceback (most recent call last):
  File "E:\Github\todo2\todoServer\venv\Lib\site-packages\rest_framework\generics.py", line 19, in get_object_or_404
    return _get_object_or_404(queryset, *filter_args, **filter_kwargs)
  File "E:\Github\todo2\todoServer\venv\Lib\site-packages\django\shortcuts.py", line 85, in get_object_or_404
    return queryset.get(*args, **kwargs)
           ~~~~~~~~~~~~^^^^^^^^^^^^^^^^^
  File "E:\Github\todo2\todoServer\venv\Lib\site-packages\django\db\models\query.py", line 633, in get
    clone = self._chain() if self.query.combinator else self.filter(*args, **kwargs)
                                                        ~~~~~~~~~~~^^^^^^^^^^^^^^^^^
  File "E:\Github\todo2\todoServer\venv\Lib\site-packages\django\db\models\query.py", line 1476, in filter
    return self._filter_or_exclude(False, args, kwargs)
           ~~~~~~~~~~~~~~~~~~~~~~~^^^^^^^^^^^^^^^^^^^^^
  File "E:\Github\todo2\todoServer\venv\Lib\site-packages\django\db\models\query.py", line 1494, in _filter_or_exclude
    clone._filter_or_exclude_inplace(negate, args, kwargs)
    ~~~~~~~~~~~~~~~~~~~~~~~~~~~~~~~~^^^^^^^^^^^^^^^^^^^^^^
  File "E:\Github\todo2\todoServer\venv\Lib\site-packages\django\db\models\query.py", line 1501, in _filter_or_exclude_inplace
    self._query.add_q(Q(*args, **kwargs))
    ~~~~~~~~~~~~~~~~~^^^^^^^^^^^^^^^^^^^^
  File "E:\Github\todo2\todoServer\venv\Lib\site-packages\django\db\models\sql\query.py", line 1600, in add_q
    clause, _ = self._add_q(q_object, self.used_aliases)
                ~~~~~~~~~~~^^^^^^^^^^^^^^^^^^^^^^^^^^^^^
  File "E:\Github\todo2\todoServer\venv\Lib\site-packages\django\db\models\sql\query.py", line 1632, in _add_q
    child_clause, needed_inner = self.build_filter(
                                 ~~~~~~~~~~~~~~~~~^
        child,
        ^^^^^^
    ...<7 lines>...
        update_join_types=update_join_types,
        ^^^^^^^^^^^^^^^^^^^^^^^^^^^^^^^^^^^^
    )
    ^
  File "E:\Github\todo2\todoServer\venv\Lib\site-packages\django\db\models\sql\query.py", line 1546, in build_filter
    condition = self.build_lookup(lookups, col, value)
  File "E:\Github\todo2\todoServer\venv\Lib\site-packages\django\db\models\sql\query.py", line 1376, in build_lookup
    lookup = lookup_class(lhs, rhs)
  File "E:\Github\todo2\todoServer\venv\Lib\site-packages\django\db\models\lookups.py", line 30, in __init__
    self.rhs = self.get_prep_lookup()
               ~~~~~~~~~~~~~~~~~~~~^^
  File "E:\Github\todo2\todoServer\venv\Lib\site-packages\django\db\models\lookups.py", line 362, in get_prep_lookup
    return super().get_prep_lookup()
           ~~~~~~~~~~~~~~~~~~~~~~~^^
  File "E:\Github\todo2\todoServer\venv\Lib\site-packages\django\db\models\lookups.py", line 88, in get_prep_lookup
    return self.lhs.output_field.get_prep_value(self.rhs)
           ~~~~~~~~~~~~~~~~~~~~~~~~~~~~~~~~~~~~^^^^^^^^^^
  File "E:\Github\todo2\todoServer\venv\Lib\site-packages\django\db\models\fields\__init__.py", line 2114, in get_prep_value
    raise e.__class__(
        "Field '%s' expected a number but got %r." % (self.name, value),
    ) from e
ValueError: Field 'id' expected a number but got 'month_stats'.

During handling of the above exception, another exception occurred:

Traceback (most recent call last):
  File "E:\Github\todo2\todoServer\venv\Lib\site-packages\rest_framework\views.py", line 506, in dispatch
    response = handler(request, *args, **kwargs)
  File "E:\Github\todo2\todoServer\venv\Lib\site-packages\rest_framework\mixins.py", line 54, in retrieve
    instance = self.get_object()
  File "E:\Github\todo2\todoServer\venv\Lib\site-packages\rest_framework\generics.py", line 96, in get_object
    obj = get_object_or_404(queryset, **filter_kwargs)
  File "E:\Github\todo2\todoServer\venv\Lib\site-packages\rest_framework\generics.py", line 21, in get_object_or_404
    raise Http404
django.http.response.Http404

    
ERROR 2024-12-16 21:54:31,023 utils 9952 7504 
API Error Details:
View: TaskViewSet
URL: /api/v1/tasks/tasks/month_stats/
Method: GET
User: fx0883
Error Type: Http404
Error Message: 
Stack Trace:
Traceback (most recent call last):
  File "E:\Github\todo2\todoServer\venv\Lib\site-packages\django\db\models\fields\__init__.py", line 2112, in get_prep_value
    return int(value)
ValueError: invalid literal for int() with base 10: 'month_stats'

The above exception was the direct cause of the following exception:

Traceback (most recent call last):
  File "E:\Github\todo2\todoServer\venv\Lib\site-packages\rest_framework\generics.py", line 19, in get_object_or_404
    return _get_object_or_404(queryset, *filter_args, **filter_kwargs)
  File "E:\Github\todo2\todoServer\venv\Lib\site-packages\django\shortcuts.py", line 85, in get_object_or_404
    return queryset.get(*args, **kwargs)
           ~~~~~~~~~~~~^^^^^^^^^^^^^^^^^
  File "E:\Github\todo2\todoServer\venv\Lib\site-packages\django\db\models\query.py", line 633, in get
    clone = self._chain() if self.query.combinator else self.filter(*args, **kwargs)
                                                        ~~~~~~~~~~~^^^^^^^^^^^^^^^^^
  File "E:\Github\todo2\todoServer\venv\Lib\site-packages\django\db\models\query.py", line 1476, in filter
    return self._filter_or_exclude(False, args, kwargs)
           ~~~~~~~~~~~~~~~~~~~~~~~^^^^^^^^^^^^^^^^^^^^^
  File "E:\Github\todo2\todoServer\venv\Lib\site-packages\django\db\models\query.py", line 1494, in _filter_or_exclude
    clone._filter_or_exclude_inplace(negate, args, kwargs)
    ~~~~~~~~~~~~~~~~~~~~~~~~~~~~~~~~^^^^^^^^^^^^^^^^^^^^^^
  File "E:\Github\todo2\todoServer\venv\Lib\site-packages\django\db\models\query.py", line 1501, in _filter_or_exclude_inplace
    self._query.add_q(Q(*args, **kwargs))
    ~~~~~~~~~~~~~~~~~^^^^^^^^^^^^^^^^^^^^
  File "E:\Github\todo2\todoServer\venv\Lib\site-packages\django\db\models\sql\query.py", line 1600, in add_q
    clause, _ = self._add_q(q_object, self.used_aliases)
                ~~~~~~~~~~~^^^^^^^^^^^^^^^^^^^^^^^^^^^^^
  File "E:\Github\todo2\todoServer\venv\Lib\site-packages\django\db\models\sql\query.py", line 1632, in _add_q
    child_clause, needed_inner = self.build_filter(
                                 ~~~~~~~~~~~~~~~~~^
        child,
        ^^^^^^
    ...<7 lines>...
        update_join_types=update_join_types,
        ^^^^^^^^^^^^^^^^^^^^^^^^^^^^^^^^^^^^
    )
    ^
  File "E:\Github\todo2\todoServer\venv\Lib\site-packages\django\db\models\sql\query.py", line 1546, in build_filter
    condition = self.build_lookup(lookups, col, value)
  File "E:\Github\todo2\todoServer\venv\Lib\site-packages\django\db\models\sql\query.py", line 1376, in build_lookup
    lookup = lookup_class(lhs, rhs)
  File "E:\Github\todo2\todoServer\venv\Lib\site-packages\django\db\models\lookups.py", line 30, in __init__
    self.rhs = self.get_prep_lookup()
               ~~~~~~~~~~~~~~~~~~~~^^
  File "E:\Github\todo2\todoServer\venv\Lib\site-packages\django\db\models\lookups.py", line 362, in get_prep_lookup
    return super().get_prep_lookup()
           ~~~~~~~~~~~~~~~~~~~~~~~^^
  File "E:\Github\todo2\todoServer\venv\Lib\site-packages\django\db\models\lookups.py", line 88, in get_prep_lookup
    return self.lhs.output_field.get_prep_value(self.rhs)
           ~~~~~~~~~~~~~~~~~~~~~~~~~~~~~~~~~~~~^^^^^^^^^^
  File "E:\Github\todo2\todoServer\venv\Lib\site-packages\django\db\models\fields\__init__.py", line 2114, in get_prep_value
    raise e.__class__(
        "Field '%s' expected a number but got %r." % (self.name, value),
    ) from e
ValueError: Field 'id' expected a number but got 'month_stats'.

During handling of the above exception, another exception occurred:

Traceback (most recent call last):
  File "E:\Github\todo2\todoServer\venv\Lib\site-packages\rest_framework\views.py", line 506, in dispatch
    response = handler(request, *args, **kwargs)
  File "E:\Github\todo2\todoServer\venv\Lib\site-packages\rest_framework\mixins.py", line 54, in retrieve
    instance = self.get_object()
  File "E:\Github\todo2\todoServer\venv\Lib\site-packages\rest_framework\generics.py", line 96, in get_object
    obj = get_object_or_404(queryset, **filter_kwargs)
  File "E:\Github\todo2\todoServer\venv\Lib\site-packages\rest_framework\generics.py", line 21, in get_object_or_404
    raise Http404
django.http.response.Http404

    
ERROR 2024-12-16 21:54:31,630 utils 9952 7504 
API Error Details:
View: TaskViewSet
URL: /api/v1/tasks/tasks/month_stats/
Method: GET
User: fx0883
Error Type: Http404
Error Message: 
Stack Trace:
Traceback (most recent call last):
  File "E:\Github\todo2\todoServer\venv\Lib\site-packages\django\db\models\fields\__init__.py", line 2112, in get_prep_value
    return int(value)
ValueError: invalid literal for int() with base 10: 'month_stats'

The above exception was the direct cause of the following exception:

Traceback (most recent call last):
  File "E:\Github\todo2\todoServer\venv\Lib\site-packages\rest_framework\generics.py", line 19, in get_object_or_404
    return _get_object_or_404(queryset, *filter_args, **filter_kwargs)
  File "E:\Github\todo2\todoServer\venv\Lib\site-packages\django\shortcuts.py", line 85, in get_object_or_404
    return queryset.get(*args, **kwargs)
           ~~~~~~~~~~~~^^^^^^^^^^^^^^^^^
  File "E:\Github\todo2\todoServer\venv\Lib\site-packages\django\db\models\query.py", line 633, in get
    clone = self._chain() if self.query.combinator else self.filter(*args, **kwargs)
                                                        ~~~~~~~~~~~^^^^^^^^^^^^^^^^^
  File "E:\Github\todo2\todoServer\venv\Lib\site-packages\django\db\models\query.py", line 1476, in filter
    return self._filter_or_exclude(False, args, kwargs)
           ~~~~~~~~~~~~~~~~~~~~~~~^^^^^^^^^^^^^^^^^^^^^
  File "E:\Github\todo2\todoServer\venv\Lib\site-packages\django\db\models\query.py", line 1494, in _filter_or_exclude
    clone._filter_or_exclude_inplace(negate, args, kwargs)
    ~~~~~~~~~~~~~~~~~~~~~~~~~~~~~~~~^^^^^^^^^^^^^^^^^^^^^^
  File "E:\Github\todo2\todoServer\venv\Lib\site-packages\django\db\models\query.py", line 1501, in _filter_or_exclude_inplace
    self._query.add_q(Q(*args, **kwargs))
    ~~~~~~~~~~~~~~~~~^^^^^^^^^^^^^^^^^^^^
  File "E:\Github\todo2\todoServer\venv\Lib\site-packages\django\db\models\sql\query.py", line 1600, in add_q
    clause, _ = self._add_q(q_object, self.used_aliases)
                ~~~~~~~~~~~^^^^^^^^^^^^^^^^^^^^^^^^^^^^^
  File "E:\Github\todo2\todoServer\venv\Lib\site-packages\django\db\models\sql\query.py", line 1632, in _add_q
    child_clause, needed_inner = self.build_filter(
                                 ~~~~~~~~~~~~~~~~~^
        child,
        ^^^^^^
    ...<7 lines>...
        update_join_types=update_join_types,
        ^^^^^^^^^^^^^^^^^^^^^^^^^^^^^^^^^^^^
    )
    ^
  File "E:\Github\todo2\todoServer\venv\Lib\site-packages\django\db\models\sql\query.py", line 1546, in build_filter
    condition = self.build_lookup(lookups, col, value)
  File "E:\Github\todo2\todoServer\venv\Lib\site-packages\django\db\models\sql\query.py", line 1376, in build_lookup
    lookup = lookup_class(lhs, rhs)
  File "E:\Github\todo2\todoServer\venv\Lib\site-packages\django\db\models\lookups.py", line 30, in __init__
    self.rhs = self.get_prep_lookup()
               ~~~~~~~~~~~~~~~~~~~~^^
  File "E:\Github\todo2\todoServer\venv\Lib\site-packages\django\db\models\lookups.py", line 362, in get_prep_lookup
    return super().get_prep_lookup()
           ~~~~~~~~~~~~~~~~~~~~~~~^^
  File "E:\Github\todo2\todoServer\venv\Lib\site-packages\django\db\models\lookups.py", line 88, in get_prep_lookup
    return self.lhs.output_field.get_prep_value(self.rhs)
           ~~~~~~~~~~~~~~~~~~~~~~~~~~~~~~~~~~~~^^^^^^^^^^
  File "E:\Github\todo2\todoServer\venv\Lib\site-packages\django\db\models\fields\__init__.py", line 2114, in get_prep_value
    raise e.__class__(
        "Field '%s' expected a number but got %r." % (self.name, value),
    ) from e
ValueError: Field 'id' expected a number but got 'month_stats'.

During handling of the above exception, another exception occurred:

Traceback (most recent call last):
  File "E:\Github\todo2\todoServer\venv\Lib\site-packages\rest_framework\views.py", line 506, in dispatch
    response = handler(request, *args, **kwargs)
  File "E:\Github\todo2\todoServer\venv\Lib\site-packages\rest_framework\mixins.py", line 54, in retrieve
    instance = self.get_object()
  File "E:\Github\todo2\todoServer\venv\Lib\site-packages\rest_framework\generics.py", line 96, in get_object
    obj = get_object_or_404(queryset, **filter_kwargs)
  File "E:\Github\todo2\todoServer\venv\Lib\site-packages\rest_framework\generics.py", line 21, in get_object_or_404
    raise Http404
django.http.response.Http404

    
ERROR 2024-12-16 21:54:32,085 utils 9952 7504 
API Error Details:
View: TaskViewSet
URL: /api/v1/tasks/tasks/month_stats/
Method: GET
User: fx0883
Error Type: Http404
Error Message: 
Stack Trace:
Traceback (most recent call last):
  File "E:\Github\todo2\todoServer\venv\Lib\site-packages\django\db\models\fields\__init__.py", line 2112, in get_prep_value
    return int(value)
ValueError: invalid literal for int() with base 10: 'month_stats'

The above exception was the direct cause of the following exception:

Traceback (most recent call last):
  File "E:\Github\todo2\todoServer\venv\Lib\site-packages\rest_framework\generics.py", line 19, in get_object_or_404
    return _get_object_or_404(queryset, *filter_args, **filter_kwargs)
  File "E:\Github\todo2\todoServer\venv\Lib\site-packages\django\shortcuts.py", line 85, in get_object_or_404
    return queryset.get(*args, **kwargs)
           ~~~~~~~~~~~~^^^^^^^^^^^^^^^^^
  File "E:\Github\todo2\todoServer\venv\Lib\site-packages\django\db\models\query.py", line 633, in get
    clone = self._chain() if self.query.combinator else self.filter(*args, **kwargs)
                                                        ~~~~~~~~~~~^^^^^^^^^^^^^^^^^
  File "E:\Github\todo2\todoServer\venv\Lib\site-packages\django\db\models\query.py", line 1476, in filter
    return self._filter_or_exclude(False, args, kwargs)
           ~~~~~~~~~~~~~~~~~~~~~~~^^^^^^^^^^^^^^^^^^^^^
  File "E:\Github\todo2\todoServer\venv\Lib\site-packages\django\db\models\query.py", line 1494, in _filter_or_exclude
    clone._filter_or_exclude_inplace(negate, args, kwargs)
    ~~~~~~~~~~~~~~~~~~~~~~~~~~~~~~~~^^^^^^^^^^^^^^^^^^^^^^
  File "E:\Github\todo2\todoServer\venv\Lib\site-packages\django\db\models\query.py", line 1501, in _filter_or_exclude_inplace
    self._query.add_q(Q(*args, **kwargs))
    ~~~~~~~~~~~~~~~~~^^^^^^^^^^^^^^^^^^^^
  File "E:\Github\todo2\todoServer\venv\Lib\site-packages\django\db\models\sql\query.py", line 1600, in add_q
    clause, _ = self._add_q(q_object, self.used_aliases)
                ~~~~~~~~~~~^^^^^^^^^^^^^^^^^^^^^^^^^^^^^
  File "E:\Github\todo2\todoServer\venv\Lib\site-packages\django\db\models\sql\query.py", line 1632, in _add_q
    child_clause, needed_inner = self.build_filter(
                                 ~~~~~~~~~~~~~~~~~^
        child,
        ^^^^^^
    ...<7 lines>...
        update_join_types=update_join_types,
        ^^^^^^^^^^^^^^^^^^^^^^^^^^^^^^^^^^^^
    )
    ^
  File "E:\Github\todo2\todoServer\venv\Lib\site-packages\django\db\models\sql\query.py", line 1546, in build_filter
    condition = self.build_lookup(lookups, col, value)
  File "E:\Github\todo2\todoServer\venv\Lib\site-packages\django\db\models\sql\query.py", line 1376, in build_lookup
    lookup = lookup_class(lhs, rhs)
  File "E:\Github\todo2\todoServer\venv\Lib\site-packages\django\db\models\lookups.py", line 30, in __init__
    self.rhs = self.get_prep_lookup()
               ~~~~~~~~~~~~~~~~~~~~^^
  File "E:\Github\todo2\todoServer\venv\Lib\site-packages\django\db\models\lookups.py", line 362, in get_prep_lookup
    return super().get_prep_lookup()
           ~~~~~~~~~~~~~~~~~~~~~~~^^
  File "E:\Github\todo2\todoServer\venv\Lib\site-packages\django\db\models\lookups.py", line 88, in get_prep_lookup
    return self.lhs.output_field.get_prep_value(self.rhs)
           ~~~~~~~~~~~~~~~~~~~~~~~~~~~~~~~~~~~~^^^^^^^^^^
  File "E:\Github\todo2\todoServer\venv\Lib\site-packages\django\db\models\fields\__init__.py", line 2114, in get_prep_value
    raise e.__class__(
        "Field '%s' expected a number but got %r." % (self.name, value),
    ) from e
ValueError: Field 'id' expected a number but got 'month_stats'.

During handling of the above exception, another exception occurred:

Traceback (most recent call last):
  File "E:\Github\todo2\todoServer\venv\Lib\site-packages\rest_framework\views.py", line 506, in dispatch
    response = handler(request, *args, **kwargs)
  File "E:\Github\todo2\todoServer\venv\Lib\site-packages\rest_framework\mixins.py", line 54, in retrieve
    instance = self.get_object()
  File "E:\Github\todo2\todoServer\venv\Lib\site-packages\rest_framework\generics.py", line 96, in get_object
    obj = get_object_or_404(queryset, **filter_kwargs)
  File "E:\Github\todo2\todoServer\venv\Lib\site-packages\rest_framework\generics.py", line 21, in get_object_or_404
    raise Http404
django.http.response.Http404

    
ERROR 2024-12-16 21:54:32,565 utils 9952 7504 
API Error Details:
View: TaskViewSet
URL: /api/v1/tasks/tasks/month_stats/
Method: GET
User: fx0883
Error Type: Http404
Error Message: 
Stack Trace:
Traceback (most recent call last):
  File "E:\Github\todo2\todoServer\venv\Lib\site-packages\django\db\models\fields\__init__.py", line 2112, in get_prep_value
    return int(value)
ValueError: invalid literal for int() with base 10: 'month_stats'

The above exception was the direct cause of the following exception:

Traceback (most recent call last):
  File "E:\Github\todo2\todoServer\venv\Lib\site-packages\rest_framework\generics.py", line 19, in get_object_or_404
    return _get_object_or_404(queryset, *filter_args, **filter_kwargs)
  File "E:\Github\todo2\todoServer\venv\Lib\site-packages\django\shortcuts.py", line 85, in get_object_or_404
    return queryset.get(*args, **kwargs)
           ~~~~~~~~~~~~^^^^^^^^^^^^^^^^^
  File "E:\Github\todo2\todoServer\venv\Lib\site-packages\django\db\models\query.py", line 633, in get
    clone = self._chain() if self.query.combinator else self.filter(*args, **kwargs)
                                                        ~~~~~~~~~~~^^^^^^^^^^^^^^^^^
  File "E:\Github\todo2\todoServer\venv\Lib\site-packages\django\db\models\query.py", line 1476, in filter
    return self._filter_or_exclude(False, args, kwargs)
           ~~~~~~~~~~~~~~~~~~~~~~~^^^^^^^^^^^^^^^^^^^^^
  File "E:\Github\todo2\todoServer\venv\Lib\site-packages\django\db\models\query.py", line 1494, in _filter_or_exclude
    clone._filter_or_exclude_inplace(negate, args, kwargs)
    ~~~~~~~~~~~~~~~~~~~~~~~~~~~~~~~~^^^^^^^^^^^^^^^^^^^^^^
  File "E:\Github\todo2\todoServer\venv\Lib\site-packages\django\db\models\query.py", line 1501, in _filter_or_exclude_inplace
    self._query.add_q(Q(*args, **kwargs))
    ~~~~~~~~~~~~~~~~~^^^^^^^^^^^^^^^^^^^^
  File "E:\Github\todo2\todoServer\venv\Lib\site-packages\django\db\models\sql\query.py", line 1600, in add_q
    clause, _ = self._add_q(q_object, self.used_aliases)
                ~~~~~~~~~~~^^^^^^^^^^^^^^^^^^^^^^^^^^^^^
  File "E:\Github\todo2\todoServer\venv\Lib\site-packages\django\db\models\sql\query.py", line 1632, in _add_q
    child_clause, needed_inner = self.build_filter(
                                 ~~~~~~~~~~~~~~~~~^
        child,
        ^^^^^^
    ...<7 lines>...
        update_join_types=update_join_types,
        ^^^^^^^^^^^^^^^^^^^^^^^^^^^^^^^^^^^^
    )
    ^
  File "E:\Github\todo2\todoServer\venv\Lib\site-packages\django\db\models\sql\query.py", line 1546, in build_filter
    condition = self.build_lookup(lookups, col, value)
  File "E:\Github\todo2\todoServer\venv\Lib\site-packages\django\db\models\sql\query.py", line 1376, in build_lookup
    lookup = lookup_class(lhs, rhs)
  File "E:\Github\todo2\todoServer\venv\Lib\site-packages\django\db\models\lookups.py", line 30, in __init__
    self.rhs = self.get_prep_lookup()
               ~~~~~~~~~~~~~~~~~~~~^^
  File "E:\Github\todo2\todoServer\venv\Lib\site-packages\django\db\models\lookups.py", line 362, in get_prep_lookup
    return super().get_prep_lookup()
           ~~~~~~~~~~~~~~~~~~~~~~~^^
  File "E:\Github\todo2\todoServer\venv\Lib\site-packages\django\db\models\lookups.py", line 88, in get_prep_lookup
    return self.lhs.output_field.get_prep_value(self.rhs)
           ~~~~~~~~~~~~~~~~~~~~~~~~~~~~~~~~~~~~^^^^^^^^^^
  File "E:\Github\todo2\todoServer\venv\Lib\site-packages\django\db\models\fields\__init__.py", line 2114, in get_prep_value
    raise e.__class__(
        "Field '%s' expected a number but got %r." % (self.name, value),
    ) from e
ValueError: Field 'id' expected a number but got 'month_stats'.

During handling of the above exception, another exception occurred:

Traceback (most recent call last):
  File "E:\Github\todo2\todoServer\venv\Lib\site-packages\rest_framework\views.py", line 506, in dispatch
    response = handler(request, *args, **kwargs)
  File "E:\Github\todo2\todoServer\venv\Lib\site-packages\rest_framework\mixins.py", line 54, in retrieve
    instance = self.get_object()
  File "E:\Github\todo2\todoServer\venv\Lib\site-packages\rest_framework\generics.py", line 96, in get_object
    obj = get_object_or_404(queryset, **filter_kwargs)
  File "E:\Github\todo2\todoServer\venv\Lib\site-packages\rest_framework\generics.py", line 21, in get_object_or_404
    raise Http404
django.http.response.Http404

    
ERROR 2024-12-16 21:54:32,860 utils 9952 7504 
API Error Details:
View: TaskViewSet
URL: /api/v1/tasks/tasks/month_stats/
Method: GET
User: fx0883
Error Type: Http404
Error Message: 
Stack Trace:
Traceback (most recent call last):
  File "E:\Github\todo2\todoServer\venv\Lib\site-packages\django\db\models\fields\__init__.py", line 2112, in get_prep_value
    return int(value)
ValueError: invalid literal for int() with base 10: 'month_stats'

The above exception was the direct cause of the following exception:

Traceback (most recent call last):
  File "E:\Github\todo2\todoServer\venv\Lib\site-packages\rest_framework\generics.py", line 19, in get_object_or_404
    return _get_object_or_404(queryset, *filter_args, **filter_kwargs)
  File "E:\Github\todo2\todoServer\venv\Lib\site-packages\django\shortcuts.py", line 85, in get_object_or_404
    return queryset.get(*args, **kwargs)
           ~~~~~~~~~~~~^^^^^^^^^^^^^^^^^
  File "E:\Github\todo2\todoServer\venv\Lib\site-packages\django\db\models\query.py", line 633, in get
    clone = self._chain() if self.query.combinator else self.filter(*args, **kwargs)
                                                        ~~~~~~~~~~~^^^^^^^^^^^^^^^^^
  File "E:\Github\todo2\todoServer\venv\Lib\site-packages\django\db\models\query.py", line 1476, in filter
    return self._filter_or_exclude(False, args, kwargs)
           ~~~~~~~~~~~~~~~~~~~~~~~^^^^^^^^^^^^^^^^^^^^^
  File "E:\Github\todo2\todoServer\venv\Lib\site-packages\django\db\models\query.py", line 1494, in _filter_or_exclude
    clone._filter_or_exclude_inplace(negate, args, kwargs)
    ~~~~~~~~~~~~~~~~~~~~~~~~~~~~~~~~^^^^^^^^^^^^^^^^^^^^^^
  File "E:\Github\todo2\todoServer\venv\Lib\site-packages\django\db\models\query.py", line 1501, in _filter_or_exclude_inplace
    self._query.add_q(Q(*args, **kwargs))
    ~~~~~~~~~~~~~~~~~^^^^^^^^^^^^^^^^^^^^
  File "E:\Github\todo2\todoServer\venv\Lib\site-packages\django\db\models\sql\query.py", line 1600, in add_q
    clause, _ = self._add_q(q_object, self.used_aliases)
                ~~~~~~~~~~~^^^^^^^^^^^^^^^^^^^^^^^^^^^^^
  File "E:\Github\todo2\todoServer\venv\Lib\site-packages\django\db\models\sql\query.py", line 1632, in _add_q
    child_clause, needed_inner = self.build_filter(
                                 ~~~~~~~~~~~~~~~~~^
        child,
        ^^^^^^
    ...<7 lines>...
        update_join_types=update_join_types,
        ^^^^^^^^^^^^^^^^^^^^^^^^^^^^^^^^^^^^
    )
    ^
  File "E:\Github\todo2\todoServer\venv\Lib\site-packages\django\db\models\sql\query.py", line 1546, in build_filter
    condition = self.build_lookup(lookups, col, value)
  File "E:\Github\todo2\todoServer\venv\Lib\site-packages\django\db\models\sql\query.py", line 1376, in build_lookup
    lookup = lookup_class(lhs, rhs)
  File "E:\Github\todo2\todoServer\venv\Lib\site-packages\django\db\models\lookups.py", line 30, in __init__
    self.rhs = self.get_prep_lookup()
               ~~~~~~~~~~~~~~~~~~~~^^
  File "E:\Github\todo2\todoServer\venv\Lib\site-packages\django\db\models\lookups.py", line 362, in get_prep_lookup
    return super().get_prep_lookup()
           ~~~~~~~~~~~~~~~~~~~~~~~^^
  File "E:\Github\todo2\todoServer\venv\Lib\site-packages\django\db\models\lookups.py", line 88, in get_prep_lookup
    return self.lhs.output_field.get_prep_value(self.rhs)
           ~~~~~~~~~~~~~~~~~~~~~~~~~~~~~~~~~~~~^^^^^^^^^^
  File "E:\Github\todo2\todoServer\venv\Lib\site-packages\django\db\models\fields\__init__.py", line 2114, in get_prep_value
    raise e.__class__(
        "Field '%s' expected a number but got %r." % (self.name, value),
    ) from e
ValueError: Field 'id' expected a number but got 'month_stats'.

During handling of the above exception, another exception occurred:

Traceback (most recent call last):
  File "E:\Github\todo2\todoServer\venv\Lib\site-packages\rest_framework\views.py", line 506, in dispatch
    response = handler(request, *args, **kwargs)
  File "E:\Github\todo2\todoServer\venv\Lib\site-packages\rest_framework\mixins.py", line 54, in retrieve
    instance = self.get_object()
  File "E:\Github\todo2\todoServer\venv\Lib\site-packages\rest_framework\generics.py", line 96, in get_object
    obj = get_object_or_404(queryset, **filter_kwargs)
  File "E:\Github\todo2\todoServer\venv\Lib\site-packages\rest_framework\generics.py", line 21, in get_object_or_404
    raise Http404
django.http.response.Http404

    
ERROR 2024-12-16 21:54:33,072 utils 9952 7504 
API Error Details:
View: TaskViewSet
URL: /api/v1/tasks/tasks/month_stats/
Method: GET
User: fx0883
Error Type: Http404
Error Message: 
Stack Trace:
Traceback (most recent call last):
  File "E:\Github\todo2\todoServer\venv\Lib\site-packages\django\db\models\fields\__init__.py", line 2112, in get_prep_value
    return int(value)
ValueError: invalid literal for int() with base 10: 'month_stats'

The above exception was the direct cause of the following exception:

Traceback (most recent call last):
  File "E:\Github\todo2\todoServer\venv\Lib\site-packages\rest_framework\generics.py", line 19, in get_object_or_404
    return _get_object_or_404(queryset, *filter_args, **filter_kwargs)
  File "E:\Github\todo2\todoServer\venv\Lib\site-packages\django\shortcuts.py", line 85, in get_object_or_404
    return queryset.get(*args, **kwargs)
           ~~~~~~~~~~~~^^^^^^^^^^^^^^^^^
  File "E:\Github\todo2\todoServer\venv\Lib\site-packages\django\db\models\query.py", line 633, in get
    clone = self._chain() if self.query.combinator else self.filter(*args, **kwargs)
                                                        ~~~~~~~~~~~^^^^^^^^^^^^^^^^^
  File "E:\Github\todo2\todoServer\venv\Lib\site-packages\django\db\models\query.py", line 1476, in filter
    return self._filter_or_exclude(False, args, kwargs)
           ~~~~~~~~~~~~~~~~~~~~~~~^^^^^^^^^^^^^^^^^^^^^
  File "E:\Github\todo2\todoServer\venv\Lib\site-packages\django\db\models\query.py", line 1494, in _filter_or_exclude
    clone._filter_or_exclude_inplace(negate, args, kwargs)
    ~~~~~~~~~~~~~~~~~~~~~~~~~~~~~~~~^^^^^^^^^^^^^^^^^^^^^^
  File "E:\Github\todo2\todoServer\venv\Lib\site-packages\django\db\models\query.py", line 1501, in _filter_or_exclude_inplace
    self._query.add_q(Q(*args, **kwargs))
    ~~~~~~~~~~~~~~~~~^^^^^^^^^^^^^^^^^^^^
  File "E:\Github\todo2\todoServer\venv\Lib\site-packages\django\db\models\sql\query.py", line 1600, in add_q
    clause, _ = self._add_q(q_object, self.used_aliases)
                ~~~~~~~~~~~^^^^^^^^^^^^^^^^^^^^^^^^^^^^^
  File "E:\Github\todo2\todoServer\venv\Lib\site-packages\django\db\models\sql\query.py", line 1632, in _add_q
    child_clause, needed_inner = self.build_filter(
                                 ~~~~~~~~~~~~~~~~~^
        child,
        ^^^^^^
    ...<7 lines>...
        update_join_types=update_join_types,
        ^^^^^^^^^^^^^^^^^^^^^^^^^^^^^^^^^^^^
    )
    ^
  File "E:\Github\todo2\todoServer\venv\Lib\site-packages\django\db\models\sql\query.py", line 1546, in build_filter
    condition = self.build_lookup(lookups, col, value)
  File "E:\Github\todo2\todoServer\venv\Lib\site-packages\django\db\models\sql\query.py", line 1376, in build_lookup
    lookup = lookup_class(lhs, rhs)
  File "E:\Github\todo2\todoServer\venv\Lib\site-packages\django\db\models\lookups.py", line 30, in __init__
    self.rhs = self.get_prep_lookup()
               ~~~~~~~~~~~~~~~~~~~~^^
  File "E:\Github\todo2\todoServer\venv\Lib\site-packages\django\db\models\lookups.py", line 362, in get_prep_lookup
    return super().get_prep_lookup()
           ~~~~~~~~~~~~~~~~~~~~~~~^^
  File "E:\Github\todo2\todoServer\venv\Lib\site-packages\django\db\models\lookups.py", line 88, in get_prep_lookup
    return self.lhs.output_field.get_prep_value(self.rhs)
           ~~~~~~~~~~~~~~~~~~~~~~~~~~~~~~~~~~~~^^^^^^^^^^
  File "E:\Github\todo2\todoServer\venv\Lib\site-packages\django\db\models\fields\__init__.py", line 2114, in get_prep_value
    raise e.__class__(
        "Field '%s' expected a number but got %r." % (self.name, value),
    ) from e
ValueError: Field 'id' expected a number but got 'month_stats'.

During handling of the above exception, another exception occurred:

Traceback (most recent call last):
  File "E:\Github\todo2\todoServer\venv\Lib\site-packages\rest_framework\views.py", line 506, in dispatch
    response = handler(request, *args, **kwargs)
  File "E:\Github\todo2\todoServer\venv\Lib\site-packages\rest_framework\mixins.py", line 54, in retrieve
    instance = self.get_object()
  File "E:\Github\todo2\todoServer\venv\Lib\site-packages\rest_framework\generics.py", line 96, in get_object
    obj = get_object_or_404(queryset, **filter_kwargs)
  File "E:\Github\todo2\todoServer\venv\Lib\site-packages\rest_framework\generics.py", line 21, in get_object_or_404
    raise Http404
django.http.response.Http404

    
ERROR 2024-12-16 21:54:54,754 utils 9952 7504 
API Error Details:
View: TaskViewSet
URL: /api/v1/tasks/tasks/daily_trend/
Method: GET
User: fx0883
Error Type: Http404
Error Message: 
Stack Trace:
Traceback (most recent call last):
  File "E:\Github\todo2\todoServer\venv\Lib\site-packages\django\db\models\fields\__init__.py", line 2112, in get_prep_value
    return int(value)
ValueError: invalid literal for int() with base 10: 'daily_trend'

The above exception was the direct cause of the following exception:

Traceback (most recent call last):
  File "E:\Github\todo2\todoServer\venv\Lib\site-packages\rest_framework\generics.py", line 19, in get_object_or_404
    return _get_object_or_404(queryset, *filter_args, **filter_kwargs)
  File "E:\Github\todo2\todoServer\venv\Lib\site-packages\django\shortcuts.py", line 85, in get_object_or_404
    return queryset.get(*args, **kwargs)
           ~~~~~~~~~~~~^^^^^^^^^^^^^^^^^
  File "E:\Github\todo2\todoServer\venv\Lib\site-packages\django\db\models\query.py", line 633, in get
    clone = self._chain() if self.query.combinator else self.filter(*args, **kwargs)
                                                        ~~~~~~~~~~~^^^^^^^^^^^^^^^^^
  File "E:\Github\todo2\todoServer\venv\Lib\site-packages\django\db\models\query.py", line 1476, in filter
    return self._filter_or_exclude(False, args, kwargs)
           ~~~~~~~~~~~~~~~~~~~~~~~^^^^^^^^^^^^^^^^^^^^^
  File "E:\Github\todo2\todoServer\venv\Lib\site-packages\django\db\models\query.py", line 1494, in _filter_or_exclude
    clone._filter_or_exclude_inplace(negate, args, kwargs)
    ~~~~~~~~~~~~~~~~~~~~~~~~~~~~~~~~^^^^^^^^^^^^^^^^^^^^^^
  File "E:\Github\todo2\todoServer\venv\Lib\site-packages\django\db\models\query.py", line 1501, in _filter_or_exclude_inplace
    self._query.add_q(Q(*args, **kwargs))
    ~~~~~~~~~~~~~~~~~^^^^^^^^^^^^^^^^^^^^
  File "E:\Github\todo2\todoServer\venv\Lib\site-packages\django\db\models\sql\query.py", line 1600, in add_q
    clause, _ = self._add_q(q_object, self.used_aliases)
                ~~~~~~~~~~~^^^^^^^^^^^^^^^^^^^^^^^^^^^^^
  File "E:\Github\todo2\todoServer\venv\Lib\site-packages\django\db\models\sql\query.py", line 1632, in _add_q
    child_clause, needed_inner = self.build_filter(
                                 ~~~~~~~~~~~~~~~~~^
        child,
        ^^^^^^
    ...<7 lines>...
        update_join_types=update_join_types,
        ^^^^^^^^^^^^^^^^^^^^^^^^^^^^^^^^^^^^
    )
    ^
  File "E:\Github\todo2\todoServer\venv\Lib\site-packages\django\db\models\sql\query.py", line 1546, in build_filter
    condition = self.build_lookup(lookups, col, value)
  File "E:\Github\todo2\todoServer\venv\Lib\site-packages\django\db\models\sql\query.py", line 1376, in build_lookup
    lookup = lookup_class(lhs, rhs)
  File "E:\Github\todo2\todoServer\venv\Lib\site-packages\django\db\models\lookups.py", line 30, in __init__
    self.rhs = self.get_prep_lookup()
               ~~~~~~~~~~~~~~~~~~~~^^
  File "E:\Github\todo2\todoServer\venv\Lib\site-packages\django\db\models\lookups.py", line 362, in get_prep_lookup
    return super().get_prep_lookup()
           ~~~~~~~~~~~~~~~~~~~~~~~^^
  File "E:\Github\todo2\todoServer\venv\Lib\site-packages\django\db\models\lookups.py", line 88, in get_prep_lookup
    return self.lhs.output_field.get_prep_value(self.rhs)
           ~~~~~~~~~~~~~~~~~~~~~~~~~~~~~~~~~~~~^^^^^^^^^^
  File "E:\Github\todo2\todoServer\venv\Lib\site-packages\django\db\models\fields\__init__.py", line 2114, in get_prep_value
    raise e.__class__(
        "Field '%s' expected a number but got %r." % (self.name, value),
    ) from e
ValueError: Field 'id' expected a number but got 'daily_trend'.

During handling of the above exception, another exception occurred:

Traceback (most recent call last):
  File "E:\Github\todo2\todoServer\venv\Lib\site-packages\rest_framework\views.py", line 506, in dispatch
    response = handler(request, *args, **kwargs)
  File "E:\Github\todo2\todoServer\venv\Lib\site-packages\rest_framework\mixins.py", line 54, in retrieve
    instance = self.get_object()
  File "E:\Github\todo2\todoServer\venv\Lib\site-packages\rest_framework\generics.py", line 96, in get_object
    obj = get_object_or_404(queryset, **filter_kwargs)
  File "E:\Github\todo2\todoServer\venv\Lib\site-packages\rest_framework\generics.py", line 21, in get_object_or_404
    raise Http404
django.http.response.Http404

    
ERROR 2024-12-16 21:54:59,241 utils 9952 7504 
API Error Details:
View: TaskViewSet
URL: /api/v1/tasks/tasks/category_stats/
Method: GET
User: fx0883
Error Type: Http404
Error Message: 
Stack Trace:
Traceback (most recent call last):
  File "E:\Github\todo2\todoServer\venv\Lib\site-packages\django\db\models\fields\__init__.py", line 2112, in get_prep_value
    return int(value)
ValueError: invalid literal for int() with base 10: 'category_stats'

The above exception was the direct cause of the following exception:

Traceback (most recent call last):
  File "E:\Github\todo2\todoServer\venv\Lib\site-packages\rest_framework\generics.py", line 19, in get_object_or_404
    return _get_object_or_404(queryset, *filter_args, **filter_kwargs)
  File "E:\Github\todo2\todoServer\venv\Lib\site-packages\django\shortcuts.py", line 85, in get_object_or_404
    return queryset.get(*args, **kwargs)
           ~~~~~~~~~~~~^^^^^^^^^^^^^^^^^
  File "E:\Github\todo2\todoServer\venv\Lib\site-packages\django\db\models\query.py", line 633, in get
    clone = self._chain() if self.query.combinator else self.filter(*args, **kwargs)
                                                        ~~~~~~~~~~~^^^^^^^^^^^^^^^^^
  File "E:\Github\todo2\todoServer\venv\Lib\site-packages\django\db\models\query.py", line 1476, in filter
    return self._filter_or_exclude(False, args, kwargs)
           ~~~~~~~~~~~~~~~~~~~~~~~^^^^^^^^^^^^^^^^^^^^^
  File "E:\Github\todo2\todoServer\venv\Lib\site-packages\django\db\models\query.py", line 1494, in _filter_or_exclude
    clone._filter_or_exclude_inplace(negate, args, kwargs)
    ~~~~~~~~~~~~~~~~~~~~~~~~~~~~~~~~^^^^^^^^^^^^^^^^^^^^^^
  File "E:\Github\todo2\todoServer\venv\Lib\site-packages\django\db\models\query.py", line 1501, in _filter_or_exclude_inplace
    self._query.add_q(Q(*args, **kwargs))
    ~~~~~~~~~~~~~~~~~^^^^^^^^^^^^^^^^^^^^
  File "E:\Github\todo2\todoServer\venv\Lib\site-packages\django\db\models\sql\query.py", line 1600, in add_q
    clause, _ = self._add_q(q_object, self.used_aliases)
                ~~~~~~~~~~~^^^^^^^^^^^^^^^^^^^^^^^^^^^^^
  File "E:\Github\todo2\todoServer\venv\Lib\site-packages\django\db\models\sql\query.py", line 1632, in _add_q
    child_clause, needed_inner = self.build_filter(
                                 ~~~~~~~~~~~~~~~~~^
        child,
        ^^^^^^
    ...<7 lines>...
        update_join_types=update_join_types,
        ^^^^^^^^^^^^^^^^^^^^^^^^^^^^^^^^^^^^
    )
    ^
  File "E:\Github\todo2\todoServer\venv\Lib\site-packages\django\db\models\sql\query.py", line 1546, in build_filter
    condition = self.build_lookup(lookups, col, value)
  File "E:\Github\todo2\todoServer\venv\Lib\site-packages\django\db\models\sql\query.py", line 1376, in build_lookup
    lookup = lookup_class(lhs, rhs)
  File "E:\Github\todo2\todoServer\venv\Lib\site-packages\django\db\models\lookups.py", line 30, in __init__
    self.rhs = self.get_prep_lookup()
               ~~~~~~~~~~~~~~~~~~~~^^
  File "E:\Github\todo2\todoServer\venv\Lib\site-packages\django\db\models\lookups.py", line 362, in get_prep_lookup
    return super().get_prep_lookup()
           ~~~~~~~~~~~~~~~~~~~~~~~^^
  File "E:\Github\todo2\todoServer\venv\Lib\site-packages\django\db\models\lookups.py", line 88, in get_prep_lookup
    return self.lhs.output_field.get_prep_value(self.rhs)
           ~~~~~~~~~~~~~~~~~~~~~~~~~~~~~~~~~~~~^^^^^^^^^^
  File "E:\Github\todo2\todoServer\venv\Lib\site-packages\django\db\models\fields\__init__.py", line 2114, in get_prep_value
    raise e.__class__(
        "Field '%s' expected a number but got %r." % (self.name, value),
    ) from e
ValueError: Field 'id' expected a number but got 'category_stats'.

During handling of the above exception, another exception occurred:

Traceback (most recent call last):
  File "E:\Github\todo2\todoServer\venv\Lib\site-packages\rest_framework\views.py", line 506, in dispatch
    response = handler(request, *args, **kwargs)
  File "E:\Github\todo2\todoServer\venv\Lib\site-packages\rest_framework\mixins.py", line 54, in retrieve
    instance = self.get_object()
  File "E:\Github\todo2\todoServer\venv\Lib\site-packages\rest_framework\generics.py", line 96, in get_object
    obj = get_object_or_404(queryset, **filter_kwargs)
  File "E:\Github\todo2\todoServer\venv\Lib\site-packages\rest_framework\generics.py", line 21, in get_object_or_404
    raise Http404
django.http.response.Http404

    
ERROR 2024-12-16 22:08:29,329 utils 10796 20856 
API Error Details:
View: TaskViewSet
URL: /api/v1/tasks/tasks/month_stats/
Method: GET
User: fx0883
Error Type: Http404
Error Message: 
Stack Trace:
Traceback (most recent call last):
  File "E:\Github\todo2\todoServer\venv\Lib\site-packages\django\db\models\fields\__init__.py", line 2112, in get_prep_value
    return int(value)
ValueError: invalid literal for int() with base 10: 'month_stats'

The above exception was the direct cause of the following exception:

Traceback (most recent call last):
  File "E:\Github\todo2\todoServer\venv\Lib\site-packages\rest_framework\generics.py", line 19, in get_object_or_404
    return _get_object_or_404(queryset, *filter_args, **filter_kwargs)
  File "E:\Github\todo2\todoServer\venv\Lib\site-packages\django\shortcuts.py", line 85, in get_object_or_404
    return queryset.get(*args, **kwargs)
           ~~~~~~~~~~~~^^^^^^^^^^^^^^^^^
  File "E:\Github\todo2\todoServer\venv\Lib\site-packages\django\db\models\query.py", line 633, in get
    clone = self._chain() if self.query.combinator else self.filter(*args, **kwargs)
                                                        ~~~~~~~~~~~^^^^^^^^^^^^^^^^^
  File "E:\Github\todo2\todoServer\venv\Lib\site-packages\django\db\models\query.py", line 1476, in filter
    return self._filter_or_exclude(False, args, kwargs)
           ~~~~~~~~~~~~~~~~~~~~~~~^^^^^^^^^^^^^^^^^^^^^
  File "E:\Github\todo2\todoServer\venv\Lib\site-packages\django\db\models\query.py", line 1494, in _filter_or_exclude
    clone._filter_or_exclude_inplace(negate, args, kwargs)
    ~~~~~~~~~~~~~~~~~~~~~~~~~~~~~~~~^^^^^^^^^^^^^^^^^^^^^^
  File "E:\Github\todo2\todoServer\venv\Lib\site-packages\django\db\models\query.py", line 1501, in _filter_or_exclude_inplace
    self._query.add_q(Q(*args, **kwargs))
    ~~~~~~~~~~~~~~~~~^^^^^^^^^^^^^^^^^^^^
  File "E:\Github\todo2\todoServer\venv\Lib\site-packages\django\db\models\sql\query.py", line 1600, in add_q
    clause, _ = self._add_q(q_object, self.used_aliases)
                ~~~~~~~~~~~^^^^^^^^^^^^^^^^^^^^^^^^^^^^^
  File "E:\Github\todo2\todoServer\venv\Lib\site-packages\django\db\models\sql\query.py", line 1632, in _add_q
    child_clause, needed_inner = self.build_filter(
                                 ~~~~~~~~~~~~~~~~~^
        child,
        ^^^^^^
    ...<7 lines>...
        update_join_types=update_join_types,
        ^^^^^^^^^^^^^^^^^^^^^^^^^^^^^^^^^^^^
    )
    ^
  File "E:\Github\todo2\todoServer\venv\Lib\site-packages\django\db\models\sql\query.py", line 1546, in build_filter
    condition = self.build_lookup(lookups, col, value)
  File "E:\Github\todo2\todoServer\venv\Lib\site-packages\django\db\models\sql\query.py", line 1376, in build_lookup
    lookup = lookup_class(lhs, rhs)
  File "E:\Github\todo2\todoServer\venv\Lib\site-packages\django\db\models\lookups.py", line 30, in __init__
    self.rhs = self.get_prep_lookup()
               ~~~~~~~~~~~~~~~~~~~~^^
  File "E:\Github\todo2\todoServer\venv\Lib\site-packages\django\db\models\lookups.py", line 362, in get_prep_lookup
    return super().get_prep_lookup()
           ~~~~~~~~~~~~~~~~~~~~~~~^^
  File "E:\Github\todo2\todoServer\venv\Lib\site-packages\django\db\models\lookups.py", line 88, in get_prep_lookup
    return self.lhs.output_field.get_prep_value(self.rhs)
           ~~~~~~~~~~~~~~~~~~~~~~~~~~~~~~~~~~~~^^^^^^^^^^
  File "E:\Github\todo2\todoServer\venv\Lib\site-packages\django\db\models\fields\__init__.py", line 2114, in get_prep_value
    raise e.__class__(
        "Field '%s' expected a number but got %r." % (self.name, value),
    ) from e
ValueError: Field 'id' expected a number but got 'month_stats'.

During handling of the above exception, another exception occurred:

Traceback (most recent call last):
  File "E:\Github\todo2\todoServer\venv\Lib\site-packages\rest_framework\views.py", line 506, in dispatch
    response = handler(request, *args, **kwargs)
  File "E:\Github\todo2\todoServer\venv\Lib\site-packages\rest_framework\mixins.py", line 54, in retrieve
    instance = self.get_object()
  File "E:\Github\todo2\todoServer\venv\Lib\site-packages\rest_framework\generics.py", line 96, in get_object
    obj = get_object_or_404(queryset, **filter_kwargs)
  File "E:\Github\todo2\todoServer\venv\Lib\site-packages\rest_framework\generics.py", line 21, in get_object_or_404
    raise Http404
django.http.response.Http404

    
ERROR 2024-12-16 22:08:36,167 utils 10796 20856 
API Error Details:
View: TaskViewSet
URL: /api/v1/tasks/tasks/month_stats/
Method: GET
User: fx0883
Error Type: Http404
Error Message: 
Stack Trace:
Traceback (most recent call last):
  File "E:\Github\todo2\todoServer\venv\Lib\site-packages\django\db\models\fields\__init__.py", line 2112, in get_prep_value
    return int(value)
ValueError: invalid literal for int() with base 10: 'month_stats'

The above exception was the direct cause of the following exception:

Traceback (most recent call last):
  File "E:\Github\todo2\todoServer\venv\Lib\site-packages\rest_framework\generics.py", line 19, in get_object_or_404
    return _get_object_or_404(queryset, *filter_args, **filter_kwargs)
  File "E:\Github\todo2\todoServer\venv\Lib\site-packages\django\shortcuts.py", line 85, in get_object_or_404
    return queryset.get(*args, **kwargs)
           ~~~~~~~~~~~~^^^^^^^^^^^^^^^^^
  File "E:\Github\todo2\todoServer\venv\Lib\site-packages\django\db\models\query.py", line 633, in get
    clone = self._chain() if self.query.combinator else self.filter(*args, **kwargs)
                                                        ~~~~~~~~~~~^^^^^^^^^^^^^^^^^
  File "E:\Github\todo2\todoServer\venv\Lib\site-packages\django\db\models\query.py", line 1476, in filter
    return self._filter_or_exclude(False, args, kwargs)
           ~~~~~~~~~~~~~~~~~~~~~~~^^^^^^^^^^^^^^^^^^^^^
  File "E:\Github\todo2\todoServer\venv\Lib\site-packages\django\db\models\query.py", line 1494, in _filter_or_exclude
    clone._filter_or_exclude_inplace(negate, args, kwargs)
    ~~~~~~~~~~~~~~~~~~~~~~~~~~~~~~~~^^^^^^^^^^^^^^^^^^^^^^
  File "E:\Github\todo2\todoServer\venv\Lib\site-packages\django\db\models\query.py", line 1501, in _filter_or_exclude_inplace
    self._query.add_q(Q(*args, **kwargs))
    ~~~~~~~~~~~~~~~~~^^^^^^^^^^^^^^^^^^^^
  File "E:\Github\todo2\todoServer\venv\Lib\site-packages\django\db\models\sql\query.py", line 1600, in add_q
    clause, _ = self._add_q(q_object, self.used_aliases)
                ~~~~~~~~~~~^^^^^^^^^^^^^^^^^^^^^^^^^^^^^
  File "E:\Github\todo2\todoServer\venv\Lib\site-packages\django\db\models\sql\query.py", line 1632, in _add_q
    child_clause, needed_inner = self.build_filter(
                                 ~~~~~~~~~~~~~~~~~^
        child,
        ^^^^^^
    ...<7 lines>...
        update_join_types=update_join_types,
        ^^^^^^^^^^^^^^^^^^^^^^^^^^^^^^^^^^^^
    )
    ^
  File "E:\Github\todo2\todoServer\venv\Lib\site-packages\django\db\models\sql\query.py", line 1546, in build_filter
    condition = self.build_lookup(lookups, col, value)
  File "E:\Github\todo2\todoServer\venv\Lib\site-packages\django\db\models\sql\query.py", line 1376, in build_lookup
    lookup = lookup_class(lhs, rhs)
  File "E:\Github\todo2\todoServer\venv\Lib\site-packages\django\db\models\lookups.py", line 30, in __init__
    self.rhs = self.get_prep_lookup()
               ~~~~~~~~~~~~~~~~~~~~^^
  File "E:\Github\todo2\todoServer\venv\Lib\site-packages\django\db\models\lookups.py", line 362, in get_prep_lookup
    return super().get_prep_lookup()
           ~~~~~~~~~~~~~~~~~~~~~~~^^
  File "E:\Github\todo2\todoServer\venv\Lib\site-packages\django\db\models\lookups.py", line 88, in get_prep_lookup
    return self.lhs.output_field.get_prep_value(self.rhs)
           ~~~~~~~~~~~~~~~~~~~~~~~~~~~~~~~~~~~~^^^^^^^^^^
  File "E:\Github\todo2\todoServer\venv\Lib\site-packages\django\db\models\fields\__init__.py", line 2114, in get_prep_value
    raise e.__class__(
        "Field '%s' expected a number but got %r." % (self.name, value),
    ) from e
ValueError: Field 'id' expected a number but got 'month_stats'.

During handling of the above exception, another exception occurred:

Traceback (most recent call last):
  File "E:\Github\todo2\todoServer\venv\Lib\site-packages\rest_framework\views.py", line 506, in dispatch
    response = handler(request, *args, **kwargs)
  File "E:\Github\todo2\todoServer\venv\Lib\site-packages\rest_framework\mixins.py", line 54, in retrieve
    instance = self.get_object()
  File "E:\Github\todo2\todoServer\venv\Lib\site-packages\rest_framework\generics.py", line 96, in get_object
    obj = get_object_or_404(queryset, **filter_kwargs)
  File "E:\Github\todo2\todoServer\venv\Lib\site-packages\rest_framework\generics.py", line 21, in get_object_or_404
    raise Http404
django.http.response.Http404

    
ERROR 2024-12-16 22:08:36,657 utils 10796 20856 
API Error Details:
View: TaskViewSet
URL: /api/v1/tasks/tasks/month_stats/
Method: GET
User: fx0883
Error Type: Http404
Error Message: 
Stack Trace:
Traceback (most recent call last):
  File "E:\Github\todo2\todoServer\venv\Lib\site-packages\django\db\models\fields\__init__.py", line 2112, in get_prep_value
    return int(value)
ValueError: invalid literal for int() with base 10: 'month_stats'

The above exception was the direct cause of the following exception:

Traceback (most recent call last):
  File "E:\Github\todo2\todoServer\venv\Lib\site-packages\rest_framework\generics.py", line 19, in get_object_or_404
    return _get_object_or_404(queryset, *filter_args, **filter_kwargs)
  File "E:\Github\todo2\todoServer\venv\Lib\site-packages\django\shortcuts.py", line 85, in get_object_or_404
    return queryset.get(*args, **kwargs)
           ~~~~~~~~~~~~^^^^^^^^^^^^^^^^^
  File "E:\Github\todo2\todoServer\venv\Lib\site-packages\django\db\models\query.py", line 633, in get
    clone = self._chain() if self.query.combinator else self.filter(*args, **kwargs)
                                                        ~~~~~~~~~~~^^^^^^^^^^^^^^^^^
  File "E:\Github\todo2\todoServer\venv\Lib\site-packages\django\db\models\query.py", line 1476, in filter
    return self._filter_or_exclude(False, args, kwargs)
           ~~~~~~~~~~~~~~~~~~~~~~~^^^^^^^^^^^^^^^^^^^^^
  File "E:\Github\todo2\todoServer\venv\Lib\site-packages\django\db\models\query.py", line 1494, in _filter_or_exclude
    clone._filter_or_exclude_inplace(negate, args, kwargs)
    ~~~~~~~~~~~~~~~~~~~~~~~~~~~~~~~~^^^^^^^^^^^^^^^^^^^^^^
  File "E:\Github\todo2\todoServer\venv\Lib\site-packages\django\db\models\query.py", line 1501, in _filter_or_exclude_inplace
    self._query.add_q(Q(*args, **kwargs))
    ~~~~~~~~~~~~~~~~~^^^^^^^^^^^^^^^^^^^^
  File "E:\Github\todo2\todoServer\venv\Lib\site-packages\django\db\models\sql\query.py", line 1600, in add_q
    clause, _ = self._add_q(q_object, self.used_aliases)
                ~~~~~~~~~~~^^^^^^^^^^^^^^^^^^^^^^^^^^^^^
  File "E:\Github\todo2\todoServer\venv\Lib\site-packages\django\db\models\sql\query.py", line 1632, in _add_q
    child_clause, needed_inner = self.build_filter(
                                 ~~~~~~~~~~~~~~~~~^
        child,
        ^^^^^^
    ...<7 lines>...
        update_join_types=update_join_types,
        ^^^^^^^^^^^^^^^^^^^^^^^^^^^^^^^^^^^^
    )
    ^
  File "E:\Github\todo2\todoServer\venv\Lib\site-packages\django\db\models\sql\query.py", line 1546, in build_filter
    condition = self.build_lookup(lookups, col, value)
  File "E:\Github\todo2\todoServer\venv\Lib\site-packages\django\db\models\sql\query.py", line 1376, in build_lookup
    lookup = lookup_class(lhs, rhs)
  File "E:\Github\todo2\todoServer\venv\Lib\site-packages\django\db\models\lookups.py", line 30, in __init__
    self.rhs = self.get_prep_lookup()
               ~~~~~~~~~~~~~~~~~~~~^^
  File "E:\Github\todo2\todoServer\venv\Lib\site-packages\django\db\models\lookups.py", line 362, in get_prep_lookup
    return super().get_prep_lookup()
           ~~~~~~~~~~~~~~~~~~~~~~~^^
  File "E:\Github\todo2\todoServer\venv\Lib\site-packages\django\db\models\lookups.py", line 88, in get_prep_lookup
    return self.lhs.output_field.get_prep_value(self.rhs)
           ~~~~~~~~~~~~~~~~~~~~~~~~~~~~~~~~~~~~^^^^^^^^^^
  File "E:\Github\todo2\todoServer\venv\Lib\site-packages\django\db\models\fields\__init__.py", line 2114, in get_prep_value
    raise e.__class__(
        "Field '%s' expected a number but got %r." % (self.name, value),
    ) from e
ValueError: Field 'id' expected a number but got 'month_stats'.

During handling of the above exception, another exception occurred:

Traceback (most recent call last):
  File "E:\Github\todo2\todoServer\venv\Lib\site-packages\rest_framework\views.py", line 506, in dispatch
    response = handler(request, *args, **kwargs)
  File "E:\Github\todo2\todoServer\venv\Lib\site-packages\rest_framework\mixins.py", line 54, in retrieve
    instance = self.get_object()
  File "E:\Github\todo2\todoServer\venv\Lib\site-packages\rest_framework\generics.py", line 96, in get_object
    obj = get_object_or_404(queryset, **filter_kwargs)
  File "E:\Github\todo2\todoServer\venv\Lib\site-packages\rest_framework\generics.py", line 21, in get_object_or_404
    raise Http404
django.http.response.Http404

    
ERROR 2024-12-16 22:08:36,919 utils 10796 20856 
API Error Details:
View: TaskViewSet
URL: /api/v1/tasks/tasks/month_stats/
Method: GET
User: fx0883
Error Type: Http404
Error Message: 
Stack Trace:
Traceback (most recent call last):
  File "E:\Github\todo2\todoServer\venv\Lib\site-packages\django\db\models\fields\__init__.py", line 2112, in get_prep_value
    return int(value)
ValueError: invalid literal for int() with base 10: 'month_stats'

The above exception was the direct cause of the following exception:

Traceback (most recent call last):
  File "E:\Github\todo2\todoServer\venv\Lib\site-packages\rest_framework\generics.py", line 19, in get_object_or_404
    return _get_object_or_404(queryset, *filter_args, **filter_kwargs)
  File "E:\Github\todo2\todoServer\venv\Lib\site-packages\django\shortcuts.py", line 85, in get_object_or_404
    return queryset.get(*args, **kwargs)
           ~~~~~~~~~~~~^^^^^^^^^^^^^^^^^
  File "E:\Github\todo2\todoServer\venv\Lib\site-packages\django\db\models\query.py", line 633, in get
    clone = self._chain() if self.query.combinator else self.filter(*args, **kwargs)
                                                        ~~~~~~~~~~~^^^^^^^^^^^^^^^^^
  File "E:\Github\todo2\todoServer\venv\Lib\site-packages\django\db\models\query.py", line 1476, in filter
    return self._filter_or_exclude(False, args, kwargs)
           ~~~~~~~~~~~~~~~~~~~~~~~^^^^^^^^^^^^^^^^^^^^^
  File "E:\Github\todo2\todoServer\venv\Lib\site-packages\django\db\models\query.py", line 1494, in _filter_or_exclude
    clone._filter_or_exclude_inplace(negate, args, kwargs)
    ~~~~~~~~~~~~~~~~~~~~~~~~~~~~~~~~^^^^^^^^^^^^^^^^^^^^^^
  File "E:\Github\todo2\todoServer\venv\Lib\site-packages\django\db\models\query.py", line 1501, in _filter_or_exclude_inplace
    self._query.add_q(Q(*args, **kwargs))
    ~~~~~~~~~~~~~~~~~^^^^^^^^^^^^^^^^^^^^
  File "E:\Github\todo2\todoServer\venv\Lib\site-packages\django\db\models\sql\query.py", line 1600, in add_q
    clause, _ = self._add_q(q_object, self.used_aliases)
                ~~~~~~~~~~~^^^^^^^^^^^^^^^^^^^^^^^^^^^^^
  File "E:\Github\todo2\todoServer\venv\Lib\site-packages\django\db\models\sql\query.py", line 1632, in _add_q
    child_clause, needed_inner = self.build_filter(
                                 ~~~~~~~~~~~~~~~~~^
        child,
        ^^^^^^
    ...<7 lines>...
        update_join_types=update_join_types,
        ^^^^^^^^^^^^^^^^^^^^^^^^^^^^^^^^^^^^
    )
    ^
  File "E:\Github\todo2\todoServer\venv\Lib\site-packages\django\db\models\sql\query.py", line 1546, in build_filter
    condition = self.build_lookup(lookups, col, value)
  File "E:\Github\todo2\todoServer\venv\Lib\site-packages\django\db\models\sql\query.py", line 1376, in build_lookup
    lookup = lookup_class(lhs, rhs)
  File "E:\Github\todo2\todoServer\venv\Lib\site-packages\django\db\models\lookups.py", line 30, in __init__
    self.rhs = self.get_prep_lookup()
               ~~~~~~~~~~~~~~~~~~~~^^
  File "E:\Github\todo2\todoServer\venv\Lib\site-packages\django\db\models\lookups.py", line 362, in get_prep_lookup
    return super().get_prep_lookup()
           ~~~~~~~~~~~~~~~~~~~~~~~^^
  File "E:\Github\todo2\todoServer\venv\Lib\site-packages\django\db\models\lookups.py", line 88, in get_prep_lookup
    return self.lhs.output_field.get_prep_value(self.rhs)
           ~~~~~~~~~~~~~~~~~~~~~~~~~~~~~~~~~~~~^^^^^^^^^^
  File "E:\Github\todo2\todoServer\venv\Lib\site-packages\django\db\models\fields\__init__.py", line 2114, in get_prep_value
    raise e.__class__(
        "Field '%s' expected a number but got %r." % (self.name, value),
    ) from e
ValueError: Field 'id' expected a number but got 'month_stats'.

During handling of the above exception, another exception occurred:

Traceback (most recent call last):
  File "E:\Github\todo2\todoServer\venv\Lib\site-packages\rest_framework\views.py", line 506, in dispatch
    response = handler(request, *args, **kwargs)
  File "E:\Github\todo2\todoServer\venv\Lib\site-packages\rest_framework\mixins.py", line 54, in retrieve
    instance = self.get_object()
  File "E:\Github\todo2\todoServer\venv\Lib\site-packages\rest_framework\generics.py", line 96, in get_object
    obj = get_object_or_404(queryset, **filter_kwargs)
  File "E:\Github\todo2\todoServer\venv\Lib\site-packages\rest_framework\generics.py", line 21, in get_object_or_404
    raise Http404
django.http.response.Http404

    
ERROR 2024-12-16 22:08:37,107 utils 10796 20856 
API Error Details:
View: TaskViewSet
URL: /api/v1/tasks/tasks/month_stats/
Method: GET
User: fx0883
Error Type: Http404
Error Message: 
Stack Trace:
Traceback (most recent call last):
  File "E:\Github\todo2\todoServer\venv\Lib\site-packages\django\db\models\fields\__init__.py", line 2112, in get_prep_value
    return int(value)
ValueError: invalid literal for int() with base 10: 'month_stats'

The above exception was the direct cause of the following exception:

Traceback (most recent call last):
  File "E:\Github\todo2\todoServer\venv\Lib\site-packages\rest_framework\generics.py", line 19, in get_object_or_404
    return _get_object_or_404(queryset, *filter_args, **filter_kwargs)
  File "E:\Github\todo2\todoServer\venv\Lib\site-packages\django\shortcuts.py", line 85, in get_object_or_404
    return queryset.get(*args, **kwargs)
           ~~~~~~~~~~~~^^^^^^^^^^^^^^^^^
  File "E:\Github\todo2\todoServer\venv\Lib\site-packages\django\db\models\query.py", line 633, in get
    clone = self._chain() if self.query.combinator else self.filter(*args, **kwargs)
                                                        ~~~~~~~~~~~^^^^^^^^^^^^^^^^^
  File "E:\Github\todo2\todoServer\venv\Lib\site-packages\django\db\models\query.py", line 1476, in filter
    return self._filter_or_exclude(False, args, kwargs)
           ~~~~~~~~~~~~~~~~~~~~~~~^^^^^^^^^^^^^^^^^^^^^
  File "E:\Github\todo2\todoServer\venv\Lib\site-packages\django\db\models\query.py", line 1494, in _filter_or_exclude
    clone._filter_or_exclude_inplace(negate, args, kwargs)
    ~~~~~~~~~~~~~~~~~~~~~~~~~~~~~~~~^^^^^^^^^^^^^^^^^^^^^^
  File "E:\Github\todo2\todoServer\venv\Lib\site-packages\django\db\models\query.py", line 1501, in _filter_or_exclude_inplace
    self._query.add_q(Q(*args, **kwargs))
    ~~~~~~~~~~~~~~~~~^^^^^^^^^^^^^^^^^^^^
  File "E:\Github\todo2\todoServer\venv\Lib\site-packages\django\db\models\sql\query.py", line 1600, in add_q
    clause, _ = self._add_q(q_object, self.used_aliases)
                ~~~~~~~~~~~^^^^^^^^^^^^^^^^^^^^^^^^^^^^^
  File "E:\Github\todo2\todoServer\venv\Lib\site-packages\django\db\models\sql\query.py", line 1632, in _add_q
    child_clause, needed_inner = self.build_filter(
                                 ~~~~~~~~~~~~~~~~~^
        child,
        ^^^^^^
    ...<7 lines>...
        update_join_types=update_join_types,
        ^^^^^^^^^^^^^^^^^^^^^^^^^^^^^^^^^^^^
    )
    ^
  File "E:\Github\todo2\todoServer\venv\Lib\site-packages\django\db\models\sql\query.py", line 1546, in build_filter
    condition = self.build_lookup(lookups, col, value)
  File "E:\Github\todo2\todoServer\venv\Lib\site-packages\django\db\models\sql\query.py", line 1376, in build_lookup
    lookup = lookup_class(lhs, rhs)
  File "E:\Github\todo2\todoServer\venv\Lib\site-packages\django\db\models\lookups.py", line 30, in __init__
    self.rhs = self.get_prep_lookup()
               ~~~~~~~~~~~~~~~~~~~~^^
  File "E:\Github\todo2\todoServer\venv\Lib\site-packages\django\db\models\lookups.py", line 362, in get_prep_lookup
    return super().get_prep_lookup()
           ~~~~~~~~~~~~~~~~~~~~~~~^^
  File "E:\Github\todo2\todoServer\venv\Lib\site-packages\django\db\models\lookups.py", line 88, in get_prep_lookup
    return self.lhs.output_field.get_prep_value(self.rhs)
           ~~~~~~~~~~~~~~~~~~~~~~~~~~~~~~~~~~~~^^^^^^^^^^
  File "E:\Github\todo2\todoServer\venv\Lib\site-packages\django\db\models\fields\__init__.py", line 2114, in get_prep_value
    raise e.__class__(
        "Field '%s' expected a number but got %r." % (self.name, value),
    ) from e
ValueError: Field 'id' expected a number but got 'month_stats'.

During handling of the above exception, another exception occurred:

Traceback (most recent call last):
  File "E:\Github\todo2\todoServer\venv\Lib\site-packages\rest_framework\views.py", line 506, in dispatch
    response = handler(request, *args, **kwargs)
  File "E:\Github\todo2\todoServer\venv\Lib\site-packages\rest_framework\mixins.py", line 54, in retrieve
    instance = self.get_object()
  File "E:\Github\todo2\todoServer\venv\Lib\site-packages\rest_framework\generics.py", line 96, in get_object
    obj = get_object_or_404(queryset, **filter_kwargs)
  File "E:\Github\todo2\todoServer\venv\Lib\site-packages\rest_framework\generics.py", line 21, in get_object_or_404
    raise Http404
django.http.response.Http404

    
ERROR 2024-12-16 22:08:37,315 utils 10796 20856 
API Error Details:
View: TaskViewSet
URL: /api/v1/tasks/tasks/month_stats/
Method: GET
User: fx0883
Error Type: Http404
Error Message: 
Stack Trace:
Traceback (most recent call last):
  File "E:\Github\todo2\todoServer\venv\Lib\site-packages\django\db\models\fields\__init__.py", line 2112, in get_prep_value
    return int(value)
ValueError: invalid literal for int() with base 10: 'month_stats'

The above exception was the direct cause of the following exception:

Traceback (most recent call last):
  File "E:\Github\todo2\todoServer\venv\Lib\site-packages\rest_framework\generics.py", line 19, in get_object_or_404
    return _get_object_or_404(queryset, *filter_args, **filter_kwargs)
  File "E:\Github\todo2\todoServer\venv\Lib\site-packages\django\shortcuts.py", line 85, in get_object_or_404
    return queryset.get(*args, **kwargs)
           ~~~~~~~~~~~~^^^^^^^^^^^^^^^^^
  File "E:\Github\todo2\todoServer\venv\Lib\site-packages\django\db\models\query.py", line 633, in get
    clone = self._chain() if self.query.combinator else self.filter(*args, **kwargs)
                                                        ~~~~~~~~~~~^^^^^^^^^^^^^^^^^
  File "E:\Github\todo2\todoServer\venv\Lib\site-packages\django\db\models\query.py", line 1476, in filter
    return self._filter_or_exclude(False, args, kwargs)
           ~~~~~~~~~~~~~~~~~~~~~~~^^^^^^^^^^^^^^^^^^^^^
  File "E:\Github\todo2\todoServer\venv\Lib\site-packages\django\db\models\query.py", line 1494, in _filter_or_exclude
    clone._filter_or_exclude_inplace(negate, args, kwargs)
    ~~~~~~~~~~~~~~~~~~~~~~~~~~~~~~~~^^^^^^^^^^^^^^^^^^^^^^
  File "E:\Github\todo2\todoServer\venv\Lib\site-packages\django\db\models\query.py", line 1501, in _filter_or_exclude_inplace
    self._query.add_q(Q(*args, **kwargs))
    ~~~~~~~~~~~~~~~~~^^^^^^^^^^^^^^^^^^^^
  File "E:\Github\todo2\todoServer\venv\Lib\site-packages\django\db\models\sql\query.py", line 1600, in add_q
    clause, _ = self._add_q(q_object, self.used_aliases)
                ~~~~~~~~~~~^^^^^^^^^^^^^^^^^^^^^^^^^^^^^
  File "E:\Github\todo2\todoServer\venv\Lib\site-packages\django\db\models\sql\query.py", line 1632, in _add_q
    child_clause, needed_inner = self.build_filter(
                                 ~~~~~~~~~~~~~~~~~^
        child,
        ^^^^^^
    ...<7 lines>...
        update_join_types=update_join_types,
        ^^^^^^^^^^^^^^^^^^^^^^^^^^^^^^^^^^^^
    )
    ^
  File "E:\Github\todo2\todoServer\venv\Lib\site-packages\django\db\models\sql\query.py", line 1546, in build_filter
    condition = self.build_lookup(lookups, col, value)
  File "E:\Github\todo2\todoServer\venv\Lib\site-packages\django\db\models\sql\query.py", line 1376, in build_lookup
    lookup = lookup_class(lhs, rhs)
  File "E:\Github\todo2\todoServer\venv\Lib\site-packages\django\db\models\lookups.py", line 30, in __init__
    self.rhs = self.get_prep_lookup()
               ~~~~~~~~~~~~~~~~~~~~^^
  File "E:\Github\todo2\todoServer\venv\Lib\site-packages\django\db\models\lookups.py", line 362, in get_prep_lookup
    return super().get_prep_lookup()
           ~~~~~~~~~~~~~~~~~~~~~~~^^
  File "E:\Github\todo2\todoServer\venv\Lib\site-packages\django\db\models\lookups.py", line 88, in get_prep_lookup
    return self.lhs.output_field.get_prep_value(self.rhs)
           ~~~~~~~~~~~~~~~~~~~~~~~~~~~~~~~~~~~~^^^^^^^^^^
  File "E:\Github\todo2\todoServer\venv\Lib\site-packages\django\db\models\fields\__init__.py", line 2114, in get_prep_value
    raise e.__class__(
        "Field '%s' expected a number but got %r." % (self.name, value),
    ) from e
ValueError: Field 'id' expected a number but got 'month_stats'.

During handling of the above exception, another exception occurred:

Traceback (most recent call last):
  File "E:\Github\todo2\todoServer\venv\Lib\site-packages\rest_framework\views.py", line 506, in dispatch
    response = handler(request, *args, **kwargs)
  File "E:\Github\todo2\todoServer\venv\Lib\site-packages\rest_framework\mixins.py", line 54, in retrieve
    instance = self.get_object()
  File "E:\Github\todo2\todoServer\venv\Lib\site-packages\rest_framework\generics.py", line 96, in get_object
    obj = get_object_or_404(queryset, **filter_kwargs)
  File "E:\Github\todo2\todoServer\venv\Lib\site-packages\rest_framework\generics.py", line 21, in get_object_or_404
    raise Http404
django.http.response.Http404

    
ERROR 2024-12-16 22:08:37,529 utils 10796 20856 
API Error Details:
View: TaskViewSet
URL: /api/v1/tasks/tasks/month_stats/
Method: GET
User: fx0883
Error Type: Http404
Error Message: 
Stack Trace:
Traceback (most recent call last):
  File "E:\Github\todo2\todoServer\venv\Lib\site-packages\django\db\models\fields\__init__.py", line 2112, in get_prep_value
    return int(value)
ValueError: invalid literal for int() with base 10: 'month_stats'

The above exception was the direct cause of the following exception:

Traceback (most recent call last):
  File "E:\Github\todo2\todoServer\venv\Lib\site-packages\rest_framework\generics.py", line 19, in get_object_or_404
    return _get_object_or_404(queryset, *filter_args, **filter_kwargs)
  File "E:\Github\todo2\todoServer\venv\Lib\site-packages\django\shortcuts.py", line 85, in get_object_or_404
    return queryset.get(*args, **kwargs)
           ~~~~~~~~~~~~^^^^^^^^^^^^^^^^^
  File "E:\Github\todo2\todoServer\venv\Lib\site-packages\django\db\models\query.py", line 633, in get
    clone = self._chain() if self.query.combinator else self.filter(*args, **kwargs)
                                                        ~~~~~~~~~~~^^^^^^^^^^^^^^^^^
  File "E:\Github\todo2\todoServer\venv\Lib\site-packages\django\db\models\query.py", line 1476, in filter
    return self._filter_or_exclude(False, args, kwargs)
           ~~~~~~~~~~~~~~~~~~~~~~~^^^^^^^^^^^^^^^^^^^^^
  File "E:\Github\todo2\todoServer\venv\Lib\site-packages\django\db\models\query.py", line 1494, in _filter_or_exclude
    clone._filter_or_exclude_inplace(negate, args, kwargs)
    ~~~~~~~~~~~~~~~~~~~~~~~~~~~~~~~~^^^^^^^^^^^^^^^^^^^^^^
  File "E:\Github\todo2\todoServer\venv\Lib\site-packages\django\db\models\query.py", line 1501, in _filter_or_exclude_inplace
    self._query.add_q(Q(*args, **kwargs))
    ~~~~~~~~~~~~~~~~~^^^^^^^^^^^^^^^^^^^^
  File "E:\Github\todo2\todoServer\venv\Lib\site-packages\django\db\models\sql\query.py", line 1600, in add_q
    clause, _ = self._add_q(q_object, self.used_aliases)
                ~~~~~~~~~~~^^^^^^^^^^^^^^^^^^^^^^^^^^^^^
  File "E:\Github\todo2\todoServer\venv\Lib\site-packages\django\db\models\sql\query.py", line 1632, in _add_q
    child_clause, needed_inner = self.build_filter(
                                 ~~~~~~~~~~~~~~~~~^
        child,
        ^^^^^^
    ...<7 lines>...
        update_join_types=update_join_types,
        ^^^^^^^^^^^^^^^^^^^^^^^^^^^^^^^^^^^^
    )
    ^
  File "E:\Github\todo2\todoServer\venv\Lib\site-packages\django\db\models\sql\query.py", line 1546, in build_filter
    condition = self.build_lookup(lookups, col, value)
  File "E:\Github\todo2\todoServer\venv\Lib\site-packages\django\db\models\sql\query.py", line 1376, in build_lookup
    lookup = lookup_class(lhs, rhs)
  File "E:\Github\todo2\todoServer\venv\Lib\site-packages\django\db\models\lookups.py", line 30, in __init__
    self.rhs = self.get_prep_lookup()
               ~~~~~~~~~~~~~~~~~~~~^^
  File "E:\Github\todo2\todoServer\venv\Lib\site-packages\django\db\models\lookups.py", line 362, in get_prep_lookup
    return super().get_prep_lookup()
           ~~~~~~~~~~~~~~~~~~~~~~~^^
  File "E:\Github\todo2\todoServer\venv\Lib\site-packages\django\db\models\lookups.py", line 88, in get_prep_lookup
    return self.lhs.output_field.get_prep_value(self.rhs)
           ~~~~~~~~~~~~~~~~~~~~~~~~~~~~~~~~~~~~^^^^^^^^^^
  File "E:\Github\todo2\todoServer\venv\Lib\site-packages\django\db\models\fields\__init__.py", line 2114, in get_prep_value
    raise e.__class__(
        "Field '%s' expected a number but got %r." % (self.name, value),
    ) from e
ValueError: Field 'id' expected a number but got 'month_stats'.

During handling of the above exception, another exception occurred:

Traceback (most recent call last):
  File "E:\Github\todo2\todoServer\venv\Lib\site-packages\rest_framework\views.py", line 506, in dispatch
    response = handler(request, *args, **kwargs)
  File "E:\Github\todo2\todoServer\venv\Lib\site-packages\rest_framework\mixins.py", line 54, in retrieve
    instance = self.get_object()
  File "E:\Github\todo2\todoServer\venv\Lib\site-packages\rest_framework\generics.py", line 96, in get_object
    obj = get_object_or_404(queryset, **filter_kwargs)
  File "E:\Github\todo2\todoServer\venv\Lib\site-packages\rest_framework\generics.py", line 21, in get_object_or_404
    raise Http404
django.http.response.Http404

    
ERROR 2024-12-16 22:08:37,721 utils 10796 20856 
API Error Details:
View: TaskViewSet
URL: /api/v1/tasks/tasks/month_stats/
Method: GET
User: fx0883
Error Type: Http404
Error Message: 
Stack Trace:
Traceback (most recent call last):
  File "E:\Github\todo2\todoServer\venv\Lib\site-packages\django\db\models\fields\__init__.py", line 2112, in get_prep_value
    return int(value)
ValueError: invalid literal for int() with base 10: 'month_stats'

The above exception was the direct cause of the following exception:

Traceback (most recent call last):
  File "E:\Github\todo2\todoServer\venv\Lib\site-packages\rest_framework\generics.py", line 19, in get_object_or_404
    return _get_object_or_404(queryset, *filter_args, **filter_kwargs)
  File "E:\Github\todo2\todoServer\venv\Lib\site-packages\django\shortcuts.py", line 85, in get_object_or_404
    return queryset.get(*args, **kwargs)
           ~~~~~~~~~~~~^^^^^^^^^^^^^^^^^
  File "E:\Github\todo2\todoServer\venv\Lib\site-packages\django\db\models\query.py", line 633, in get
    clone = self._chain() if self.query.combinator else self.filter(*args, **kwargs)
                                                        ~~~~~~~~~~~^^^^^^^^^^^^^^^^^
  File "E:\Github\todo2\todoServer\venv\Lib\site-packages\django\db\models\query.py", line 1476, in filter
    return self._filter_or_exclude(False, args, kwargs)
           ~~~~~~~~~~~~~~~~~~~~~~~^^^^^^^^^^^^^^^^^^^^^
  File "E:\Github\todo2\todoServer\venv\Lib\site-packages\django\db\models\query.py", line 1494, in _filter_or_exclude
    clone._filter_or_exclude_inplace(negate, args, kwargs)
    ~~~~~~~~~~~~~~~~~~~~~~~~~~~~~~~~^^^^^^^^^^^^^^^^^^^^^^
  File "E:\Github\todo2\todoServer\venv\Lib\site-packages\django\db\models\query.py", line 1501, in _filter_or_exclude_inplace
    self._query.add_q(Q(*args, **kwargs))
    ~~~~~~~~~~~~~~~~~^^^^^^^^^^^^^^^^^^^^
  File "E:\Github\todo2\todoServer\venv\Lib\site-packages\django\db\models\sql\query.py", line 1600, in add_q
    clause, _ = self._add_q(q_object, self.used_aliases)
                ~~~~~~~~~~~^^^^^^^^^^^^^^^^^^^^^^^^^^^^^
  File "E:\Github\todo2\todoServer\venv\Lib\site-packages\django\db\models\sql\query.py", line 1632, in _add_q
    child_clause, needed_inner = self.build_filter(
                                 ~~~~~~~~~~~~~~~~~^
        child,
        ^^^^^^
    ...<7 lines>...
        update_join_types=update_join_types,
        ^^^^^^^^^^^^^^^^^^^^^^^^^^^^^^^^^^^^
    )
    ^
  File "E:\Github\todo2\todoServer\venv\Lib\site-packages\django\db\models\sql\query.py", line 1546, in build_filter
    condition = self.build_lookup(lookups, col, value)
  File "E:\Github\todo2\todoServer\venv\Lib\site-packages\django\db\models\sql\query.py", line 1376, in build_lookup
    lookup = lookup_class(lhs, rhs)
  File "E:\Github\todo2\todoServer\venv\Lib\site-packages\django\db\models\lookups.py", line 30, in __init__
    self.rhs = self.get_prep_lookup()
               ~~~~~~~~~~~~~~~~~~~~^^
  File "E:\Github\todo2\todoServer\venv\Lib\site-packages\django\db\models\lookups.py", line 362, in get_prep_lookup
    return super().get_prep_lookup()
           ~~~~~~~~~~~~~~~~~~~~~~~^^
  File "E:\Github\todo2\todoServer\venv\Lib\site-packages\django\db\models\lookups.py", line 88, in get_prep_lookup
    return self.lhs.output_field.get_prep_value(self.rhs)
           ~~~~~~~~~~~~~~~~~~~~~~~~~~~~~~~~~~~~^^^^^^^^^^
  File "E:\Github\todo2\todoServer\venv\Lib\site-packages\django\db\models\fields\__init__.py", line 2114, in get_prep_value
    raise e.__class__(
        "Field '%s' expected a number but got %r." % (self.name, value),
    ) from e
ValueError: Field 'id' expected a number but got 'month_stats'.

During handling of the above exception, another exception occurred:

Traceback (most recent call last):
  File "E:\Github\todo2\todoServer\venv\Lib\site-packages\rest_framework\views.py", line 506, in dispatch
    response = handler(request, *args, **kwargs)
  File "E:\Github\todo2\todoServer\venv\Lib\site-packages\rest_framework\mixins.py", line 54, in retrieve
    instance = self.get_object()
  File "E:\Github\todo2\todoServer\venv\Lib\site-packages\rest_framework\generics.py", line 96, in get_object
    obj = get_object_or_404(queryset, **filter_kwargs)
  File "E:\Github\todo2\todoServer\venv\Lib\site-packages\rest_framework\generics.py", line 21, in get_object_or_404
    raise Http404
django.http.response.Http404

    
ERROR 2024-12-16 22:08:37,930 utils 10796 20856 
API Error Details:
View: TaskViewSet
URL: /api/v1/tasks/tasks/month_stats/
Method: GET
User: fx0883
Error Type: Http404
Error Message: 
Stack Trace:
Traceback (most recent call last):
  File "E:\Github\todo2\todoServer\venv\Lib\site-packages\django\db\models\fields\__init__.py", line 2112, in get_prep_value
    return int(value)
ValueError: invalid literal for int() with base 10: 'month_stats'

The above exception was the direct cause of the following exception:

Traceback (most recent call last):
  File "E:\Github\todo2\todoServer\venv\Lib\site-packages\rest_framework\generics.py", line 19, in get_object_or_404
    return _get_object_or_404(queryset, *filter_args, **filter_kwargs)
  File "E:\Github\todo2\todoServer\venv\Lib\site-packages\django\shortcuts.py", line 85, in get_object_or_404
    return queryset.get(*args, **kwargs)
           ~~~~~~~~~~~~^^^^^^^^^^^^^^^^^
  File "E:\Github\todo2\todoServer\venv\Lib\site-packages\django\db\models\query.py", line 633, in get
    clone = self._chain() if self.query.combinator else self.filter(*args, **kwargs)
                                                        ~~~~~~~~~~~^^^^^^^^^^^^^^^^^
  File "E:\Github\todo2\todoServer\venv\Lib\site-packages\django\db\models\query.py", line 1476, in filter
    return self._filter_or_exclude(False, args, kwargs)
           ~~~~~~~~~~~~~~~~~~~~~~~^^^^^^^^^^^^^^^^^^^^^
  File "E:\Github\todo2\todoServer\venv\Lib\site-packages\django\db\models\query.py", line 1494, in _filter_or_exclude
    clone._filter_or_exclude_inplace(negate, args, kwargs)
    ~~~~~~~~~~~~~~~~~~~~~~~~~~~~~~~~^^^^^^^^^^^^^^^^^^^^^^
  File "E:\Github\todo2\todoServer\venv\Lib\site-packages\django\db\models\query.py", line 1501, in _filter_or_exclude_inplace
    self._query.add_q(Q(*args, **kwargs))
    ~~~~~~~~~~~~~~~~~^^^^^^^^^^^^^^^^^^^^
  File "E:\Github\todo2\todoServer\venv\Lib\site-packages\django\db\models\sql\query.py", line 1600, in add_q
    clause, _ = self._add_q(q_object, self.used_aliases)
                ~~~~~~~~~~~^^^^^^^^^^^^^^^^^^^^^^^^^^^^^
  File "E:\Github\todo2\todoServer\venv\Lib\site-packages\django\db\models\sql\query.py", line 1632, in _add_q
    child_clause, needed_inner = self.build_filter(
                                 ~~~~~~~~~~~~~~~~~^
        child,
        ^^^^^^
    ...<7 lines>...
        update_join_types=update_join_types,
        ^^^^^^^^^^^^^^^^^^^^^^^^^^^^^^^^^^^^
    )
    ^
  File "E:\Github\todo2\todoServer\venv\Lib\site-packages\django\db\models\sql\query.py", line 1546, in build_filter
    condition = self.build_lookup(lookups, col, value)
  File "E:\Github\todo2\todoServer\venv\Lib\site-packages\django\db\models\sql\query.py", line 1376, in build_lookup
    lookup = lookup_class(lhs, rhs)
  File "E:\Github\todo2\todoServer\venv\Lib\site-packages\django\db\models\lookups.py", line 30, in __init__
    self.rhs = self.get_prep_lookup()
               ~~~~~~~~~~~~~~~~~~~~^^
  File "E:\Github\todo2\todoServer\venv\Lib\site-packages\django\db\models\lookups.py", line 362, in get_prep_lookup
    return super().get_prep_lookup()
           ~~~~~~~~~~~~~~~~~~~~~~~^^
  File "E:\Github\todo2\todoServer\venv\Lib\site-packages\django\db\models\lookups.py", line 88, in get_prep_lookup
    return self.lhs.output_field.get_prep_value(self.rhs)
           ~~~~~~~~~~~~~~~~~~~~~~~~~~~~~~~~~~~~^^^^^^^^^^
  File "E:\Github\todo2\todoServer\venv\Lib\site-packages\django\db\models\fields\__init__.py", line 2114, in get_prep_value
    raise e.__class__(
        "Field '%s' expected a number but got %r." % (self.name, value),
    ) from e
ValueError: Field 'id' expected a number but got 'month_stats'.

During handling of the above exception, another exception occurred:

Traceback (most recent call last):
  File "E:\Github\todo2\todoServer\venv\Lib\site-packages\rest_framework\views.py", line 506, in dispatch
    response = handler(request, *args, **kwargs)
  File "E:\Github\todo2\todoServer\venv\Lib\site-packages\rest_framework\mixins.py", line 54, in retrieve
    instance = self.get_object()
  File "E:\Github\todo2\todoServer\venv\Lib\site-packages\rest_framework\generics.py", line 96, in get_object
    obj = get_object_or_404(queryset, **filter_kwargs)
  File "E:\Github\todo2\todoServer\venv\Lib\site-packages\rest_framework\generics.py", line 21, in get_object_or_404
    raise Http404
django.http.response.Http404

    
ERROR 2024-12-16 22:08:38,157 utils 10796 20856 
API Error Details:
View: TaskViewSet
URL: /api/v1/tasks/tasks/month_stats/
Method: GET
User: fx0883
Error Type: Http404
Error Message: 
Stack Trace:
Traceback (most recent call last):
  File "E:\Github\todo2\todoServer\venv\Lib\site-packages\django\db\models\fields\__init__.py", line 2112, in get_prep_value
    return int(value)
ValueError: invalid literal for int() with base 10: 'month_stats'

The above exception was the direct cause of the following exception:

Traceback (most recent call last):
  File "E:\Github\todo2\todoServer\venv\Lib\site-packages\rest_framework\generics.py", line 19, in get_object_or_404
    return _get_object_or_404(queryset, *filter_args, **filter_kwargs)
  File "E:\Github\todo2\todoServer\venv\Lib\site-packages\django\shortcuts.py", line 85, in get_object_or_404
    return queryset.get(*args, **kwargs)
           ~~~~~~~~~~~~^^^^^^^^^^^^^^^^^
  File "E:\Github\todo2\todoServer\venv\Lib\site-packages\django\db\models\query.py", line 633, in get
    clone = self._chain() if self.query.combinator else self.filter(*args, **kwargs)
                                                        ~~~~~~~~~~~^^^^^^^^^^^^^^^^^
  File "E:\Github\todo2\todoServer\venv\Lib\site-packages\django\db\models\query.py", line 1476, in filter
    return self._filter_or_exclude(False, args, kwargs)
           ~~~~~~~~~~~~~~~~~~~~~~~^^^^^^^^^^^^^^^^^^^^^
  File "E:\Github\todo2\todoServer\venv\Lib\site-packages\django\db\models\query.py", line 1494, in _filter_or_exclude
    clone._filter_or_exclude_inplace(negate, args, kwargs)
    ~~~~~~~~~~~~~~~~~~~~~~~~~~~~~~~~^^^^^^^^^^^^^^^^^^^^^^
  File "E:\Github\todo2\todoServer\venv\Lib\site-packages\django\db\models\query.py", line 1501, in _filter_or_exclude_inplace
    self._query.add_q(Q(*args, **kwargs))
    ~~~~~~~~~~~~~~~~~^^^^^^^^^^^^^^^^^^^^
  File "E:\Github\todo2\todoServer\venv\Lib\site-packages\django\db\models\sql\query.py", line 1600, in add_q
    clause, _ = self._add_q(q_object, self.used_aliases)
                ~~~~~~~~~~~^^^^^^^^^^^^^^^^^^^^^^^^^^^^^
  File "E:\Github\todo2\todoServer\venv\Lib\site-packages\django\db\models\sql\query.py", line 1632, in _add_q
    child_clause, needed_inner = self.build_filter(
                                 ~~~~~~~~~~~~~~~~~^
        child,
        ^^^^^^
    ...<7 lines>...
        update_join_types=update_join_types,
        ^^^^^^^^^^^^^^^^^^^^^^^^^^^^^^^^^^^^
    )
    ^
  File "E:\Github\todo2\todoServer\venv\Lib\site-packages\django\db\models\sql\query.py", line 1546, in build_filter
    condition = self.build_lookup(lookups, col, value)
  File "E:\Github\todo2\todoServer\venv\Lib\site-packages\django\db\models\sql\query.py", line 1376, in build_lookup
    lookup = lookup_class(lhs, rhs)
  File "E:\Github\todo2\todoServer\venv\Lib\site-packages\django\db\models\lookups.py", line 30, in __init__
    self.rhs = self.get_prep_lookup()
               ~~~~~~~~~~~~~~~~~~~~^^
  File "E:\Github\todo2\todoServer\venv\Lib\site-packages\django\db\models\lookups.py", line 362, in get_prep_lookup
    return super().get_prep_lookup()
           ~~~~~~~~~~~~~~~~~~~~~~~^^
  File "E:\Github\todo2\todoServer\venv\Lib\site-packages\django\db\models\lookups.py", line 88, in get_prep_lookup
    return self.lhs.output_field.get_prep_value(self.rhs)
           ~~~~~~~~~~~~~~~~~~~~~~~~~~~~~~~~~~~~^^^^^^^^^^
  File "E:\Github\todo2\todoServer\venv\Lib\site-packages\django\db\models\fields\__init__.py", line 2114, in get_prep_value
    raise e.__class__(
        "Field '%s' expected a number but got %r." % (self.name, value),
    ) from e
ValueError: Field 'id' expected a number but got 'month_stats'.

During handling of the above exception, another exception occurred:

Traceback (most recent call last):
  File "E:\Github\todo2\todoServer\venv\Lib\site-packages\rest_framework\views.py", line 506, in dispatch
    response = handler(request, *args, **kwargs)
  File "E:\Github\todo2\todoServer\venv\Lib\site-packages\rest_framework\mixins.py", line 54, in retrieve
    instance = self.get_object()
  File "E:\Github\todo2\todoServer\venv\Lib\site-packages\rest_framework\generics.py", line 96, in get_object
    obj = get_object_or_404(queryset, **filter_kwargs)
  File "E:\Github\todo2\todoServer\venv\Lib\site-packages\rest_framework\generics.py", line 21, in get_object_or_404
    raise Http404
django.http.response.Http404

    
ERROR 2024-12-16 22:08:38,379 utils 10796 20856 
API Error Details:
View: TaskViewSet
URL: /api/v1/tasks/tasks/month_stats/
Method: GET
User: fx0883
Error Type: Http404
Error Message: 
Stack Trace:
Traceback (most recent call last):
  File "E:\Github\todo2\todoServer\venv\Lib\site-packages\django\db\models\fields\__init__.py", line 2112, in get_prep_value
    return int(value)
ValueError: invalid literal for int() with base 10: 'month_stats'

The above exception was the direct cause of the following exception:

Traceback (most recent call last):
  File "E:\Github\todo2\todoServer\venv\Lib\site-packages\rest_framework\generics.py", line 19, in get_object_or_404
    return _get_object_or_404(queryset, *filter_args, **filter_kwargs)
  File "E:\Github\todo2\todoServer\venv\Lib\site-packages\django\shortcuts.py", line 85, in get_object_or_404
    return queryset.get(*args, **kwargs)
           ~~~~~~~~~~~~^^^^^^^^^^^^^^^^^
  File "E:\Github\todo2\todoServer\venv\Lib\site-packages\django\db\models\query.py", line 633, in get
    clone = self._chain() if self.query.combinator else self.filter(*args, **kwargs)
                                                        ~~~~~~~~~~~^^^^^^^^^^^^^^^^^
  File "E:\Github\todo2\todoServer\venv\Lib\site-packages\django\db\models\query.py", line 1476, in filter
    return self._filter_or_exclude(False, args, kwargs)
           ~~~~~~~~~~~~~~~~~~~~~~~^^^^^^^^^^^^^^^^^^^^^
  File "E:\Github\todo2\todoServer\venv\Lib\site-packages\django\db\models\query.py", line 1494, in _filter_or_exclude
    clone._filter_or_exclude_inplace(negate, args, kwargs)
    ~~~~~~~~~~~~~~~~~~~~~~~~~~~~~~~~^^^^^^^^^^^^^^^^^^^^^^
  File "E:\Github\todo2\todoServer\venv\Lib\site-packages\django\db\models\query.py", line 1501, in _filter_or_exclude_inplace
    self._query.add_q(Q(*args, **kwargs))
    ~~~~~~~~~~~~~~~~~^^^^^^^^^^^^^^^^^^^^
  File "E:\Github\todo2\todoServer\venv\Lib\site-packages\django\db\models\sql\query.py", line 1600, in add_q
    clause, _ = self._add_q(q_object, self.used_aliases)
                ~~~~~~~~~~~^^^^^^^^^^^^^^^^^^^^^^^^^^^^^
  File "E:\Github\todo2\todoServer\venv\Lib\site-packages\django\db\models\sql\query.py", line 1632, in _add_q
    child_clause, needed_inner = self.build_filter(
                                 ~~~~~~~~~~~~~~~~~^
        child,
        ^^^^^^
    ...<7 lines>...
        update_join_types=update_join_types,
        ^^^^^^^^^^^^^^^^^^^^^^^^^^^^^^^^^^^^
    )
    ^
  File "E:\Github\todo2\todoServer\venv\Lib\site-packages\django\db\models\sql\query.py", line 1546, in build_filter
    condition = self.build_lookup(lookups, col, value)
  File "E:\Github\todo2\todoServer\venv\Lib\site-packages\django\db\models\sql\query.py", line 1376, in build_lookup
    lookup = lookup_class(lhs, rhs)
  File "E:\Github\todo2\todoServer\venv\Lib\site-packages\django\db\models\lookups.py", line 30, in __init__
    self.rhs = self.get_prep_lookup()
               ~~~~~~~~~~~~~~~~~~~~^^
  File "E:\Github\todo2\todoServer\venv\Lib\site-packages\django\db\models\lookups.py", line 362, in get_prep_lookup
    return super().get_prep_lookup()
           ~~~~~~~~~~~~~~~~~~~~~~~^^
  File "E:\Github\todo2\todoServer\venv\Lib\site-packages\django\db\models\lookups.py", line 88, in get_prep_lookup
    return self.lhs.output_field.get_prep_value(self.rhs)
           ~~~~~~~~~~~~~~~~~~~~~~~~~~~~~~~~~~~~^^^^^^^^^^
  File "E:\Github\todo2\todoServer\venv\Lib\site-packages\django\db\models\fields\__init__.py", line 2114, in get_prep_value
    raise e.__class__(
        "Field '%s' expected a number but got %r." % (self.name, value),
    ) from e
ValueError: Field 'id' expected a number but got 'month_stats'.

During handling of the above exception, another exception occurred:

Traceback (most recent call last):
  File "E:\Github\todo2\todoServer\venv\Lib\site-packages\rest_framework\views.py", line 506, in dispatch
    response = handler(request, *args, **kwargs)
  File "E:\Github\todo2\todoServer\venv\Lib\site-packages\rest_framework\mixins.py", line 54, in retrieve
    instance = self.get_object()
  File "E:\Github\todo2\todoServer\venv\Lib\site-packages\rest_framework\generics.py", line 96, in get_object
    obj = get_object_or_404(queryset, **filter_kwargs)
  File "E:\Github\todo2\todoServer\venv\Lib\site-packages\rest_framework\generics.py", line 21, in get_object_or_404
    raise Http404
django.http.response.Http404

    
ERROR 2024-12-16 22:08:38,587 utils 10796 20856 
API Error Details:
View: TaskViewSet
URL: /api/v1/tasks/tasks/month_stats/
Method: GET
User: fx0883
Error Type: Http404
Error Message: 
Stack Trace:
Traceback (most recent call last):
  File "E:\Github\todo2\todoServer\venv\Lib\site-packages\django\db\models\fields\__init__.py", line 2112, in get_prep_value
    return int(value)
ValueError: invalid literal for int() with base 10: 'month_stats'

The above exception was the direct cause of the following exception:

Traceback (most recent call last):
  File "E:\Github\todo2\todoServer\venv\Lib\site-packages\rest_framework\generics.py", line 19, in get_object_or_404
    return _get_object_or_404(queryset, *filter_args, **filter_kwargs)
  File "E:\Github\todo2\todoServer\venv\Lib\site-packages\django\shortcuts.py", line 85, in get_object_or_404
    return queryset.get(*args, **kwargs)
           ~~~~~~~~~~~~^^^^^^^^^^^^^^^^^
  File "E:\Github\todo2\todoServer\venv\Lib\site-packages\django\db\models\query.py", line 633, in get
    clone = self._chain() if self.query.combinator else self.filter(*args, **kwargs)
                                                        ~~~~~~~~~~~^^^^^^^^^^^^^^^^^
  File "E:\Github\todo2\todoServer\venv\Lib\site-packages\django\db\models\query.py", line 1476, in filter
    return self._filter_or_exclude(False, args, kwargs)
           ~~~~~~~~~~~~~~~~~~~~~~~^^^^^^^^^^^^^^^^^^^^^
  File "E:\Github\todo2\todoServer\venv\Lib\site-packages\django\db\models\query.py", line 1494, in _filter_or_exclude
    clone._filter_or_exclude_inplace(negate, args, kwargs)
    ~~~~~~~~~~~~~~~~~~~~~~~~~~~~~~~~^^^^^^^^^^^^^^^^^^^^^^
  File "E:\Github\todo2\todoServer\venv\Lib\site-packages\django\db\models\query.py", line 1501, in _filter_or_exclude_inplace
    self._query.add_q(Q(*args, **kwargs))
    ~~~~~~~~~~~~~~~~~^^^^^^^^^^^^^^^^^^^^
  File "E:\Github\todo2\todoServer\venv\Lib\site-packages\django\db\models\sql\query.py", line 1600, in add_q
    clause, _ = self._add_q(q_object, self.used_aliases)
                ~~~~~~~~~~~^^^^^^^^^^^^^^^^^^^^^^^^^^^^^
  File "E:\Github\todo2\todoServer\venv\Lib\site-packages\django\db\models\sql\query.py", line 1632, in _add_q
    child_clause, needed_inner = self.build_filter(
                                 ~~~~~~~~~~~~~~~~~^
        child,
        ^^^^^^
    ...<7 lines>...
        update_join_types=update_join_types,
        ^^^^^^^^^^^^^^^^^^^^^^^^^^^^^^^^^^^^
    )
    ^
  File "E:\Github\todo2\todoServer\venv\Lib\site-packages\django\db\models\sql\query.py", line 1546, in build_filter
    condition = self.build_lookup(lookups, col, value)
  File "E:\Github\todo2\todoServer\venv\Lib\site-packages\django\db\models\sql\query.py", line 1376, in build_lookup
    lookup = lookup_class(lhs, rhs)
  File "E:\Github\todo2\todoServer\venv\Lib\site-packages\django\db\models\lookups.py", line 30, in __init__
    self.rhs = self.get_prep_lookup()
               ~~~~~~~~~~~~~~~~~~~~^^
  File "E:\Github\todo2\todoServer\venv\Lib\site-packages\django\db\models\lookups.py", line 362, in get_prep_lookup
    return super().get_prep_lookup()
           ~~~~~~~~~~~~~~~~~~~~~~~^^
  File "E:\Github\todo2\todoServer\venv\Lib\site-packages\django\db\models\lookups.py", line 88, in get_prep_lookup
    return self.lhs.output_field.get_prep_value(self.rhs)
           ~~~~~~~~~~~~~~~~~~~~~~~~~~~~~~~~~~~~^^^^^^^^^^
  File "E:\Github\todo2\todoServer\venv\Lib\site-packages\django\db\models\fields\__init__.py", line 2114, in get_prep_value
    raise e.__class__(
        "Field '%s' expected a number but got %r." % (self.name, value),
    ) from e
ValueError: Field 'id' expected a number but got 'month_stats'.

During handling of the above exception, another exception occurred:

Traceback (most recent call last):
  File "E:\Github\todo2\todoServer\venv\Lib\site-packages\rest_framework\views.py", line 506, in dispatch
    response = handler(request, *args, **kwargs)
  File "E:\Github\todo2\todoServer\venv\Lib\site-packages\rest_framework\mixins.py", line 54, in retrieve
    instance = self.get_object()
  File "E:\Github\todo2\todoServer\venv\Lib\site-packages\rest_framework\generics.py", line 96, in get_object
    obj = get_object_or_404(queryset, **filter_kwargs)
  File "E:\Github\todo2\todoServer\venv\Lib\site-packages\rest_framework\generics.py", line 21, in get_object_or_404
    raise Http404
django.http.response.Http404

    
ERROR 2024-12-16 22:08:38,788 utils 10796 20856 
API Error Details:
View: TaskViewSet
URL: /api/v1/tasks/tasks/month_stats/
Method: GET
User: fx0883
Error Type: Http404
Error Message: 
Stack Trace:
Traceback (most recent call last):
  File "E:\Github\todo2\todoServer\venv\Lib\site-packages\django\db\models\fields\__init__.py", line 2112, in get_prep_value
    return int(value)
ValueError: invalid literal for int() with base 10: 'month_stats'

The above exception was the direct cause of the following exception:

Traceback (most recent call last):
  File "E:\Github\todo2\todoServer\venv\Lib\site-packages\rest_framework\generics.py", line 19, in get_object_or_404
    return _get_object_or_404(queryset, *filter_args, **filter_kwargs)
  File "E:\Github\todo2\todoServer\venv\Lib\site-packages\django\shortcuts.py", line 85, in get_object_or_404
    return queryset.get(*args, **kwargs)
           ~~~~~~~~~~~~^^^^^^^^^^^^^^^^^
  File "E:\Github\todo2\todoServer\venv\Lib\site-packages\django\db\models\query.py", line 633, in get
    clone = self._chain() if self.query.combinator else self.filter(*args, **kwargs)
                                                        ~~~~~~~~~~~^^^^^^^^^^^^^^^^^
  File "E:\Github\todo2\todoServer\venv\Lib\site-packages\django\db\models\query.py", line 1476, in filter
    return self._filter_or_exclude(False, args, kwargs)
           ~~~~~~~~~~~~~~~~~~~~~~~^^^^^^^^^^^^^^^^^^^^^
  File "E:\Github\todo2\todoServer\venv\Lib\site-packages\django\db\models\query.py", line 1494, in _filter_or_exclude
    clone._filter_or_exclude_inplace(negate, args, kwargs)
    ~~~~~~~~~~~~~~~~~~~~~~~~~~~~~~~~^^^^^^^^^^^^^^^^^^^^^^
  File "E:\Github\todo2\todoServer\venv\Lib\site-packages\django\db\models\query.py", line 1501, in _filter_or_exclude_inplace
    self._query.add_q(Q(*args, **kwargs))
    ~~~~~~~~~~~~~~~~~^^^^^^^^^^^^^^^^^^^^
  File "E:\Github\todo2\todoServer\venv\Lib\site-packages\django\db\models\sql\query.py", line 1600, in add_q
    clause, _ = self._add_q(q_object, self.used_aliases)
                ~~~~~~~~~~~^^^^^^^^^^^^^^^^^^^^^^^^^^^^^
  File "E:\Github\todo2\todoServer\venv\Lib\site-packages\django\db\models\sql\query.py", line 1632, in _add_q
    child_clause, needed_inner = self.build_filter(
                                 ~~~~~~~~~~~~~~~~~^
        child,
        ^^^^^^
    ...<7 lines>...
        update_join_types=update_join_types,
        ^^^^^^^^^^^^^^^^^^^^^^^^^^^^^^^^^^^^
    )
    ^
  File "E:\Github\todo2\todoServer\venv\Lib\site-packages\django\db\models\sql\query.py", line 1546, in build_filter
    condition = self.build_lookup(lookups, col, value)
  File "E:\Github\todo2\todoServer\venv\Lib\site-packages\django\db\models\sql\query.py", line 1376, in build_lookup
    lookup = lookup_class(lhs, rhs)
  File "E:\Github\todo2\todoServer\venv\Lib\site-packages\django\db\models\lookups.py", line 30, in __init__
    self.rhs = self.get_prep_lookup()
               ~~~~~~~~~~~~~~~~~~~~^^
  File "E:\Github\todo2\todoServer\venv\Lib\site-packages\django\db\models\lookups.py", line 362, in get_prep_lookup
    return super().get_prep_lookup()
           ~~~~~~~~~~~~~~~~~~~~~~~^^
  File "E:\Github\todo2\todoServer\venv\Lib\site-packages\django\db\models\lookups.py", line 88, in get_prep_lookup
    return self.lhs.output_field.get_prep_value(self.rhs)
           ~~~~~~~~~~~~~~~~~~~~~~~~~~~~~~~~~~~~^^^^^^^^^^
  File "E:\Github\todo2\todoServer\venv\Lib\site-packages\django\db\models\fields\__init__.py", line 2114, in get_prep_value
    raise e.__class__(
        "Field '%s' expected a number but got %r." % (self.name, value),
    ) from e
ValueError: Field 'id' expected a number but got 'month_stats'.

During handling of the above exception, another exception occurred:

Traceback (most recent call last):
  File "E:\Github\todo2\todoServer\venv\Lib\site-packages\rest_framework\views.py", line 506, in dispatch
    response = handler(request, *args, **kwargs)
  File "E:\Github\todo2\todoServer\venv\Lib\site-packages\rest_framework\mixins.py", line 54, in retrieve
    instance = self.get_object()
  File "E:\Github\todo2\todoServer\venv\Lib\site-packages\rest_framework\generics.py", line 96, in get_object
    obj = get_object_or_404(queryset, **filter_kwargs)
  File "E:\Github\todo2\todoServer\venv\Lib\site-packages\rest_framework\generics.py", line 21, in get_object_or_404
    raise Http404
django.http.response.Http404

    
ERROR 2024-12-16 22:08:39,050 utils 10796 20856 
API Error Details:
View: TaskViewSet
URL: /api/v1/tasks/tasks/month_stats/
Method: GET
User: fx0883
Error Type: Http404
Error Message: 
Stack Trace:
Traceback (most recent call last):
  File "E:\Github\todo2\todoServer\venv\Lib\site-packages\django\db\models\fields\__init__.py", line 2112, in get_prep_value
    return int(value)
ValueError: invalid literal for int() with base 10: 'month_stats'

The above exception was the direct cause of the following exception:

Traceback (most recent call last):
  File "E:\Github\todo2\todoServer\venv\Lib\site-packages\rest_framework\generics.py", line 19, in get_object_or_404
    return _get_object_or_404(queryset, *filter_args, **filter_kwargs)
  File "E:\Github\todo2\todoServer\venv\Lib\site-packages\django\shortcuts.py", line 85, in get_object_or_404
    return queryset.get(*args, **kwargs)
           ~~~~~~~~~~~~^^^^^^^^^^^^^^^^^
  File "E:\Github\todo2\todoServer\venv\Lib\site-packages\django\db\models\query.py", line 633, in get
    clone = self._chain() if self.query.combinator else self.filter(*args, **kwargs)
                                                        ~~~~~~~~~~~^^^^^^^^^^^^^^^^^
  File "E:\Github\todo2\todoServer\venv\Lib\site-packages\django\db\models\query.py", line 1476, in filter
    return self._filter_or_exclude(False, args, kwargs)
           ~~~~~~~~~~~~~~~~~~~~~~~^^^^^^^^^^^^^^^^^^^^^
  File "E:\Github\todo2\todoServer\venv\Lib\site-packages\django\db\models\query.py", line 1494, in _filter_or_exclude
    clone._filter_or_exclude_inplace(negate, args, kwargs)
    ~~~~~~~~~~~~~~~~~~~~~~~~~~~~~~~~^^^^^^^^^^^^^^^^^^^^^^
  File "E:\Github\todo2\todoServer\venv\Lib\site-packages\django\db\models\query.py", line 1501, in _filter_or_exclude_inplace
    self._query.add_q(Q(*args, **kwargs))
    ~~~~~~~~~~~~~~~~~^^^^^^^^^^^^^^^^^^^^
  File "E:\Github\todo2\todoServer\venv\Lib\site-packages\django\db\models\sql\query.py", line 1600, in add_q
    clause, _ = self._add_q(q_object, self.used_aliases)
                ~~~~~~~~~~~^^^^^^^^^^^^^^^^^^^^^^^^^^^^^
  File "E:\Github\todo2\todoServer\venv\Lib\site-packages\django\db\models\sql\query.py", line 1632, in _add_q
    child_clause, needed_inner = self.build_filter(
                                 ~~~~~~~~~~~~~~~~~^
        child,
        ^^^^^^
    ...<7 lines>...
        update_join_types=update_join_types,
        ^^^^^^^^^^^^^^^^^^^^^^^^^^^^^^^^^^^^
    )
    ^
  File "E:\Github\todo2\todoServer\venv\Lib\site-packages\django\db\models\sql\query.py", line 1546, in build_filter
    condition = self.build_lookup(lookups, col, value)
  File "E:\Github\todo2\todoServer\venv\Lib\site-packages\django\db\models\sql\query.py", line 1376, in build_lookup
    lookup = lookup_class(lhs, rhs)
  File "E:\Github\todo2\todoServer\venv\Lib\site-packages\django\db\models\lookups.py", line 30, in __init__
    self.rhs = self.get_prep_lookup()
               ~~~~~~~~~~~~~~~~~~~~^^
  File "E:\Github\todo2\todoServer\venv\Lib\site-packages\django\db\models\lookups.py", line 362, in get_prep_lookup
    return super().get_prep_lookup()
           ~~~~~~~~~~~~~~~~~~~~~~~^^
  File "E:\Github\todo2\todoServer\venv\Lib\site-packages\django\db\models\lookups.py", line 88, in get_prep_lookup
    return self.lhs.output_field.get_prep_value(self.rhs)
           ~~~~~~~~~~~~~~~~~~~~~~~~~~~~~~~~~~~~^^^^^^^^^^
  File "E:\Github\todo2\todoServer\venv\Lib\site-packages\django\db\models\fields\__init__.py", line 2114, in get_prep_value
    raise e.__class__(
        "Field '%s' expected a number but got %r." % (self.name, value),
    ) from e
ValueError: Field 'id' expected a number but got 'month_stats'.

During handling of the above exception, another exception occurred:

Traceback (most recent call last):
  File "E:\Github\todo2\todoServer\venv\Lib\site-packages\rest_framework\views.py", line 506, in dispatch
    response = handler(request, *args, **kwargs)
  File "E:\Github\todo2\todoServer\venv\Lib\site-packages\rest_framework\mixins.py", line 54, in retrieve
    instance = self.get_object()
  File "E:\Github\todo2\todoServer\venv\Lib\site-packages\rest_framework\generics.py", line 96, in get_object
    obj = get_object_or_404(queryset, **filter_kwargs)
  File "E:\Github\todo2\todoServer\venv\Lib\site-packages\rest_framework\generics.py", line 21, in get_object_or_404
    raise Http404
django.http.response.Http404

    
ERROR 2024-12-16 22:08:39,319 utils 10796 20856 
API Error Details:
View: TaskViewSet
URL: /api/v1/tasks/tasks/month_stats/
Method: GET
User: fx0883
Error Type: Http404
Error Message: 
Stack Trace:
Traceback (most recent call last):
  File "E:\Github\todo2\todoServer\venv\Lib\site-packages\django\db\models\fields\__init__.py", line 2112, in get_prep_value
    return int(value)
ValueError: invalid literal for int() with base 10: 'month_stats'

The above exception was the direct cause of the following exception:

Traceback (most recent call last):
  File "E:\Github\todo2\todoServer\venv\Lib\site-packages\rest_framework\generics.py", line 19, in get_object_or_404
    return _get_object_or_404(queryset, *filter_args, **filter_kwargs)
  File "E:\Github\todo2\todoServer\venv\Lib\site-packages\django\shortcuts.py", line 85, in get_object_or_404
    return queryset.get(*args, **kwargs)
           ~~~~~~~~~~~~^^^^^^^^^^^^^^^^^
  File "E:\Github\todo2\todoServer\venv\Lib\site-packages\django\db\models\query.py", line 633, in get
    clone = self._chain() if self.query.combinator else self.filter(*args, **kwargs)
                                                        ~~~~~~~~~~~^^^^^^^^^^^^^^^^^
  File "E:\Github\todo2\todoServer\venv\Lib\site-packages\django\db\models\query.py", line 1476, in filter
    return self._filter_or_exclude(False, args, kwargs)
           ~~~~~~~~~~~~~~~~~~~~~~~^^^^^^^^^^^^^^^^^^^^^
  File "E:\Github\todo2\todoServer\venv\Lib\site-packages\django\db\models\query.py", line 1494, in _filter_or_exclude
    clone._filter_or_exclude_inplace(negate, args, kwargs)
    ~~~~~~~~~~~~~~~~~~~~~~~~~~~~~~~~^^^^^^^^^^^^^^^^^^^^^^
  File "E:\Github\todo2\todoServer\venv\Lib\site-packages\django\db\models\query.py", line 1501, in _filter_or_exclude_inplace
    self._query.add_q(Q(*args, **kwargs))
    ~~~~~~~~~~~~~~~~~^^^^^^^^^^^^^^^^^^^^
  File "E:\Github\todo2\todoServer\venv\Lib\site-packages\django\db\models\sql\query.py", line 1600, in add_q
    clause, _ = self._add_q(q_object, self.used_aliases)
                ~~~~~~~~~~~^^^^^^^^^^^^^^^^^^^^^^^^^^^^^
  File "E:\Github\todo2\todoServer\venv\Lib\site-packages\django\db\models\sql\query.py", line 1632, in _add_q
    child_clause, needed_inner = self.build_filter(
                                 ~~~~~~~~~~~~~~~~~^
        child,
        ^^^^^^
    ...<7 lines>...
        update_join_types=update_join_types,
        ^^^^^^^^^^^^^^^^^^^^^^^^^^^^^^^^^^^^
    )
    ^
  File "E:\Github\todo2\todoServer\venv\Lib\site-packages\django\db\models\sql\query.py", line 1546, in build_filter
    condition = self.build_lookup(lookups, col, value)
  File "E:\Github\todo2\todoServer\venv\Lib\site-packages\django\db\models\sql\query.py", line 1376, in build_lookup
    lookup = lookup_class(lhs, rhs)
  File "E:\Github\todo2\todoServer\venv\Lib\site-packages\django\db\models\lookups.py", line 30, in __init__
    self.rhs = self.get_prep_lookup()
               ~~~~~~~~~~~~~~~~~~~~^^
  File "E:\Github\todo2\todoServer\venv\Lib\site-packages\django\db\models\lookups.py", line 362, in get_prep_lookup
    return super().get_prep_lookup()
           ~~~~~~~~~~~~~~~~~~~~~~~^^
  File "E:\Github\todo2\todoServer\venv\Lib\site-packages\django\db\models\lookups.py", line 88, in get_prep_lookup
    return self.lhs.output_field.get_prep_value(self.rhs)
           ~~~~~~~~~~~~~~~~~~~~~~~~~~~~~~~~~~~~^^^^^^^^^^
  File "E:\Github\todo2\todoServer\venv\Lib\site-packages\django\db\models\fields\__init__.py", line 2114, in get_prep_value
    raise e.__class__(
        "Field '%s' expected a number but got %r." % (self.name, value),
    ) from e
ValueError: Field 'id' expected a number but got 'month_stats'.

During handling of the above exception, another exception occurred:

Traceback (most recent call last):
  File "E:\Github\todo2\todoServer\venv\Lib\site-packages\rest_framework\views.py", line 506, in dispatch
    response = handler(request, *args, **kwargs)
  File "E:\Github\todo2\todoServer\venv\Lib\site-packages\rest_framework\mixins.py", line 54, in retrieve
    instance = self.get_object()
  File "E:\Github\todo2\todoServer\venv\Lib\site-packages\rest_framework\generics.py", line 96, in get_object
    obj = get_object_or_404(queryset, **filter_kwargs)
  File "E:\Github\todo2\todoServer\venv\Lib\site-packages\rest_framework\generics.py", line 21, in get_object_or_404
    raise Http404
django.http.response.Http404

    
ERROR 2024-12-16 22:08:39,563 utils 10796 20856 
API Error Details:
View: TaskViewSet
URL: /api/v1/tasks/tasks/month_stats/
Method: GET
User: fx0883
Error Type: Http404
Error Message: 
Stack Trace:
Traceback (most recent call last):
  File "E:\Github\todo2\todoServer\venv\Lib\site-packages\django\db\models\fields\__init__.py", line 2112, in get_prep_value
    return int(value)
ValueError: invalid literal for int() with base 10: 'month_stats'

The above exception was the direct cause of the following exception:

Traceback (most recent call last):
  File "E:\Github\todo2\todoServer\venv\Lib\site-packages\rest_framework\generics.py", line 19, in get_object_or_404
    return _get_object_or_404(queryset, *filter_args, **filter_kwargs)
  File "E:\Github\todo2\todoServer\venv\Lib\site-packages\django\shortcuts.py", line 85, in get_object_or_404
    return queryset.get(*args, **kwargs)
           ~~~~~~~~~~~~^^^^^^^^^^^^^^^^^
  File "E:\Github\todo2\todoServer\venv\Lib\site-packages\django\db\models\query.py", line 633, in get
    clone = self._chain() if self.query.combinator else self.filter(*args, **kwargs)
                                                        ~~~~~~~~~~~^^^^^^^^^^^^^^^^^
  File "E:\Github\todo2\todoServer\venv\Lib\site-packages\django\db\models\query.py", line 1476, in filter
    return self._filter_or_exclude(False, args, kwargs)
           ~~~~~~~~~~~~~~~~~~~~~~~^^^^^^^^^^^^^^^^^^^^^
  File "E:\Github\todo2\todoServer\venv\Lib\site-packages\django\db\models\query.py", line 1494, in _filter_or_exclude
    clone._filter_or_exclude_inplace(negate, args, kwargs)
    ~~~~~~~~~~~~~~~~~~~~~~~~~~~~~~~~^^^^^^^^^^^^^^^^^^^^^^
  File "E:\Github\todo2\todoServer\venv\Lib\site-packages\django\db\models\query.py", line 1501, in _filter_or_exclude_inplace
    self._query.add_q(Q(*args, **kwargs))
    ~~~~~~~~~~~~~~~~~^^^^^^^^^^^^^^^^^^^^
  File "E:\Github\todo2\todoServer\venv\Lib\site-packages\django\db\models\sql\query.py", line 1600, in add_q
    clause, _ = self._add_q(q_object, self.used_aliases)
                ~~~~~~~~~~~^^^^^^^^^^^^^^^^^^^^^^^^^^^^^
  File "E:\Github\todo2\todoServer\venv\Lib\site-packages\django\db\models\sql\query.py", line 1632, in _add_q
    child_clause, needed_inner = self.build_filter(
                                 ~~~~~~~~~~~~~~~~~^
        child,
        ^^^^^^
    ...<7 lines>...
        update_join_types=update_join_types,
        ^^^^^^^^^^^^^^^^^^^^^^^^^^^^^^^^^^^^
    )
    ^
  File "E:\Github\todo2\todoServer\venv\Lib\site-packages\django\db\models\sql\query.py", line 1546, in build_filter
    condition = self.build_lookup(lookups, col, value)
  File "E:\Github\todo2\todoServer\venv\Lib\site-packages\django\db\models\sql\query.py", line 1376, in build_lookup
    lookup = lookup_class(lhs, rhs)
  File "E:\Github\todo2\todoServer\venv\Lib\site-packages\django\db\models\lookups.py", line 30, in __init__
    self.rhs = self.get_prep_lookup()
               ~~~~~~~~~~~~~~~~~~~~^^
  File "E:\Github\todo2\todoServer\venv\Lib\site-packages\django\db\models\lookups.py", line 362, in get_prep_lookup
    return super().get_prep_lookup()
           ~~~~~~~~~~~~~~~~~~~~~~~^^
  File "E:\Github\todo2\todoServer\venv\Lib\site-packages\django\db\models\lookups.py", line 88, in get_prep_lookup
    return self.lhs.output_field.get_prep_value(self.rhs)
           ~~~~~~~~~~~~~~~~~~~~~~~~~~~~~~~~~~~~^^^^^^^^^^
  File "E:\Github\todo2\todoServer\venv\Lib\site-packages\django\db\models\fields\__init__.py", line 2114, in get_prep_value
    raise e.__class__(
        "Field '%s' expected a number but got %r." % (self.name, value),
    ) from e
ValueError: Field 'id' expected a number but got 'month_stats'.

During handling of the above exception, another exception occurred:

Traceback (most recent call last):
  File "E:\Github\todo2\todoServer\venv\Lib\site-packages\rest_framework\views.py", line 506, in dispatch
    response = handler(request, *args, **kwargs)
  File "E:\Github\todo2\todoServer\venv\Lib\site-packages\rest_framework\mixins.py", line 54, in retrieve
    instance = self.get_object()
  File "E:\Github\todo2\todoServer\venv\Lib\site-packages\rest_framework\generics.py", line 96, in get_object
    obj = get_object_or_404(queryset, **filter_kwargs)
  File "E:\Github\todo2\todoServer\venv\Lib\site-packages\rest_framework\generics.py", line 21, in get_object_or_404
    raise Http404
django.http.response.Http404

    
ERROR 2024-12-16 22:08:39,913 utils 10796 20856 
API Error Details:
View: TaskViewSet
URL: /api/v1/tasks/tasks/month_stats/
Method: GET
User: fx0883
Error Type: Http404
Error Message: 
Stack Trace:
Traceback (most recent call last):
  File "E:\Github\todo2\todoServer\venv\Lib\site-packages\django\db\models\fields\__init__.py", line 2112, in get_prep_value
    return int(value)
ValueError: invalid literal for int() with base 10: 'month_stats'

The above exception was the direct cause of the following exception:

Traceback (most recent call last):
  File "E:\Github\todo2\todoServer\venv\Lib\site-packages\rest_framework\generics.py", line 19, in get_object_or_404
    return _get_object_or_404(queryset, *filter_args, **filter_kwargs)
  File "E:\Github\todo2\todoServer\venv\Lib\site-packages\django\shortcuts.py", line 85, in get_object_or_404
    return queryset.get(*args, **kwargs)
           ~~~~~~~~~~~~^^^^^^^^^^^^^^^^^
  File "E:\Github\todo2\todoServer\venv\Lib\site-packages\django\db\models\query.py", line 633, in get
    clone = self._chain() if self.query.combinator else self.filter(*args, **kwargs)
                                                        ~~~~~~~~~~~^^^^^^^^^^^^^^^^^
  File "E:\Github\todo2\todoServer\venv\Lib\site-packages\django\db\models\query.py", line 1476, in filter
    return self._filter_or_exclude(False, args, kwargs)
           ~~~~~~~~~~~~~~~~~~~~~~~^^^^^^^^^^^^^^^^^^^^^
  File "E:\Github\todo2\todoServer\venv\Lib\site-packages\django\db\models\query.py", line 1494, in _filter_or_exclude
    clone._filter_or_exclude_inplace(negate, args, kwargs)
    ~~~~~~~~~~~~~~~~~~~~~~~~~~~~~~~~^^^^^^^^^^^^^^^^^^^^^^
  File "E:\Github\todo2\todoServer\venv\Lib\site-packages\django\db\models\query.py", line 1501, in _filter_or_exclude_inplace
    self._query.add_q(Q(*args, **kwargs))
    ~~~~~~~~~~~~~~~~~^^^^^^^^^^^^^^^^^^^^
  File "E:\Github\todo2\todoServer\venv\Lib\site-packages\django\db\models\sql\query.py", line 1600, in add_q
    clause, _ = self._add_q(q_object, self.used_aliases)
                ~~~~~~~~~~~^^^^^^^^^^^^^^^^^^^^^^^^^^^^^
  File "E:\Github\todo2\todoServer\venv\Lib\site-packages\django\db\models\sql\query.py", line 1632, in _add_q
    child_clause, needed_inner = self.build_filter(
                                 ~~~~~~~~~~~~~~~~~^
        child,
        ^^^^^^
    ...<7 lines>...
        update_join_types=update_join_types,
        ^^^^^^^^^^^^^^^^^^^^^^^^^^^^^^^^^^^^
    )
    ^
  File "E:\Github\todo2\todoServer\venv\Lib\site-packages\django\db\models\sql\query.py", line 1546, in build_filter
    condition = self.build_lookup(lookups, col, value)
  File "E:\Github\todo2\todoServer\venv\Lib\site-packages\django\db\models\sql\query.py", line 1376, in build_lookup
    lookup = lookup_class(lhs, rhs)
  File "E:\Github\todo2\todoServer\venv\Lib\site-packages\django\db\models\lookups.py", line 30, in __init__
    self.rhs = self.get_prep_lookup()
               ~~~~~~~~~~~~~~~~~~~~^^
  File "E:\Github\todo2\todoServer\venv\Lib\site-packages\django\db\models\lookups.py", line 362, in get_prep_lookup
    return super().get_prep_lookup()
           ~~~~~~~~~~~~~~~~~~~~~~~^^
  File "E:\Github\todo2\todoServer\venv\Lib\site-packages\django\db\models\lookups.py", line 88, in get_prep_lookup
    return self.lhs.output_field.get_prep_value(self.rhs)
           ~~~~~~~~~~~~~~~~~~~~~~~~~~~~~~~~~~~~^^^^^^^^^^
  File "E:\Github\todo2\todoServer\venv\Lib\site-packages\django\db\models\fields\__init__.py", line 2114, in get_prep_value
    raise e.__class__(
        "Field '%s' expected a number but got %r." % (self.name, value),
    ) from e
ValueError: Field 'id' expected a number but got 'month_stats'.

During handling of the above exception, another exception occurred:

Traceback (most recent call last):
  File "E:\Github\todo2\todoServer\venv\Lib\site-packages\rest_framework\views.py", line 506, in dispatch
    response = handler(request, *args, **kwargs)
  File "E:\Github\todo2\todoServer\venv\Lib\site-packages\rest_framework\mixins.py", line 54, in retrieve
    instance = self.get_object()
  File "E:\Github\todo2\todoServer\venv\Lib\site-packages\rest_framework\generics.py", line 96, in get_object
    obj = get_object_or_404(queryset, **filter_kwargs)
  File "E:\Github\todo2\todoServer\venv\Lib\site-packages\rest_framework\generics.py", line 21, in get_object_or_404
    raise Http404
django.http.response.Http404

    
ERROR 2024-12-16 22:08:40,405 utils 10796 20856 
API Error Details:
View: TaskViewSet
URL: /api/v1/tasks/tasks/month_stats/
Method: GET
User: fx0883
Error Type: Http404
Error Message: 
Stack Trace:
Traceback (most recent call last):
  File "E:\Github\todo2\todoServer\venv\Lib\site-packages\django\db\models\fields\__init__.py", line 2112, in get_prep_value
    return int(value)
ValueError: invalid literal for int() with base 10: 'month_stats'

The above exception was the direct cause of the following exception:

Traceback (most recent call last):
  File "E:\Github\todo2\todoServer\venv\Lib\site-packages\rest_framework\generics.py", line 19, in get_object_or_404
    return _get_object_or_404(queryset, *filter_args, **filter_kwargs)
  File "E:\Github\todo2\todoServer\venv\Lib\site-packages\django\shortcuts.py", line 85, in get_object_or_404
    return queryset.get(*args, **kwargs)
           ~~~~~~~~~~~~^^^^^^^^^^^^^^^^^
  File "E:\Github\todo2\todoServer\venv\Lib\site-packages\django\db\models\query.py", line 633, in get
    clone = self._chain() if self.query.combinator else self.filter(*args, **kwargs)
                                                        ~~~~~~~~~~~^^^^^^^^^^^^^^^^^
  File "E:\Github\todo2\todoServer\venv\Lib\site-packages\django\db\models\query.py", line 1476, in filter
    return self._filter_or_exclude(False, args, kwargs)
           ~~~~~~~~~~~~~~~~~~~~~~~^^^^^^^^^^^^^^^^^^^^^
  File "E:\Github\todo2\todoServer\venv\Lib\site-packages\django\db\models\query.py", line 1494, in _filter_or_exclude
    clone._filter_or_exclude_inplace(negate, args, kwargs)
    ~~~~~~~~~~~~~~~~~~~~~~~~~~~~~~~~^^^^^^^^^^^^^^^^^^^^^^
  File "E:\Github\todo2\todoServer\venv\Lib\site-packages\django\db\models\query.py", line 1501, in _filter_or_exclude_inplace
    self._query.add_q(Q(*args, **kwargs))
    ~~~~~~~~~~~~~~~~~^^^^^^^^^^^^^^^^^^^^
  File "E:\Github\todo2\todoServer\venv\Lib\site-packages\django\db\models\sql\query.py", line 1600, in add_q
    clause, _ = self._add_q(q_object, self.used_aliases)
                ~~~~~~~~~~~^^^^^^^^^^^^^^^^^^^^^^^^^^^^^
  File "E:\Github\todo2\todoServer\venv\Lib\site-packages\django\db\models\sql\query.py", line 1632, in _add_q
    child_clause, needed_inner = self.build_filter(
                                 ~~~~~~~~~~~~~~~~~^
        child,
        ^^^^^^
    ...<7 lines>...
        update_join_types=update_join_types,
        ^^^^^^^^^^^^^^^^^^^^^^^^^^^^^^^^^^^^
    )
    ^
  File "E:\Github\todo2\todoServer\venv\Lib\site-packages\django\db\models\sql\query.py", line 1546, in build_filter
    condition = self.build_lookup(lookups, col, value)
  File "E:\Github\todo2\todoServer\venv\Lib\site-packages\django\db\models\sql\query.py", line 1376, in build_lookup
    lookup = lookup_class(lhs, rhs)
  File "E:\Github\todo2\todoServer\venv\Lib\site-packages\django\db\models\lookups.py", line 30, in __init__
    self.rhs = self.get_prep_lookup()
               ~~~~~~~~~~~~~~~~~~~~^^
  File "E:\Github\todo2\todoServer\venv\Lib\site-packages\django\db\models\lookups.py", line 362, in get_prep_lookup
    return super().get_prep_lookup()
           ~~~~~~~~~~~~~~~~~~~~~~~^^
  File "E:\Github\todo2\todoServer\venv\Lib\site-packages\django\db\models\lookups.py", line 88, in get_prep_lookup
    return self.lhs.output_field.get_prep_value(self.rhs)
           ~~~~~~~~~~~~~~~~~~~~~~~~~~~~~~~~~~~~^^^^^^^^^^
  File "E:\Github\todo2\todoServer\venv\Lib\site-packages\django\db\models\fields\__init__.py", line 2114, in get_prep_value
    raise e.__class__(
        "Field '%s' expected a number but got %r." % (self.name, value),
    ) from e
ValueError: Field 'id' expected a number but got 'month_stats'.

During handling of the above exception, another exception occurred:

Traceback (most recent call last):
  File "E:\Github\todo2\todoServer\venv\Lib\site-packages\rest_framework\views.py", line 506, in dispatch
    response = handler(request, *args, **kwargs)
  File "E:\Github\todo2\todoServer\venv\Lib\site-packages\rest_framework\mixins.py", line 54, in retrieve
    instance = self.get_object()
  File "E:\Github\todo2\todoServer\venv\Lib\site-packages\rest_framework\generics.py", line 96, in get_object
    obj = get_object_or_404(queryset, **filter_kwargs)
  File "E:\Github\todo2\todoServer\venv\Lib\site-packages\rest_framework\generics.py", line 21, in get_object_or_404
    raise Http404
django.http.response.Http404

    
ERROR 2024-12-16 22:08:40,896 utils 10796 20856 
API Error Details:
View: TaskViewSet
URL: /api/v1/tasks/tasks/month_stats/
Method: GET
User: fx0883
Error Type: Http404
Error Message: 
Stack Trace:
Traceback (most recent call last):
  File "E:\Github\todo2\todoServer\venv\Lib\site-packages\django\db\models\fields\__init__.py", line 2112, in get_prep_value
    return int(value)
ValueError: invalid literal for int() with base 10: 'month_stats'

The above exception was the direct cause of the following exception:

Traceback (most recent call last):
  File "E:\Github\todo2\todoServer\venv\Lib\site-packages\rest_framework\generics.py", line 19, in get_object_or_404
    return _get_object_or_404(queryset, *filter_args, **filter_kwargs)
  File "E:\Github\todo2\todoServer\venv\Lib\site-packages\django\shortcuts.py", line 85, in get_object_or_404
    return queryset.get(*args, **kwargs)
           ~~~~~~~~~~~~^^^^^^^^^^^^^^^^^
  File "E:\Github\todo2\todoServer\venv\Lib\site-packages\django\db\models\query.py", line 633, in get
    clone = self._chain() if self.query.combinator else self.filter(*args, **kwargs)
                                                        ~~~~~~~~~~~^^^^^^^^^^^^^^^^^
  File "E:\Github\todo2\todoServer\venv\Lib\site-packages\django\db\models\query.py", line 1476, in filter
    return self._filter_or_exclude(False, args, kwargs)
           ~~~~~~~~~~~~~~~~~~~~~~~^^^^^^^^^^^^^^^^^^^^^
  File "E:\Github\todo2\todoServer\venv\Lib\site-packages\django\db\models\query.py", line 1494, in _filter_or_exclude
    clone._filter_or_exclude_inplace(negate, args, kwargs)
    ~~~~~~~~~~~~~~~~~~~~~~~~~~~~~~~~^^^^^^^^^^^^^^^^^^^^^^
  File "E:\Github\todo2\todoServer\venv\Lib\site-packages\django\db\models\query.py", line 1501, in _filter_or_exclude_inplace
    self._query.add_q(Q(*args, **kwargs))
    ~~~~~~~~~~~~~~~~~^^^^^^^^^^^^^^^^^^^^
  File "E:\Github\todo2\todoServer\venv\Lib\site-packages\django\db\models\sql\query.py", line 1600, in add_q
    clause, _ = self._add_q(q_object, self.used_aliases)
                ~~~~~~~~~~~^^^^^^^^^^^^^^^^^^^^^^^^^^^^^
  File "E:\Github\todo2\todoServer\venv\Lib\site-packages\django\db\models\sql\query.py", line 1632, in _add_q
    child_clause, needed_inner = self.build_filter(
                                 ~~~~~~~~~~~~~~~~~^
        child,
        ^^^^^^
    ...<7 lines>...
        update_join_types=update_join_types,
        ^^^^^^^^^^^^^^^^^^^^^^^^^^^^^^^^^^^^
    )
    ^
  File "E:\Github\todo2\todoServer\venv\Lib\site-packages\django\db\models\sql\query.py", line 1546, in build_filter
    condition = self.build_lookup(lookups, col, value)
  File "E:\Github\todo2\todoServer\venv\Lib\site-packages\django\db\models\sql\query.py", line 1376, in build_lookup
    lookup = lookup_class(lhs, rhs)
  File "E:\Github\todo2\todoServer\venv\Lib\site-packages\django\db\models\lookups.py", line 30, in __init__
    self.rhs = self.get_prep_lookup()
               ~~~~~~~~~~~~~~~~~~~~^^
  File "E:\Github\todo2\todoServer\venv\Lib\site-packages\django\db\models\lookups.py", line 362, in get_prep_lookup
    return super().get_prep_lookup()
           ~~~~~~~~~~~~~~~~~~~~~~~^^
  File "E:\Github\todo2\todoServer\venv\Lib\site-packages\django\db\models\lookups.py", line 88, in get_prep_lookup
    return self.lhs.output_field.get_prep_value(self.rhs)
           ~~~~~~~~~~~~~~~~~~~~~~~~~~~~~~~~~~~~^^^^^^^^^^
  File "E:\Github\todo2\todoServer\venv\Lib\site-packages\django\db\models\fields\__init__.py", line 2114, in get_prep_value
    raise e.__class__(
        "Field '%s' expected a number but got %r." % (self.name, value),
    ) from e
ValueError: Field 'id' expected a number but got 'month_stats'.

During handling of the above exception, another exception occurred:

Traceback (most recent call last):
  File "E:\Github\todo2\todoServer\venv\Lib\site-packages\rest_framework\views.py", line 506, in dispatch
    response = handler(request, *args, **kwargs)
  File "E:\Github\todo2\todoServer\venv\Lib\site-packages\rest_framework\mixins.py", line 54, in retrieve
    instance = self.get_object()
  File "E:\Github\todo2\todoServer\venv\Lib\site-packages\rest_framework\generics.py", line 96, in get_object
    obj = get_object_or_404(queryset, **filter_kwargs)
  File "E:\Github\todo2\todoServer\venv\Lib\site-packages\rest_framework\generics.py", line 21, in get_object_or_404
    raise Http404
django.http.response.Http404

    
ERROR 2024-12-16 23:34:29,751 utils 2068 4100 
API Error Details:
View: MonthStatsView
URL: /api/v1/tasks/tasks/month_stats/2024-11/
Method: GET
User: AnonymousUser
Error Type: InvalidToken
Error Message: {'detail': ErrorDetail(string='此令牌对任何类型的令牌无效', code='token_not_valid'), 'code': ErrorDetail(string='token_not_valid', code='token_not_valid'), 'messages': [{'token_class': ErrorDetail(string='AccessToken', code='token_not_valid'), 'token_type': ErrorDetail(string='access', code='token_not_valid'), 'message': ErrorDetail(string='令牌无效或已过期', code='token_not_valid')}]}
Stack Trace:
Traceback (most recent call last):
  File "E:\Github\todo2\todoServer\venv\Lib\site-packages\rest_framework\views.py", line 497, in dispatch
    self.initial(request, *args, **kwargs)
    ~~~~~~~~~~~~^^^^^^^^^^^^^^^^^^^^^^^^^^
  File "E:\Github\todo2\todoServer\venv\Lib\site-packages\rest_framework\views.py", line 414, in initial
    self.perform_authentication(request)
    ~~~~~~~~~~~~~~~~~~~~~~~~~~~^^^^^^^^^
  File "E:\Github\todo2\todoServer\venv\Lib\site-packages\rest_framework\views.py", line 324, in perform_authentication
    request.user
  File "E:\Github\todo2\todoServer\venv\Lib\site-packages\rest_framework\request.py", line 227, in user
    self._authenticate()
    ~~~~~~~~~~~~~~~~~~^^
  File "E:\Github\todo2\todoServer\venv\Lib\site-packages\rest_framework\request.py", line 380, in _authenticate
    user_auth_tuple = authenticator.authenticate(self)
  File "E:\Github\todo2\todoServer\venv\Lib\site-packages\rest_framework_simplejwt\authentication.py", line 49, in authenticate
    validated_token = self.get_validated_token(raw_token)
  File "E:\Github\todo2\todoServer\venv\Lib\site-packages\rest_framework_simplejwt\authentication.py", line 113, in get_validated_token
    raise InvalidToken(
    ...<4 lines>...
    )
rest_framework_simplejwt.exceptions.InvalidToken: {'detail': ErrorDetail(string='此令牌对任何类型的令牌无效', code='token_not_valid'), 'code': ErrorDetail(string='token_not_valid', code='token_not_valid'), 'messages': [{'token_class': ErrorDetail(string='AccessToken', code='token_not_valid'), 'token_type': ErrorDetail(string='access', code='token_not_valid'), 'message': ErrorDetail(string='令牌无效或已过期', code='token_not_valid')}]}

    
ERROR 2024-12-16 23:34:29,751 utils 2068 9268 
API Error Details:
View: CategoryStatsView
URL: /api/v1/tasks/tasks/category_stats/2024-11/
Method: GET
User: AnonymousUser
Error Type: InvalidToken
Error Message: {'detail': ErrorDetail(string='此令牌对任何类型的令牌无效', code='token_not_valid'), 'code': ErrorDetail(string='token_not_valid', code='token_not_valid'), 'messages': [{'token_class': ErrorDetail(string='AccessToken', code='token_not_valid'), 'token_type': ErrorDetail(string='access', code='token_not_valid'), 'message': ErrorDetail(string='令牌无效或已过期', code='token_not_valid')}]}
Stack Trace:
Traceback (most recent call last):
  File "E:\Github\todo2\todoServer\venv\Lib\site-packages\rest_framework\views.py", line 497, in dispatch
    self.initial(request, *args, **kwargs)
    ~~~~~~~~~~~~^^^^^^^^^^^^^^^^^^^^^^^^^^
  File "E:\Github\todo2\todoServer\venv\Lib\site-packages\rest_framework\views.py", line 414, in initial
    self.perform_authentication(request)
    ~~~~~~~~~~~~~~~~~~~~~~~~~~~^^^^^^^^^
  File "E:\Github\todo2\todoServer\venv\Lib\site-packages\rest_framework\views.py", line 324, in perform_authentication
    request.user
  File "E:\Github\todo2\todoServer\venv\Lib\site-packages\rest_framework\request.py", line 227, in user
    self._authenticate()
    ~~~~~~~~~~~~~~~~~~^^
  File "E:\Github\todo2\todoServer\venv\Lib\site-packages\rest_framework\request.py", line 380, in _authenticate
    user_auth_tuple = authenticator.authenticate(self)
  File "E:\Github\todo2\todoServer\venv\Lib\site-packages\rest_framework_simplejwt\authentication.py", line 49, in authenticate
    validated_token = self.get_validated_token(raw_token)
  File "E:\Github\todo2\todoServer\venv\Lib\site-packages\rest_framework_simplejwt\authentication.py", line 113, in get_validated_token
    raise InvalidToken(
    ...<4 lines>...
    )
rest_framework_simplejwt.exceptions.InvalidToken: {'detail': ErrorDetail(string='此令牌对任何类型的令牌无效', code='token_not_valid'), 'code': ErrorDetail(string='token_not_valid', code='token_not_valid'), 'messages': [{'token_class': ErrorDetail(string='AccessToken', code='token_not_valid'), 'token_type': ErrorDetail(string='access', code='token_not_valid'), 'message': ErrorDetail(string='令牌无效或已过期', code='token_not_valid')}]}

    
ERROR 2024-12-16 23:34:29,753 utils 2068 21404 
API Error Details:
View: DailyTrendView
URL: /api/v1/tasks/tasks/daily_trend/2024-11/
Method: GET
User: AnonymousUser
Error Type: InvalidToken
Error Message: {'detail': ErrorDetail(string='此令牌对任何类型的令牌无效', code='token_not_valid'), 'code': ErrorDetail(string='token_not_valid', code='token_not_valid'), 'messages': [{'token_class': ErrorDetail(string='AccessToken', code='token_not_valid'), 'token_type': ErrorDetail(string='access', code='token_not_valid'), 'message': ErrorDetail(string='令牌无效或已过期', code='token_not_valid')}]}
Stack Trace:
Traceback (most recent call last):
  File "E:\Github\todo2\todoServer\venv\Lib\site-packages\rest_framework\views.py", line 497, in dispatch
    self.initial(request, *args, **kwargs)
    ~~~~~~~~~~~~^^^^^^^^^^^^^^^^^^^^^^^^^^
  File "E:\Github\todo2\todoServer\venv\Lib\site-packages\rest_framework\views.py", line 414, in initial
    self.perform_authentication(request)
    ~~~~~~~~~~~~~~~~~~~~~~~~~~~^^^^^^^^^
  File "E:\Github\todo2\todoServer\venv\Lib\site-packages\rest_framework\views.py", line 324, in perform_authentication
    request.user
  File "E:\Github\todo2\todoServer\venv\Lib\site-packages\rest_framework\request.py", line 227, in user
    self._authenticate()
    ~~~~~~~~~~~~~~~~~~^^
  File "E:\Github\todo2\todoServer\venv\Lib\site-packages\rest_framework\request.py", line 380, in _authenticate
    user_auth_tuple = authenticator.authenticate(self)
  File "E:\Github\todo2\todoServer\venv\Lib\site-packages\rest_framework_simplejwt\authentication.py", line 49, in authenticate
    validated_token = self.get_validated_token(raw_token)
  File "E:\Github\todo2\todoServer\venv\Lib\site-packages\rest_framework_simplejwt\authentication.py", line 113, in get_validated_token
    raise InvalidToken(
    ...<4 lines>...
    )
rest_framework_simplejwt.exceptions.InvalidToken: {'detail': ErrorDetail(string='此令牌对任何类型的令牌无效', code='token_not_valid'), 'code': ErrorDetail(string='token_not_valid', code='token_not_valid'), 'messages': [{'token_class': ErrorDetail(string='AccessToken', code='token_not_valid'), 'token_type': ErrorDetail(string='access', code='token_not_valid'), 'message': ErrorDetail(string='令牌无效或已过期', code='token_not_valid')}]}

    
ERROR 2024-12-16 23:45:06,741 utils 18352 14688 
API Error Details:
View: PriorityStatsView
URL: /api/v1/tasks/tasks/priority_stats/2024-12/
Method: GET
User: AnonymousUser
Error Type: NotAuthenticated
Error Message: 身份认证信息未提供。
Stack Trace:
Traceback (most recent call last):
  File "E:\Github\todo2\todoServer\venv\Lib\site-packages\rest_framework\views.py", line 497, in dispatch
    self.initial(request, *args, **kwargs)
    ~~~~~~~~~~~~^^^^^^^^^^^^^^^^^^^^^^^^^^
  File "E:\Github\todo2\todoServer\venv\Lib\site-packages\rest_framework\views.py", line 415, in initial
    self.check_permissions(request)
    ~~~~~~~~~~~~~~~~~~~~~~^^^^^^^^^
  File "E:\Github\todo2\todoServer\venv\Lib\site-packages\rest_framework\views.py", line 333, in check_permissions
    self.permission_denied(
    ~~~~~~~~~~~~~~~~~~~~~~^
        request,
        ^^^^^^^^
        message=getattr(permission, 'message', None),
        ^^^^^^^^^^^^^^^^^^^^^^^^^^^^^^^^^^^^^^^^^^^^^
        code=getattr(permission, 'code', None)
        ^^^^^^^^^^^^^^^^^^^^^^^^^^^^^^^^^^^^^^
    )
    ^
  File "E:\Github\todo2\todoServer\venv\Lib\site-packages\rest_framework\views.py", line 174, in permission_denied
    raise exceptions.NotAuthenticated()
rest_framework.exceptions.NotAuthenticated: 身份认证信息未提供。

    
ERROR 2024-12-17 11:14:58,328 utils 11408 12868 
API Error Details:
View: TaskViewSet
URL: /api/v1/tasks/tasks/
Method: GET
User: AnonymousUser
Error Type: NotAuthenticated
Error Message: 身份认证信息未提供。
Stack Trace:
Traceback (most recent call last):
  File "E:\Github\todo2\todoServer\venv\Lib\site-packages\rest_framework\views.py", line 497, in dispatch
    self.initial(request, *args, **kwargs)
    ~~~~~~~~~~~~^^^^^^^^^^^^^^^^^^^^^^^^^^
  File "E:\Github\todo2\todoServer\venv\Lib\site-packages\rest_framework\views.py", line 415, in initial
    self.check_permissions(request)
    ~~~~~~~~~~~~~~~~~~~~~~^^^^^^^^^
  File "E:\Github\todo2\todoServer\venv\Lib\site-packages\rest_framework\views.py", line 333, in check_permissions
    self.permission_denied(
    ~~~~~~~~~~~~~~~~~~~~~~^
        request,
        ^^^^^^^^
        message=getattr(permission, 'message', None),
        ^^^^^^^^^^^^^^^^^^^^^^^^^^^^^^^^^^^^^^^^^^^^^
        code=getattr(permission, 'code', None)
        ^^^^^^^^^^^^^^^^^^^^^^^^^^^^^^^^^^^^^^
    )
    ^
  File "E:\Github\todo2\todoServer\venv\Lib\site-packages\rest_framework\views.py", line 174, in permission_denied
    raise exceptions.NotAuthenticated()
rest_framework.exceptions.NotAuthenticated: 身份认证信息未提供。

    
ERROR 2024-12-17 11:14:58,329 utils 11408 15640 
API Error Details:
View: CategoryViewSet
URL: /api/v1/tasks/categories/
Method: GET
User: AnonymousUser
Error Type: NotAuthenticated
Error Message: 身份认证信息未提供。
Stack Trace:
Traceback (most recent call last):
  File "E:\Github\todo2\todoServer\venv\Lib\site-packages\rest_framework\views.py", line 497, in dispatch
    self.initial(request, *args, **kwargs)
    ~~~~~~~~~~~~^^^^^^^^^^^^^^^^^^^^^^^^^^
  File "E:\Github\todo2\todoServer\venv\Lib\site-packages\rest_framework\views.py", line 415, in initial
    self.check_permissions(request)
    ~~~~~~~~~~~~~~~~~~~~~~^^^^^^^^^
  File "E:\Github\todo2\todoServer\venv\Lib\site-packages\rest_framework\views.py", line 333, in check_permissions
    self.permission_denied(
    ~~~~~~~~~~~~~~~~~~~~~~^
        request,
        ^^^^^^^^
        message=getattr(permission, 'message', None),
        ^^^^^^^^^^^^^^^^^^^^^^^^^^^^^^^^^^^^^^^^^^^^^
        code=getattr(permission, 'code', None)
        ^^^^^^^^^^^^^^^^^^^^^^^^^^^^^^^^^^^^^^
    )
    ^
  File "E:\Github\todo2\todoServer\venv\Lib\site-packages\rest_framework\views.py", line 174, in permission_denied
    raise exceptions.NotAuthenticated()
rest_framework.exceptions.NotAuthenticated: 身份认证信息未提供。

    
ERROR 2024-12-17 11:14:58,332 utils 11408 12868 
API Error Details:
View: TaskViewSet
URL: /api/v1/tasks/tasks/
Method: GET
User: AnonymousUser
Error Type: NotAuthenticated
Error Message: 身份认证信息未提供。
Stack Trace:
Traceback (most recent call last):
  File "E:\Github\todo2\todoServer\venv\Lib\site-packages\rest_framework\views.py", line 497, in dispatch
    self.initial(request, *args, **kwargs)
    ~~~~~~~~~~~~^^^^^^^^^^^^^^^^^^^^^^^^^^
  File "E:\Github\todo2\todoServer\venv\Lib\site-packages\rest_framework\views.py", line 415, in initial
    self.check_permissions(request)
    ~~~~~~~~~~~~~~~~~~~~~~^^^^^^^^^
  File "E:\Github\todo2\todoServer\venv\Lib\site-packages\rest_framework\views.py", line 333, in check_permissions
    self.permission_denied(
    ~~~~~~~~~~~~~~~~~~~~~~^
        request,
        ^^^^^^^^
        message=getattr(permission, 'message', None),
        ^^^^^^^^^^^^^^^^^^^^^^^^^^^^^^^^^^^^^^^^^^^^^
        code=getattr(permission, 'code', None)
        ^^^^^^^^^^^^^^^^^^^^^^^^^^^^^^^^^^^^^^
    )
    ^
  File "E:\Github\todo2\todoServer\venv\Lib\site-packages\rest_framework\views.py", line 174, in permission_denied
    raise exceptions.NotAuthenticated()
rest_framework.exceptions.NotAuthenticated: 身份认证信息未提供。

    
ERROR 2024-12-17 11:14:59,206 utils 11408 12868 
API Error Details:
View: TaskViewSet
URL: /api/v1/tasks/tasks/
Method: GET
User: AnonymousUser
Error Type: NotAuthenticated
Error Message: 身份认证信息未提供。
Stack Trace:
Traceback (most recent call last):
  File "E:\Github\todo2\todoServer\venv\Lib\site-packages\rest_framework\views.py", line 497, in dispatch
    self.initial(request, *args, **kwargs)
    ~~~~~~~~~~~~^^^^^^^^^^^^^^^^^^^^^^^^^^
  File "E:\Github\todo2\todoServer\venv\Lib\site-packages\rest_framework\views.py", line 415, in initial
    self.check_permissions(request)
    ~~~~~~~~~~~~~~~~~~~~~~^^^^^^^^^
  File "E:\Github\todo2\todoServer\venv\Lib\site-packages\rest_framework\views.py", line 333, in check_permissions
    self.permission_denied(
    ~~~~~~~~~~~~~~~~~~~~~~^
        request,
        ^^^^^^^^
        message=getattr(permission, 'message', None),
        ^^^^^^^^^^^^^^^^^^^^^^^^^^^^^^^^^^^^^^^^^^^^^
        code=getattr(permission, 'code', None)
        ^^^^^^^^^^^^^^^^^^^^^^^^^^^^^^^^^^^^^^
    )
    ^
  File "E:\Github\todo2\todoServer\venv\Lib\site-packages\rest_framework\views.py", line 174, in permission_denied
    raise exceptions.NotAuthenticated()
rest_framework.exceptions.NotAuthenticated: 身份认证信息未提供。

    
ERROR 2024-12-17 11:14:59,206 utils 11408 15640 
API Error Details:
View: CategoryViewSet
URL: /api/v1/tasks/categories/
Method: GET
User: AnonymousUser
Error Type: NotAuthenticated
Error Message: 身份认证信息未提供。
Stack Trace:
Traceback (most recent call last):
  File "E:\Github\todo2\todoServer\venv\Lib\site-packages\rest_framework\views.py", line 497, in dispatch
    self.initial(request, *args, **kwargs)
    ~~~~~~~~~~~~^^^^^^^^^^^^^^^^^^^^^^^^^^
  File "E:\Github\todo2\todoServer\venv\Lib\site-packages\rest_framework\views.py", line 415, in initial
    self.check_permissions(request)
    ~~~~~~~~~~~~~~~~~~~~~~^^^^^^^^^
  File "E:\Github\todo2\todoServer\venv\Lib\site-packages\rest_framework\views.py", line 333, in check_permissions
    self.permission_denied(
    ~~~~~~~~~~~~~~~~~~~~~~^
        request,
        ^^^^^^^^
        message=getattr(permission, 'message', None),
        ^^^^^^^^^^^^^^^^^^^^^^^^^^^^^^^^^^^^^^^^^^^^^
        code=getattr(permission, 'code', None)
        ^^^^^^^^^^^^^^^^^^^^^^^^^^^^^^^^^^^^^^
    )
    ^
  File "E:\Github\todo2\todoServer\venv\Lib\site-packages\rest_framework\views.py", line 174, in permission_denied
    raise exceptions.NotAuthenticated()
rest_framework.exceptions.NotAuthenticated: 身份认证信息未提供。

    
ERROR 2024-12-17 11:14:59,209 utils 11408 12868 
API Error Details:
View: TaskViewSet
URL: /api/v1/tasks/tasks/
Method: GET
User: AnonymousUser
Error Type: NotAuthenticated
Error Message: 身份认证信息未提供。
Stack Trace:
Traceback (most recent call last):
  File "E:\Github\todo2\todoServer\venv\Lib\site-packages\rest_framework\views.py", line 497, in dispatch
    self.initial(request, *args, **kwargs)
    ~~~~~~~~~~~~^^^^^^^^^^^^^^^^^^^^^^^^^^
  File "E:\Github\todo2\todoServer\venv\Lib\site-packages\rest_framework\views.py", line 415, in initial
    self.check_permissions(request)
    ~~~~~~~~~~~~~~~~~~~~~~^^^^^^^^^
  File "E:\Github\todo2\todoServer\venv\Lib\site-packages\rest_framework\views.py", line 333, in check_permissions
    self.permission_denied(
    ~~~~~~~~~~~~~~~~~~~~~~^
        request,
        ^^^^^^^^
        message=getattr(permission, 'message', None),
        ^^^^^^^^^^^^^^^^^^^^^^^^^^^^^^^^^^^^^^^^^^^^^
        code=getattr(permission, 'code', None)
        ^^^^^^^^^^^^^^^^^^^^^^^^^^^^^^^^^^^^^^
    )
    ^
  File "E:\Github\todo2\todoServer\venv\Lib\site-packages\rest_framework\views.py", line 174, in permission_denied
    raise exceptions.NotAuthenticated()
rest_framework.exceptions.NotAuthenticated: 身份认证信息未提供。

    
ERROR 2024-12-17 11:14:59,902 utils 11408 12868 
API Error Details:
View: TaskViewSet
URL: /api/v1/tasks/tasks/
Method: GET
User: AnonymousUser
Error Type: NotAuthenticated
Error Message: 身份认证信息未提供。
Stack Trace:
Traceback (most recent call last):
  File "E:\Github\todo2\todoServer\venv\Lib\site-packages\rest_framework\views.py", line 497, in dispatch
    self.initial(request, *args, **kwargs)
    ~~~~~~~~~~~~^^^^^^^^^^^^^^^^^^^^^^^^^^
  File "E:\Github\todo2\todoServer\venv\Lib\site-packages\rest_framework\views.py", line 415, in initial
    self.check_permissions(request)
    ~~~~~~~~~~~~~~~~~~~~~~^^^^^^^^^
  File "E:\Github\todo2\todoServer\venv\Lib\site-packages\rest_framework\views.py", line 333, in check_permissions
    self.permission_denied(
    ~~~~~~~~~~~~~~~~~~~~~~^
        request,
        ^^^^^^^^
        message=getattr(permission, 'message', None),
        ^^^^^^^^^^^^^^^^^^^^^^^^^^^^^^^^^^^^^^^^^^^^^
        code=getattr(permission, 'code', None)
        ^^^^^^^^^^^^^^^^^^^^^^^^^^^^^^^^^^^^^^
    )
    ^
  File "E:\Github\todo2\todoServer\venv\Lib\site-packages\rest_framework\views.py", line 174, in permission_denied
    raise exceptions.NotAuthenticated()
rest_framework.exceptions.NotAuthenticated: 身份认证信息未提供。

    
ERROR 2024-12-17 11:14:59,902 utils 11408 15640 
API Error Details:
View: CategoryViewSet
URL: /api/v1/tasks/categories/
Method: GET
User: AnonymousUser
Error Type: NotAuthenticated
Error Message: 身份认证信息未提供。
Stack Trace:
Traceback (most recent call last):
  File "E:\Github\todo2\todoServer\venv\Lib\site-packages\rest_framework\views.py", line 497, in dispatch
    self.initial(request, *args, **kwargs)
    ~~~~~~~~~~~~^^^^^^^^^^^^^^^^^^^^^^^^^^
  File "E:\Github\todo2\todoServer\venv\Lib\site-packages\rest_framework\views.py", line 415, in initial
    self.check_permissions(request)
    ~~~~~~~~~~~~~~~~~~~~~~^^^^^^^^^
  File "E:\Github\todo2\todoServer\venv\Lib\site-packages\rest_framework\views.py", line 333, in check_permissions
    self.permission_denied(
    ~~~~~~~~~~~~~~~~~~~~~~^
        request,
        ^^^^^^^^
        message=getattr(permission, 'message', None),
        ^^^^^^^^^^^^^^^^^^^^^^^^^^^^^^^^^^^^^^^^^^^^^
        code=getattr(permission, 'code', None)
        ^^^^^^^^^^^^^^^^^^^^^^^^^^^^^^^^^^^^^^
    )
    ^
  File "E:\Github\todo2\todoServer\venv\Lib\site-packages\rest_framework\views.py", line 174, in permission_denied
    raise exceptions.NotAuthenticated()
rest_framework.exceptions.NotAuthenticated: 身份认证信息未提供。

    
ERROR 2024-12-17 11:14:59,905 utils 11408 12868 
API Error Details:
View: TaskViewSet
URL: /api/v1/tasks/tasks/
Method: GET
User: AnonymousUser
Error Type: NotAuthenticated
Error Message: 身份认证信息未提供。
Stack Trace:
Traceback (most recent call last):
  File "E:\Github\todo2\todoServer\venv\Lib\site-packages\rest_framework\views.py", line 497, in dispatch
    self.initial(request, *args, **kwargs)
    ~~~~~~~~~~~~^^^^^^^^^^^^^^^^^^^^^^^^^^
  File "E:\Github\todo2\todoServer\venv\Lib\site-packages\rest_framework\views.py", line 415, in initial
    self.check_permissions(request)
    ~~~~~~~~~~~~~~~~~~~~~~^^^^^^^^^
  File "E:\Github\todo2\todoServer\venv\Lib\site-packages\rest_framework\views.py", line 333, in check_permissions
    self.permission_denied(
    ~~~~~~~~~~~~~~~~~~~~~~^
        request,
        ^^^^^^^^
        message=getattr(permission, 'message', None),
        ^^^^^^^^^^^^^^^^^^^^^^^^^^^^^^^^^^^^^^^^^^^^^
        code=getattr(permission, 'code', None)
        ^^^^^^^^^^^^^^^^^^^^^^^^^^^^^^^^^^^^^^
    )
    ^
  File "E:\Github\todo2\todoServer\venv\Lib\site-packages\rest_framework\views.py", line 174, in permission_denied
    raise exceptions.NotAuthenticated()
rest_framework.exceptions.NotAuthenticated: 身份认证信息未提供。

    
ERROR 2024-12-17 11:15:00,373 utils 11408 12868 
API Error Details:
View: TaskViewSet
URL: /api/v1/tasks/tasks/
Method: GET
User: AnonymousUser
Error Type: NotAuthenticated
Error Message: 身份认证信息未提供。
Stack Trace:
Traceback (most recent call last):
  File "E:\Github\todo2\todoServer\venv\Lib\site-packages\rest_framework\views.py", line 497, in dispatch
    self.initial(request, *args, **kwargs)
    ~~~~~~~~~~~~^^^^^^^^^^^^^^^^^^^^^^^^^^
  File "E:\Github\todo2\todoServer\venv\Lib\site-packages\rest_framework\views.py", line 415, in initial
    self.check_permissions(request)
    ~~~~~~~~~~~~~~~~~~~~~~^^^^^^^^^
  File "E:\Github\todo2\todoServer\venv\Lib\site-packages\rest_framework\views.py", line 333, in check_permissions
    self.permission_denied(
    ~~~~~~~~~~~~~~~~~~~~~~^
        request,
        ^^^^^^^^
        message=getattr(permission, 'message', None),
        ^^^^^^^^^^^^^^^^^^^^^^^^^^^^^^^^^^^^^^^^^^^^^
        code=getattr(permission, 'code', None)
        ^^^^^^^^^^^^^^^^^^^^^^^^^^^^^^^^^^^^^^
    )
    ^
  File "E:\Github\todo2\todoServer\venv\Lib\site-packages\rest_framework\views.py", line 174, in permission_denied
    raise exceptions.NotAuthenticated()
rest_framework.exceptions.NotAuthenticated: 身份认证信息未提供。

    
ERROR 2024-12-17 11:15:00,373 utils 11408 15640 
API Error Details:
View: CategoryViewSet
URL: /api/v1/tasks/categories/
Method: GET
User: AnonymousUser
Error Type: NotAuthenticated
Error Message: 身份认证信息未提供。
Stack Trace:
Traceback (most recent call last):
  File "E:\Github\todo2\todoServer\venv\Lib\site-packages\rest_framework\views.py", line 497, in dispatch
    self.initial(request, *args, **kwargs)
    ~~~~~~~~~~~~^^^^^^^^^^^^^^^^^^^^^^^^^^
  File "E:\Github\todo2\todoServer\venv\Lib\site-packages\rest_framework\views.py", line 415, in initial
    self.check_permissions(request)
    ~~~~~~~~~~~~~~~~~~~~~~^^^^^^^^^
  File "E:\Github\todo2\todoServer\venv\Lib\site-packages\rest_framework\views.py", line 333, in check_permissions
    self.permission_denied(
    ~~~~~~~~~~~~~~~~~~~~~~^
        request,
        ^^^^^^^^
        message=getattr(permission, 'message', None),
        ^^^^^^^^^^^^^^^^^^^^^^^^^^^^^^^^^^^^^^^^^^^^^
        code=getattr(permission, 'code', None)
        ^^^^^^^^^^^^^^^^^^^^^^^^^^^^^^^^^^^^^^
    )
    ^
  File "E:\Github\todo2\todoServer\venv\Lib\site-packages\rest_framework\views.py", line 174, in permission_denied
    raise exceptions.NotAuthenticated()
rest_framework.exceptions.NotAuthenticated: 身份认证信息未提供。

    
ERROR 2024-12-17 11:15:00,375 utils 11408 12868 
API Error Details:
View: TaskViewSet
URL: /api/v1/tasks/tasks/
Method: GET
User: AnonymousUser
Error Type: NotAuthenticated
Error Message: 身份认证信息未提供。
Stack Trace:
Traceback (most recent call last):
  File "E:\Github\todo2\todoServer\venv\Lib\site-packages\rest_framework\views.py", line 497, in dispatch
    self.initial(request, *args, **kwargs)
    ~~~~~~~~~~~~^^^^^^^^^^^^^^^^^^^^^^^^^^
  File "E:\Github\todo2\todoServer\venv\Lib\site-packages\rest_framework\views.py", line 415, in initial
    self.check_permissions(request)
    ~~~~~~~~~~~~~~~~~~~~~~^^^^^^^^^
  File "E:\Github\todo2\todoServer\venv\Lib\site-packages\rest_framework\views.py", line 333, in check_permissions
    self.permission_denied(
    ~~~~~~~~~~~~~~~~~~~~~~^
        request,
        ^^^^^^^^
        message=getattr(permission, 'message', None),
        ^^^^^^^^^^^^^^^^^^^^^^^^^^^^^^^^^^^^^^^^^^^^^
        code=getattr(permission, 'code', None)
        ^^^^^^^^^^^^^^^^^^^^^^^^^^^^^^^^^^^^^^
    )
    ^
  File "E:\Github\todo2\todoServer\venv\Lib\site-packages\rest_framework\views.py", line 174, in permission_denied
    raise exceptions.NotAuthenticated()
rest_framework.exceptions.NotAuthenticated: 身份认证信息未提供。

    
ERROR 2024-12-17 11:15:00,735 utils 11408 12868 
API Error Details:
View: TaskViewSet
URL: /api/v1/tasks/tasks/
Method: GET
User: AnonymousUser
Error Type: NotAuthenticated
Error Message: 身份认证信息未提供。
Stack Trace:
Traceback (most recent call last):
  File "E:\Github\todo2\todoServer\venv\Lib\site-packages\rest_framework\views.py", line 497, in dispatch
    self.initial(request, *args, **kwargs)
    ~~~~~~~~~~~~^^^^^^^^^^^^^^^^^^^^^^^^^^
  File "E:\Github\todo2\todoServer\venv\Lib\site-packages\rest_framework\views.py", line 415, in initial
    self.check_permissions(request)
    ~~~~~~~~~~~~~~~~~~~~~~^^^^^^^^^
  File "E:\Github\todo2\todoServer\venv\Lib\site-packages\rest_framework\views.py", line 333, in check_permissions
    self.permission_denied(
    ~~~~~~~~~~~~~~~~~~~~~~^
        request,
        ^^^^^^^^
        message=getattr(permission, 'message', None),
        ^^^^^^^^^^^^^^^^^^^^^^^^^^^^^^^^^^^^^^^^^^^^^
        code=getattr(permission, 'code', None)
        ^^^^^^^^^^^^^^^^^^^^^^^^^^^^^^^^^^^^^^
    )
    ^
  File "E:\Github\todo2\todoServer\venv\Lib\site-packages\rest_framework\views.py", line 174, in permission_denied
    raise exceptions.NotAuthenticated()
rest_framework.exceptions.NotAuthenticated: 身份认证信息未提供。

    
ERROR 2024-12-17 11:15:00,736 utils 11408 15640 
API Error Details:
View: CategoryViewSet
URL: /api/v1/tasks/categories/
Method: GET
User: AnonymousUser
Error Type: NotAuthenticated
Error Message: 身份认证信息未提供。
Stack Trace:
Traceback (most recent call last):
  File "E:\Github\todo2\todoServer\venv\Lib\site-packages\rest_framework\views.py", line 497, in dispatch
    self.initial(request, *args, **kwargs)
    ~~~~~~~~~~~~^^^^^^^^^^^^^^^^^^^^^^^^^^
  File "E:\Github\todo2\todoServer\venv\Lib\site-packages\rest_framework\views.py", line 415, in initial
    self.check_permissions(request)
    ~~~~~~~~~~~~~~~~~~~~~~^^^^^^^^^
  File "E:\Github\todo2\todoServer\venv\Lib\site-packages\rest_framework\views.py", line 333, in check_permissions
    self.permission_denied(
    ~~~~~~~~~~~~~~~~~~~~~~^
        request,
        ^^^^^^^^
        message=getattr(permission, 'message', None),
        ^^^^^^^^^^^^^^^^^^^^^^^^^^^^^^^^^^^^^^^^^^^^^
        code=getattr(permission, 'code', None)
        ^^^^^^^^^^^^^^^^^^^^^^^^^^^^^^^^^^^^^^
    )
    ^
  File "E:\Github\todo2\todoServer\venv\Lib\site-packages\rest_framework\views.py", line 174, in permission_denied
    raise exceptions.NotAuthenticated()
rest_framework.exceptions.NotAuthenticated: 身份认证信息未提供。

    
ERROR 2024-12-17 11:15:00,739 utils 11408 15640 
API Error Details:
View: TaskViewSet
URL: /api/v1/tasks/tasks/
Method: GET
User: AnonymousUser
Error Type: NotAuthenticated
Error Message: 身份认证信息未提供。
Stack Trace:
Traceback (most recent call last):
  File "E:\Github\todo2\todoServer\venv\Lib\site-packages\rest_framework\views.py", line 497, in dispatch
    self.initial(request, *args, **kwargs)
    ~~~~~~~~~~~~^^^^^^^^^^^^^^^^^^^^^^^^^^
  File "E:\Github\todo2\todoServer\venv\Lib\site-packages\rest_framework\views.py", line 415, in initial
    self.check_permissions(request)
    ~~~~~~~~~~~~~~~~~~~~~~^^^^^^^^^
  File "E:\Github\todo2\todoServer\venv\Lib\site-packages\rest_framework\views.py", line 333, in check_permissions
    self.permission_denied(
    ~~~~~~~~~~~~~~~~~~~~~~^
        request,
        ^^^^^^^^
        message=getattr(permission, 'message', None),
        ^^^^^^^^^^^^^^^^^^^^^^^^^^^^^^^^^^^^^^^^^^^^^
        code=getattr(permission, 'code', None)
        ^^^^^^^^^^^^^^^^^^^^^^^^^^^^^^^^^^^^^^
    )
    ^
  File "E:\Github\todo2\todoServer\venv\Lib\site-packages\rest_framework\views.py", line 174, in permission_denied
    raise exceptions.NotAuthenticated()
rest_framework.exceptions.NotAuthenticated: 身份认证信息未提供。

    
ERROR 2024-12-17 11:15:00,887 utils 11408 15640 
API Error Details:
View: TaskViewSet
URL: /api/v1/tasks/tasks/
Method: GET
User: AnonymousUser
Error Type: NotAuthenticated
Error Message: 身份认证信息未提供。
Stack Trace:
Traceback (most recent call last):
  File "E:\Github\todo2\todoServer\venv\Lib\site-packages\rest_framework\views.py", line 497, in dispatch
    self.initial(request, *args, **kwargs)
    ~~~~~~~~~~~~^^^^^^^^^^^^^^^^^^^^^^^^^^
  File "E:\Github\todo2\todoServer\venv\Lib\site-packages\rest_framework\views.py", line 415, in initial
    self.check_permissions(request)
    ~~~~~~~~~~~~~~~~~~~~~~^^^^^^^^^
  File "E:\Github\todo2\todoServer\venv\Lib\site-packages\rest_framework\views.py", line 333, in check_permissions
    self.permission_denied(
    ~~~~~~~~~~~~~~~~~~~~~~^
        request,
        ^^^^^^^^
        message=getattr(permission, 'message', None),
        ^^^^^^^^^^^^^^^^^^^^^^^^^^^^^^^^^^^^^^^^^^^^^
        code=getattr(permission, 'code', None)
        ^^^^^^^^^^^^^^^^^^^^^^^^^^^^^^^^^^^^^^
    )
    ^
  File "E:\Github\todo2\todoServer\venv\Lib\site-packages\rest_framework\views.py", line 174, in permission_denied
    raise exceptions.NotAuthenticated()
rest_framework.exceptions.NotAuthenticated: 身份认证信息未提供。

    
ERROR 2024-12-17 11:15:00,887 utils 11408 12868 
API Error Details:
View: CategoryViewSet
URL: /api/v1/tasks/categories/
Method: GET
User: AnonymousUser
Error Type: NotAuthenticated
Error Message: 身份认证信息未提供。
Stack Trace:
Traceback (most recent call last):
  File "E:\Github\todo2\todoServer\venv\Lib\site-packages\rest_framework\views.py", line 497, in dispatch
    self.initial(request, *args, **kwargs)
    ~~~~~~~~~~~~^^^^^^^^^^^^^^^^^^^^^^^^^^
  File "E:\Github\todo2\todoServer\venv\Lib\site-packages\rest_framework\views.py", line 415, in initial
    self.check_permissions(request)
    ~~~~~~~~~~~~~~~~~~~~~~^^^^^^^^^
  File "E:\Github\todo2\todoServer\venv\Lib\site-packages\rest_framework\views.py", line 333, in check_permissions
    self.permission_denied(
    ~~~~~~~~~~~~~~~~~~~~~~^
        request,
        ^^^^^^^^
        message=getattr(permission, 'message', None),
        ^^^^^^^^^^^^^^^^^^^^^^^^^^^^^^^^^^^^^^^^^^^^^
        code=getattr(permission, 'code', None)
        ^^^^^^^^^^^^^^^^^^^^^^^^^^^^^^^^^^^^^^
    )
    ^
  File "E:\Github\todo2\todoServer\venv\Lib\site-packages\rest_framework\views.py", line 174, in permission_denied
    raise exceptions.NotAuthenticated()
rest_framework.exceptions.NotAuthenticated: 身份认证信息未提供。

    
ERROR 2024-12-17 11:15:00,890 utils 11408 15640 
API Error Details:
View: TaskViewSet
URL: /api/v1/tasks/tasks/
Method: GET
User: AnonymousUser
Error Type: NotAuthenticated
Error Message: 身份认证信息未提供。
Stack Trace:
Traceback (most recent call last):
  File "E:\Github\todo2\todoServer\venv\Lib\site-packages\rest_framework\views.py", line 497, in dispatch
    self.initial(request, *args, **kwargs)
    ~~~~~~~~~~~~^^^^^^^^^^^^^^^^^^^^^^^^^^
  File "E:\Github\todo2\todoServer\venv\Lib\site-packages\rest_framework\views.py", line 415, in initial
    self.check_permissions(request)
    ~~~~~~~~~~~~~~~~~~~~~~^^^^^^^^^
  File "E:\Github\todo2\todoServer\venv\Lib\site-packages\rest_framework\views.py", line 333, in check_permissions
    self.permission_denied(
    ~~~~~~~~~~~~~~~~~~~~~~^
        request,
        ^^^^^^^^
        message=getattr(permission, 'message', None),
        ^^^^^^^^^^^^^^^^^^^^^^^^^^^^^^^^^^^^^^^^^^^^^
        code=getattr(permission, 'code', None)
        ^^^^^^^^^^^^^^^^^^^^^^^^^^^^^^^^^^^^^^
    )
    ^
  File "E:\Github\todo2\todoServer\venv\Lib\site-packages\rest_framework\views.py", line 174, in permission_denied
    raise exceptions.NotAuthenticated()
rest_framework.exceptions.NotAuthenticated: 身份认证信息未提供。

    
ERROR 2024-12-17 11:15:01,532 utils 11408 15640 
API Error Details:
View: TaskViewSet
URL: /api/v1/tasks/tasks/
Method: GET
User: AnonymousUser
Error Type: NotAuthenticated
Error Message: 身份认证信息未提供。
Stack Trace:
Traceback (most recent call last):
  File "E:\Github\todo2\todoServer\venv\Lib\site-packages\rest_framework\views.py", line 497, in dispatch
    self.initial(request, *args, **kwargs)
    ~~~~~~~~~~~~^^^^^^^^^^^^^^^^^^^^^^^^^^
  File "E:\Github\todo2\todoServer\venv\Lib\site-packages\rest_framework\views.py", line 415, in initial
    self.check_permissions(request)
    ~~~~~~~~~~~~~~~~~~~~~~^^^^^^^^^
  File "E:\Github\todo2\todoServer\venv\Lib\site-packages\rest_framework\views.py", line 333, in check_permissions
    self.permission_denied(
    ~~~~~~~~~~~~~~~~~~~~~~^
        request,
        ^^^^^^^^
        message=getattr(permission, 'message', None),
        ^^^^^^^^^^^^^^^^^^^^^^^^^^^^^^^^^^^^^^^^^^^^^
        code=getattr(permission, 'code', None)
        ^^^^^^^^^^^^^^^^^^^^^^^^^^^^^^^^^^^^^^
    )
    ^
  File "E:\Github\todo2\todoServer\venv\Lib\site-packages\rest_framework\views.py", line 174, in permission_denied
    raise exceptions.NotAuthenticated()
rest_framework.exceptions.NotAuthenticated: 身份认证信息未提供。

    
ERROR 2024-12-17 11:15:01,533 utils 11408 12868 
API Error Details:
View: CategoryViewSet
URL: /api/v1/tasks/categories/
Method: GET
User: AnonymousUser
Error Type: NotAuthenticated
Error Message: 身份认证信息未提供。
Stack Trace:
Traceback (most recent call last):
  File "E:\Github\todo2\todoServer\venv\Lib\site-packages\rest_framework\views.py", line 497, in dispatch
    self.initial(request, *args, **kwargs)
    ~~~~~~~~~~~~^^^^^^^^^^^^^^^^^^^^^^^^^^
  File "E:\Github\todo2\todoServer\venv\Lib\site-packages\rest_framework\views.py", line 415, in initial
    self.check_permissions(request)
    ~~~~~~~~~~~~~~~~~~~~~~^^^^^^^^^
  File "E:\Github\todo2\todoServer\venv\Lib\site-packages\rest_framework\views.py", line 333, in check_permissions
    self.permission_denied(
    ~~~~~~~~~~~~~~~~~~~~~~^
        request,
        ^^^^^^^^
        message=getattr(permission, 'message', None),
        ^^^^^^^^^^^^^^^^^^^^^^^^^^^^^^^^^^^^^^^^^^^^^
        code=getattr(permission, 'code', None)
        ^^^^^^^^^^^^^^^^^^^^^^^^^^^^^^^^^^^^^^
    )
    ^
  File "E:\Github\todo2\todoServer\venv\Lib\site-packages\rest_framework\views.py", line 174, in permission_denied
    raise exceptions.NotAuthenticated()
rest_framework.exceptions.NotAuthenticated: 身份认证信息未提供。

    
ERROR 2024-12-17 11:15:01,536 utils 11408 15640 
API Error Details:
View: TaskViewSet
URL: /api/v1/tasks/tasks/
Method: GET
User: AnonymousUser
Error Type: NotAuthenticated
Error Message: 身份认证信息未提供。
Stack Trace:
Traceback (most recent call last):
  File "E:\Github\todo2\todoServer\venv\Lib\site-packages\rest_framework\views.py", line 497, in dispatch
    self.initial(request, *args, **kwargs)
    ~~~~~~~~~~~~^^^^^^^^^^^^^^^^^^^^^^^^^^
  File "E:\Github\todo2\todoServer\venv\Lib\site-packages\rest_framework\views.py", line 415, in initial
    self.check_permissions(request)
    ~~~~~~~~~~~~~~~~~~~~~~^^^^^^^^^
  File "E:\Github\todo2\todoServer\venv\Lib\site-packages\rest_framework\views.py", line 333, in check_permissions
    self.permission_denied(
    ~~~~~~~~~~~~~~~~~~~~~~^
        request,
        ^^^^^^^^
        message=getattr(permission, 'message', None),
        ^^^^^^^^^^^^^^^^^^^^^^^^^^^^^^^^^^^^^^^^^^^^^
        code=getattr(permission, 'code', None)
        ^^^^^^^^^^^^^^^^^^^^^^^^^^^^^^^^^^^^^^
    )
    ^
  File "E:\Github\todo2\todoServer\venv\Lib\site-packages\rest_framework\views.py", line 174, in permission_denied
    raise exceptions.NotAuthenticated()
rest_framework.exceptions.NotAuthenticated: 身份认证信息未提供。

    
ERROR 2024-12-17 11:15:07,744 utils 11408 15640 
API Error Details:
View: CategoryViewSet
URL: /api/v1/tasks/categories/
Method: GET
User: AnonymousUser
Error Type: NotAuthenticated
Error Message: 身份认证信息未提供。
Stack Trace:
Traceback (most recent call last):
  File "E:\Github\todo2\todoServer\venv\Lib\site-packages\rest_framework\views.py", line 497, in dispatch
    self.initial(request, *args, **kwargs)
    ~~~~~~~~~~~~^^^^^^^^^^^^^^^^^^^^^^^^^^
  File "E:\Github\todo2\todoServer\venv\Lib\site-packages\rest_framework\views.py", line 415, in initial
    self.check_permissions(request)
    ~~~~~~~~~~~~~~~~~~~~~~^^^^^^^^^
  File "E:\Github\todo2\todoServer\venv\Lib\site-packages\rest_framework\views.py", line 333, in check_permissions
    self.permission_denied(
    ~~~~~~~~~~~~~~~~~~~~~~^
        request,
        ^^^^^^^^
        message=getattr(permission, 'message', None),
        ^^^^^^^^^^^^^^^^^^^^^^^^^^^^^^^^^^^^^^^^^^^^^
        code=getattr(permission, 'code', None)
        ^^^^^^^^^^^^^^^^^^^^^^^^^^^^^^^^^^^^^^
    )
    ^
  File "E:\Github\todo2\todoServer\venv\Lib\site-packages\rest_framework\views.py", line 174, in permission_denied
    raise exceptions.NotAuthenticated()
rest_framework.exceptions.NotAuthenticated: 身份认证信息未提供。

    
ERROR 2024-12-17 12:15:15,113 utils 11408 13028 
API Error Details:
View: MonthStatsView
URL: /api/v1/tasks/tasks/month_stats/2024-12/
Method: GET
User: AnonymousUser
Error Type: InvalidToken
Error Message: {'detail': ErrorDetail(string='此令牌对任何类型的令牌无效', code='token_not_valid'), 'code': ErrorDetail(string='token_not_valid', code='token_not_valid'), 'messages': [{'token_class': ErrorDetail(string='AccessToken', code='token_not_valid'), 'token_type': ErrorDetail(string='access', code='token_not_valid'), 'message': ErrorDetail(string='令牌无效或已过期', code='token_not_valid')}]}
Stack Trace:
Traceback (most recent call last):
  File "E:\Github\todo2\todoServer\venv\Lib\site-packages\rest_framework\views.py", line 497, in dispatch
    self.initial(request, *args, **kwargs)
    ~~~~~~~~~~~~^^^^^^^^^^^^^^^^^^^^^^^^^^
  File "E:\Github\todo2\todoServer\venv\Lib\site-packages\rest_framework\views.py", line 414, in initial
    self.perform_authentication(request)
    ~~~~~~~~~~~~~~~~~~~~~~~~~~~^^^^^^^^^
  File "E:\Github\todo2\todoServer\venv\Lib\site-packages\rest_framework\views.py", line 324, in perform_authentication
    request.user
  File "E:\Github\todo2\todoServer\venv\Lib\site-packages\rest_framework\request.py", line 227, in user
    self._authenticate()
    ~~~~~~~~~~~~~~~~~~^^
  File "E:\Github\todo2\todoServer\venv\Lib\site-packages\rest_framework\request.py", line 380, in _authenticate
    user_auth_tuple = authenticator.authenticate(self)
  File "E:\Github\todo2\todoServer\venv\Lib\site-packages\rest_framework_simplejwt\authentication.py", line 49, in authenticate
    validated_token = self.get_validated_token(raw_token)
  File "E:\Github\todo2\todoServer\venv\Lib\site-packages\rest_framework_simplejwt\authentication.py", line 113, in get_validated_token
    raise InvalidToken(
    ...<4 lines>...
    )
rest_framework_simplejwt.exceptions.InvalidToken: {'detail': ErrorDetail(string='此令牌对任何类型的令牌无效', code='token_not_valid'), 'code': ErrorDetail(string='token_not_valid', code='token_not_valid'), 'messages': [{'token_class': ErrorDetail(string='AccessToken', code='token_not_valid'), 'token_type': ErrorDetail(string='access', code='token_not_valid'), 'message': ErrorDetail(string='令牌无效或已过期', code='token_not_valid')}]}

    
ERROR 2024-12-17 12:15:15,126 utils 11408 13028 
API Error Details:
View: CategoryStatsView
URL: /api/v1/tasks/tasks/category_stats/2024-12/
Method: GET
User: AnonymousUser
Error Type: InvalidToken
Error Message: {'detail': ErrorDetail(string='此令牌对任何类型的令牌无效', code='token_not_valid'), 'code': ErrorDetail(string='token_not_valid', code='token_not_valid'), 'messages': [{'token_class': ErrorDetail(string='AccessToken', code='token_not_valid'), 'token_type': ErrorDetail(string='access', code='token_not_valid'), 'message': ErrorDetail(string='令牌无效或已过期', code='token_not_valid')}]}
Stack Trace:
Traceback (most recent call last):
  File "E:\Github\todo2\todoServer\venv\Lib\site-packages\rest_framework\views.py", line 497, in dispatch
    self.initial(request, *args, **kwargs)
    ~~~~~~~~~~~~^^^^^^^^^^^^^^^^^^^^^^^^^^
  File "E:\Github\todo2\todoServer\venv\Lib\site-packages\rest_framework\views.py", line 414, in initial
    self.perform_authentication(request)
    ~~~~~~~~~~~~~~~~~~~~~~~~~~~^^^^^^^^^
  File "E:\Github\todo2\todoServer\venv\Lib\site-packages\rest_framework\views.py", line 324, in perform_authentication
    request.user
  File "E:\Github\todo2\todoServer\venv\Lib\site-packages\rest_framework\request.py", line 227, in user
    self._authenticate()
    ~~~~~~~~~~~~~~~~~~^^
  File "E:\Github\todo2\todoServer\venv\Lib\site-packages\rest_framework\request.py", line 380, in _authenticate
    user_auth_tuple = authenticator.authenticate(self)
  File "E:\Github\todo2\todoServer\venv\Lib\site-packages\rest_framework_simplejwt\authentication.py", line 49, in authenticate
    validated_token = self.get_validated_token(raw_token)
  File "E:\Github\todo2\todoServer\venv\Lib\site-packages\rest_framework_simplejwt\authentication.py", line 113, in get_validated_token
    raise InvalidToken(
    ...<4 lines>...
    )
rest_framework_simplejwt.exceptions.InvalidToken: {'detail': ErrorDetail(string='此令牌对任何类型的令牌无效', code='token_not_valid'), 'code': ErrorDetail(string='token_not_valid', code='token_not_valid'), 'messages': [{'token_class': ErrorDetail(string='AccessToken', code='token_not_valid'), 'token_type': ErrorDetail(string='access', code='token_not_valid'), 'message': ErrorDetail(string='令牌无效或已过期', code='token_not_valid')}]}

    
ERROR 2024-12-17 12:15:15,126 utils 11408 17684 
API Error Details:
View: MonthStatsView
URL: /api/v1/tasks/tasks/month_stats/2024-12/
Method: GET
User: AnonymousUser
Error Type: InvalidToken
Error Message: {'detail': ErrorDetail(string='此令牌对任何类型的令牌无效', code='token_not_valid'), 'code': ErrorDetail(string='token_not_valid', code='token_not_valid'), 'messages': [{'token_class': ErrorDetail(string='AccessToken', code='token_not_valid'), 'token_type': ErrorDetail(string='access', code='token_not_valid'), 'message': ErrorDetail(string='令牌无效或已过期', code='token_not_valid')}]}
Stack Trace:
Traceback (most recent call last):
  File "E:\Github\todo2\todoServer\venv\Lib\site-packages\rest_framework\views.py", line 497, in dispatch
    self.initial(request, *args, **kwargs)
    ~~~~~~~~~~~~^^^^^^^^^^^^^^^^^^^^^^^^^^
  File "E:\Github\todo2\todoServer\venv\Lib\site-packages\rest_framework\views.py", line 414, in initial
    self.perform_authentication(request)
    ~~~~~~~~~~~~~~~~~~~~~~~~~~~^^^^^^^^^
  File "E:\Github\todo2\todoServer\venv\Lib\site-packages\rest_framework\views.py", line 324, in perform_authentication
    request.user
  File "E:\Github\todo2\todoServer\venv\Lib\site-packages\rest_framework\request.py", line 227, in user
    self._authenticate()
    ~~~~~~~~~~~~~~~~~~^^
  File "E:\Github\todo2\todoServer\venv\Lib\site-packages\rest_framework\request.py", line 380, in _authenticate
    user_auth_tuple = authenticator.authenticate(self)
  File "E:\Github\todo2\todoServer\venv\Lib\site-packages\rest_framework_simplejwt\authentication.py", line 49, in authenticate
    validated_token = self.get_validated_token(raw_token)
  File "E:\Github\todo2\todoServer\venv\Lib\site-packages\rest_framework_simplejwt\authentication.py", line 113, in get_validated_token
    raise InvalidToken(
    ...<4 lines>...
    )
rest_framework_simplejwt.exceptions.InvalidToken: {'detail': ErrorDetail(string='此令牌对任何类型的令牌无效', code='token_not_valid'), 'code': ErrorDetail(string='token_not_valid', code='token_not_valid'), 'messages': [{'token_class': ErrorDetail(string='AccessToken', code='token_not_valid'), 'token_type': ErrorDetail(string='access', code='token_not_valid'), 'message': ErrorDetail(string='令牌无效或已过期', code='token_not_valid')}]}

    
ERROR 2024-12-17 12:15:15,126 utils 11408 6616 
API Error Details:
View: PriorityStatsView
URL: /api/v1/tasks/tasks/priority_stats/2024-12/
Method: GET
User: AnonymousUser
Error Type: InvalidToken
Error Message: {'detail': ErrorDetail(string='此令牌对任何类型的令牌无效', code='token_not_valid'), 'code': ErrorDetail(string='token_not_valid', code='token_not_valid'), 'messages': [{'token_class': ErrorDetail(string='AccessToken', code='token_not_valid'), 'token_type': ErrorDetail(string='access', code='token_not_valid'), 'message': ErrorDetail(string='令牌无效或已过期', code='token_not_valid')}]}
Stack Trace:
Traceback (most recent call last):
  File "E:\Github\todo2\todoServer\venv\Lib\site-packages\rest_framework\views.py", line 497, in dispatch
    self.initial(request, *args, **kwargs)
    ~~~~~~~~~~~~^^^^^^^^^^^^^^^^^^^^^^^^^^
  File "E:\Github\todo2\todoServer\venv\Lib\site-packages\rest_framework\views.py", line 414, in initial
    self.perform_authentication(request)
    ~~~~~~~~~~~~~~~~~~~~~~~~~~~^^^^^^^^^
  File "E:\Github\todo2\todoServer\venv\Lib\site-packages\rest_framework\views.py", line 324, in perform_authentication
    request.user
  File "E:\Github\todo2\todoServer\venv\Lib\site-packages\rest_framework\request.py", line 227, in user
    self._authenticate()
    ~~~~~~~~~~~~~~~~~~^^
  File "E:\Github\todo2\todoServer\venv\Lib\site-packages\rest_framework\request.py", line 380, in _authenticate
    user_auth_tuple = authenticator.authenticate(self)
  File "E:\Github\todo2\todoServer\venv\Lib\site-packages\rest_framework_simplejwt\authentication.py", line 49, in authenticate
    validated_token = self.get_validated_token(raw_token)
  File "E:\Github\todo2\todoServer\venv\Lib\site-packages\rest_framework_simplejwt\authentication.py", line 113, in get_validated_token
    raise InvalidToken(
    ...<4 lines>...
    )
rest_framework_simplejwt.exceptions.InvalidToken: {'detail': ErrorDetail(string='此令牌对任何类型的令牌无效', code='token_not_valid'), 'code': ErrorDetail(string='token_not_valid', code='token_not_valid'), 'messages': [{'token_class': ErrorDetail(string='AccessToken', code='token_not_valid'), 'token_type': ErrorDetail(string='access', code='token_not_valid'), 'message': ErrorDetail(string='令牌无效或已过期', code='token_not_valid')}]}

    
ERROR 2024-12-17 12:15:15,145 utils 11408 13028 
API Error Details:
View: CategoryStatsView
URL: /api/v1/tasks/tasks/category_stats/2024-12/
Method: GET
User: AnonymousUser
Error Type: InvalidToken
Error Message: {'detail': ErrorDetail(string='此令牌对任何类型的令牌无效', code='token_not_valid'), 'code': ErrorDetail(string='token_not_valid', code='token_not_valid'), 'messages': [{'token_class': ErrorDetail(string='AccessToken', code='token_not_valid'), 'token_type': ErrorDetail(string='access', code='token_not_valid'), 'message': ErrorDetail(string='令牌无效或已过期', code='token_not_valid')}]}
Stack Trace:
Traceback (most recent call last):
  File "E:\Github\todo2\todoServer\venv\Lib\site-packages\rest_framework\views.py", line 497, in dispatch
    self.initial(request, *args, **kwargs)
    ~~~~~~~~~~~~^^^^^^^^^^^^^^^^^^^^^^^^^^
  File "E:\Github\todo2\todoServer\venv\Lib\site-packages\rest_framework\views.py", line 414, in initial
    self.perform_authentication(request)
    ~~~~~~~~~~~~~~~~~~~~~~~~~~~^^^^^^^^^
  File "E:\Github\todo2\todoServer\venv\Lib\site-packages\rest_framework\views.py", line 324, in perform_authentication
    request.user
  File "E:\Github\todo2\todoServer\venv\Lib\site-packages\rest_framework\request.py", line 227, in user
    self._authenticate()
    ~~~~~~~~~~~~~~~~~~^^
  File "E:\Github\todo2\todoServer\venv\Lib\site-packages\rest_framework\request.py", line 380, in _authenticate
    user_auth_tuple = authenticator.authenticate(self)
  File "E:\Github\todo2\todoServer\venv\Lib\site-packages\rest_framework_simplejwt\authentication.py", line 49, in authenticate
    validated_token = self.get_validated_token(raw_token)
  File "E:\Github\todo2\todoServer\venv\Lib\site-packages\rest_framework_simplejwt\authentication.py", line 113, in get_validated_token
    raise InvalidToken(
    ...<4 lines>...
    )
rest_framework_simplejwt.exceptions.InvalidToken: {'detail': ErrorDetail(string='此令牌对任何类型的令牌无效', code='token_not_valid'), 'code': ErrorDetail(string='token_not_valid', code='token_not_valid'), 'messages': [{'token_class': ErrorDetail(string='AccessToken', code='token_not_valid'), 'token_type': ErrorDetail(string='access', code='token_not_valid'), 'message': ErrorDetail(string='令牌无效或已过期', code='token_not_valid')}]}

    
ERROR 2024-12-17 12:15:15,145 utils 11408 6616 
API Error Details:
View: PriorityStatsView
URL: /api/v1/tasks/tasks/priority_stats/2024-12/
Method: GET
User: AnonymousUser
Error Type: InvalidToken
Error Message: {'detail': ErrorDetail(string='此令牌对任何类型的令牌无效', code='token_not_valid'), 'code': ErrorDetail(string='token_not_valid', code='token_not_valid'), 'messages': [{'token_class': ErrorDetail(string='AccessToken', code='token_not_valid'), 'token_type': ErrorDetail(string='access', code='token_not_valid'), 'message': ErrorDetail(string='令牌无效或已过期', code='token_not_valid')}]}
Stack Trace:
Traceback (most recent call last):
  File "E:\Github\todo2\todoServer\venv\Lib\site-packages\rest_framework\views.py", line 497, in dispatch
    self.initial(request, *args, **kwargs)
    ~~~~~~~~~~~~^^^^^^^^^^^^^^^^^^^^^^^^^^
  File "E:\Github\todo2\todoServer\venv\Lib\site-packages\rest_framework\views.py", line 414, in initial
    self.perform_authentication(request)
    ~~~~~~~~~~~~~~~~~~~~~~~~~~~^^^^^^^^^
  File "E:\Github\todo2\todoServer\venv\Lib\site-packages\rest_framework\views.py", line 324, in perform_authentication
    request.user
  File "E:\Github\todo2\todoServer\venv\Lib\site-packages\rest_framework\request.py", line 227, in user
    self._authenticate()
    ~~~~~~~~~~~~~~~~~~^^
  File "E:\Github\todo2\todoServer\venv\Lib\site-packages\rest_framework\request.py", line 380, in _authenticate
    user_auth_tuple = authenticator.authenticate(self)
  File "E:\Github\todo2\todoServer\venv\Lib\site-packages\rest_framework_simplejwt\authentication.py", line 49, in authenticate
    validated_token = self.get_validated_token(raw_token)
  File "E:\Github\todo2\todoServer\venv\Lib\site-packages\rest_framework_simplejwt\authentication.py", line 113, in get_validated_token
    raise InvalidToken(
    ...<4 lines>...
    )
rest_framework_simplejwt.exceptions.InvalidToken: {'detail': ErrorDetail(string='此令牌对任何类型的令牌无效', code='token_not_valid'), 'code': ErrorDetail(string='token_not_valid', code='token_not_valid'), 'messages': [{'token_class': ErrorDetail(string='AccessToken', code='token_not_valid'), 'token_type': ErrorDetail(string='access', code='token_not_valid'), 'message': ErrorDetail(string='令牌无效或已过期', code='token_not_valid')}]}

    
ERROR 2024-12-17 12:28:14,835 utils 11408 14196 
API Error Details:
View: CategoryViewSet
URL: /api/v1/tasks/categories/
Method: GET
User: AnonymousUser
Error Type: NotAuthenticated
Error Message: 身份认证信息未提供。
Stack Trace:
Traceback (most recent call last):
  File "E:\Github\todo2\todoServer\venv\Lib\site-packages\rest_framework\views.py", line 497, in dispatch
    self.initial(request, *args, **kwargs)
    ~~~~~~~~~~~~^^^^^^^^^^^^^^^^^^^^^^^^^^
  File "E:\Github\todo2\todoServer\venv\Lib\site-packages\rest_framework\views.py", line 415, in initial
    self.check_permissions(request)
    ~~~~~~~~~~~~~~~~~~~~~~^^^^^^^^^
  File "E:\Github\todo2\todoServer\venv\Lib\site-packages\rest_framework\views.py", line 333, in check_permissions
    self.permission_denied(
    ~~~~~~~~~~~~~~~~~~~~~~^
        request,
        ^^^^^^^^
        message=getattr(permission, 'message', None),
        ^^^^^^^^^^^^^^^^^^^^^^^^^^^^^^^^^^^^^^^^^^^^^
        code=getattr(permission, 'code', None)
        ^^^^^^^^^^^^^^^^^^^^^^^^^^^^^^^^^^^^^^
    )
    ^
  File "E:\Github\todo2\todoServer\venv\Lib\site-packages\rest_framework\views.py", line 174, in permission_denied
    raise exceptions.NotAuthenticated()
rest_framework.exceptions.NotAuthenticated: 身份认证信息未提供。

    
ERROR 2024-12-17 13:08:39,231 utils 11408 8792 
API Error Details:
View: CategoryViewSet
URL: /api/v1/tasks/categories/
Method: GET
User: AnonymousUser
Error Type: NotAuthenticated
Error Message: 身份认证信息未提供。
Stack Trace:
Traceback (most recent call last):
  File "E:\Github\todo2\todoServer\venv\Lib\site-packages\rest_framework\views.py", line 497, in dispatch
    self.initial(request, *args, **kwargs)
    ~~~~~~~~~~~~^^^^^^^^^^^^^^^^^^^^^^^^^^
  File "E:\Github\todo2\todoServer\venv\Lib\site-packages\rest_framework\views.py", line 415, in initial
    self.check_permissions(request)
    ~~~~~~~~~~~~~~~~~~~~~~^^^^^^^^^
  File "E:\Github\todo2\todoServer\venv\Lib\site-packages\rest_framework\views.py", line 333, in check_permissions
    self.permission_denied(
    ~~~~~~~~~~~~~~~~~~~~~~^
        request,
        ^^^^^^^^
        message=getattr(permission, 'message', None),
        ^^^^^^^^^^^^^^^^^^^^^^^^^^^^^^^^^^^^^^^^^^^^^
        code=getattr(permission, 'code', None)
        ^^^^^^^^^^^^^^^^^^^^^^^^^^^^^^^^^^^^^^
    )
    ^
  File "E:\Github\todo2\todoServer\venv\Lib\site-packages\rest_framework\views.py", line 174, in permission_denied
    raise exceptions.NotAuthenticated()
rest_framework.exceptions.NotAuthenticated: 身份认证信息未提供。

    
ERROR 2024-12-17 13:08:56,361 utils 11408 3692 
API Error Details:
View: CategoryViewSet
URL: /api/v1/tasks/categories/
Method: GET
User: AnonymousUser
Error Type: NotAuthenticated
Error Message: 身份认证信息未提供。
Stack Trace:
Traceback (most recent call last):
  File "E:\Github\todo2\todoServer\venv\Lib\site-packages\rest_framework\views.py", line 497, in dispatch
    self.initial(request, *args, **kwargs)
    ~~~~~~~~~~~~^^^^^^^^^^^^^^^^^^^^^^^^^^
  File "E:\Github\todo2\todoServer\venv\Lib\site-packages\rest_framework\views.py", line 415, in initial
    self.check_permissions(request)
    ~~~~~~~~~~~~~~~~~~~~~~^^^^^^^^^
  File "E:\Github\todo2\todoServer\venv\Lib\site-packages\rest_framework\views.py", line 333, in check_permissions
    self.permission_denied(
    ~~~~~~~~~~~~~~~~~~~~~~^
        request,
        ^^^^^^^^
        message=getattr(permission, 'message', None),
        ^^^^^^^^^^^^^^^^^^^^^^^^^^^^^^^^^^^^^^^^^^^^^
        code=getattr(permission, 'code', None)
        ^^^^^^^^^^^^^^^^^^^^^^^^^^^^^^^^^^^^^^
    )
    ^
  File "E:\Github\todo2\todoServer\venv\Lib\site-packages\rest_framework\views.py", line 174, in permission_denied
    raise exceptions.NotAuthenticated()
rest_framework.exceptions.NotAuthenticated: 身份认证信息未提供。

    
ERROR 2024-12-17 14:02:13,299 utils 11408 19080 
API Error Details:
View: CategoryViewSet
URL: /api/v1/tasks/categories/
Method: GET
User: AnonymousUser
Error Type: NotAuthenticated
Error Message: 身份认证信息未提供。
Stack Trace:
Traceback (most recent call last):
  File "E:\Github\todo2\todoServer\venv\Lib\site-packages\rest_framework\views.py", line 497, in dispatch
    self.initial(request, *args, **kwargs)
    ~~~~~~~~~~~~^^^^^^^^^^^^^^^^^^^^^^^^^^
  File "E:\Github\todo2\todoServer\venv\Lib\site-packages\rest_framework\views.py", line 415, in initial
    self.check_permissions(request)
    ~~~~~~~~~~~~~~~~~~~~~~^^^^^^^^^
  File "E:\Github\todo2\todoServer\venv\Lib\site-packages\rest_framework\views.py", line 333, in check_permissions
    self.permission_denied(
    ~~~~~~~~~~~~~~~~~~~~~~^
        request,
        ^^^^^^^^
        message=getattr(permission, 'message', None),
        ^^^^^^^^^^^^^^^^^^^^^^^^^^^^^^^^^^^^^^^^^^^^^
        code=getattr(permission, 'code', None)
        ^^^^^^^^^^^^^^^^^^^^^^^^^^^^^^^^^^^^^^
    )
    ^
  File "E:\Github\todo2\todoServer\venv\Lib\site-packages\rest_framework\views.py", line 174, in permission_denied
    raise exceptions.NotAuthenticated()
rest_framework.exceptions.NotAuthenticated: 身份认证信息未提供。

    
ERROR 2024-12-17 14:08:12,071 utils 11408 15720 
API Error Details:
View: UserViewSet
URL: /api/v1/accounts/users/request_password_reset/
Method: POST
User: fx0883
Error Type: ValidationError
Error Message: {'email': [ErrorDetail(string='该字段是必填项。', code='required')]}
Stack Trace:
Traceback (most recent call last):
  File "E:\Github\todo2\todoServer\venv\Lib\site-packages\rest_framework\views.py", line 506, in dispatch
    response = handler(request, *args, **kwargs)
  File "E:\Github\todo2\todoServer\venv\Lib\site-packages\django\utils\decorators.py", line 48, in _wrapper
    return bound_method(*args, **kwargs)
  File "E:\Github\todo2\todoServer\venv\Lib\site-packages\django\views\decorators\csrf.py", line 65, in _view_wrapper
    return view_func(request, *args, **kwargs)
  File "E:\Github\todo2\todoServer\accounts\views.py", line 327, in request_password_reset
    serializer.is_valid(raise_exception=True)
    ~~~~~~~~~~~~~~~~~~~^^^^^^^^^^^^^^^^^^^^^^
  File "E:\Github\todo2\todoServer\venv\Lib\site-packages\rest_framework\serializers.py", line 235, in is_valid
    raise ValidationError(self.errors)
rest_framework.exceptions.ValidationError: {'email': [ErrorDetail(string='该字段是必填项。', code='required')]}

    
ERROR 2024-12-17 16:04:19,378 utils 4552 20296 
API Error Details:
View: CategoryViewSet
URL: /api/v1/tasks/categories/
Method: GET
User: AnonymousUser
Error Type: InvalidToken
Error Message: {'detail': ErrorDetail(string='此令牌对任何类型的令牌无效', code='token_not_valid'), 'code': ErrorDetail(string='token_not_valid', code='token_not_valid'), 'messages': [{'token_class': ErrorDetail(string='AccessToken', code='token_not_valid'), 'token_type': ErrorDetail(string='access', code='token_not_valid'), 'message': ErrorDetail(string='令牌无效或已过期', code='token_not_valid')}]}
Stack Trace:
Traceback (most recent call last):
  File "E:\Github\todo2\todoServer\venv\Lib\site-packages\rest_framework\views.py", line 497, in dispatch
    self.initial(request, *args, **kwargs)
    ~~~~~~~~~~~~^^^^^^^^^^^^^^^^^^^^^^^^^^
  File "E:\Github\todo2\todoServer\venv\Lib\site-packages\rest_framework\views.py", line 414, in initial
    self.perform_authentication(request)
    ~~~~~~~~~~~~~~~~~~~~~~~~~~~^^^^^^^^^
  File "E:\Github\todo2\todoServer\venv\Lib\site-packages\rest_framework\views.py", line 324, in perform_authentication
    request.user
  File "E:\Github\todo2\todoServer\venv\Lib\site-packages\rest_framework\request.py", line 227, in user
    self._authenticate()
    ~~~~~~~~~~~~~~~~~~^^
  File "E:\Github\todo2\todoServer\venv\Lib\site-packages\rest_framework\request.py", line 380, in _authenticate
    user_auth_tuple = authenticator.authenticate(self)
  File "E:\Github\todo2\todoServer\venv\Lib\site-packages\rest_framework_simplejwt\authentication.py", line 49, in authenticate
    validated_token = self.get_validated_token(raw_token)
  File "E:\Github\todo2\todoServer\venv\Lib\site-packages\rest_framework_simplejwt\authentication.py", line 113, in get_validated_token
    raise InvalidToken(
    ...<4 lines>...
    )
rest_framework_simplejwt.exceptions.InvalidToken: {'detail': ErrorDetail(string='此令牌对任何类型的令牌无效', code='token_not_valid'), 'code': ErrorDetail(string='token_not_valid', code='token_not_valid'), 'messages': [{'token_class': ErrorDetail(string='AccessToken', code='token_not_valid'), 'token_type': ErrorDetail(string='access', code='token_not_valid'), 'message': ErrorDetail(string='令牌无效或已过期', code='token_not_valid')}]}

    
ERROR 2024-12-17 16:04:19,379 utils 4552 15148 
API Error Details:
View: TaskViewSet
URL: /api/v1/tasks/tasks/
Method: GET
User: AnonymousUser
Error Type: InvalidToken
Error Message: {'detail': ErrorDetail(string='此令牌对任何类型的令牌无效', code='token_not_valid'), 'code': ErrorDetail(string='token_not_valid', code='token_not_valid'), 'messages': [{'token_class': ErrorDetail(string='AccessToken', code='token_not_valid'), 'token_type': ErrorDetail(string='access', code='token_not_valid'), 'message': ErrorDetail(string='令牌无效或已过期', code='token_not_valid')}]}
Stack Trace:
Traceback (most recent call last):
  File "E:\Github\todo2\todoServer\venv\Lib\site-packages\rest_framework\views.py", line 497, in dispatch
    self.initial(request, *args, **kwargs)
    ~~~~~~~~~~~~^^^^^^^^^^^^^^^^^^^^^^^^^^
  File "E:\Github\todo2\todoServer\venv\Lib\site-packages\rest_framework\views.py", line 414, in initial
    self.perform_authentication(request)
    ~~~~~~~~~~~~~~~~~~~~~~~~~~~^^^^^^^^^
  File "E:\Github\todo2\todoServer\venv\Lib\site-packages\rest_framework\views.py", line 324, in perform_authentication
    request.user
  File "E:\Github\todo2\todoServer\venv\Lib\site-packages\rest_framework\request.py", line 227, in user
    self._authenticate()
    ~~~~~~~~~~~~~~~~~~^^
  File "E:\Github\todo2\todoServer\venv\Lib\site-packages\rest_framework\request.py", line 380, in _authenticate
    user_auth_tuple = authenticator.authenticate(self)
  File "E:\Github\todo2\todoServer\venv\Lib\site-packages\rest_framework_simplejwt\authentication.py", line 49, in authenticate
    validated_token = self.get_validated_token(raw_token)
  File "E:\Github\todo2\todoServer\venv\Lib\site-packages\rest_framework_simplejwt\authentication.py", line 113, in get_validated_token
    raise InvalidToken(
    ...<4 lines>...
    )
rest_framework_simplejwt.exceptions.InvalidToken: {'detail': ErrorDetail(string='此令牌对任何类型的令牌无效', code='token_not_valid'), 'code': ErrorDetail(string='token_not_valid', code='token_not_valid'), 'messages': [{'token_class': ErrorDetail(string='AccessToken', code='token_not_valid'), 'token_type': ErrorDetail(string='access', code='token_not_valid'), 'message': ErrorDetail(string='令牌无效或已过期', code='token_not_valid')}]}

    
ERROR 2024-12-17 16:04:19,384 utils 4552 15148 
API Error Details:
View: TaskViewSet
URL: /api/v1/tasks/tasks/
Method: GET
User: AnonymousUser
Error Type: InvalidToken
Error Message: {'detail': ErrorDetail(string='此令牌对任何类型的令牌无效', code='token_not_valid'), 'code': ErrorDetail(string='token_not_valid', code='token_not_valid'), 'messages': [{'token_class': ErrorDetail(string='AccessToken', code='token_not_valid'), 'token_type': ErrorDetail(string='access', code='token_not_valid'), 'message': ErrorDetail(string='令牌无效或已过期', code='token_not_valid')}]}
Stack Trace:
Traceback (most recent call last):
  File "E:\Github\todo2\todoServer\venv\Lib\site-packages\rest_framework\views.py", line 497, in dispatch
    self.initial(request, *args, **kwargs)
    ~~~~~~~~~~~~^^^^^^^^^^^^^^^^^^^^^^^^^^
  File "E:\Github\todo2\todoServer\venv\Lib\site-packages\rest_framework\views.py", line 414, in initial
    self.perform_authentication(request)
    ~~~~~~~~~~~~~~~~~~~~~~~~~~~^^^^^^^^^
  File "E:\Github\todo2\todoServer\venv\Lib\site-packages\rest_framework\views.py", line 324, in perform_authentication
    request.user
  File "E:\Github\todo2\todoServer\venv\Lib\site-packages\rest_framework\request.py", line 227, in user
    self._authenticate()
    ~~~~~~~~~~~~~~~~~~^^
  File "E:\Github\todo2\todoServer\venv\Lib\site-packages\rest_framework\request.py", line 380, in _authenticate
    user_auth_tuple = authenticator.authenticate(self)
  File "E:\Github\todo2\todoServer\venv\Lib\site-packages\rest_framework_simplejwt\authentication.py", line 49, in authenticate
    validated_token = self.get_validated_token(raw_token)
  File "E:\Github\todo2\todoServer\venv\Lib\site-packages\rest_framework_simplejwt\authentication.py", line 113, in get_validated_token
    raise InvalidToken(
    ...<4 lines>...
    )
rest_framework_simplejwt.exceptions.InvalidToken: {'detail': ErrorDetail(string='此令牌对任何类型的令牌无效', code='token_not_valid'), 'code': ErrorDetail(string='token_not_valid', code='token_not_valid'), 'messages': [{'token_class': ErrorDetail(string='AccessToken', code='token_not_valid'), 'token_type': ErrorDetail(string='access', code='token_not_valid'), 'message': ErrorDetail(string='令牌无效或已过期', code='token_not_valid')}]}

    
